Workbook

Sheet MASTER BY DIVISION
A1: ='16U BOYS GOLD-9 TEAMS'!A13 -> DATE | B1: ='16U BOYS GOLD-9 TEAMS'!B13 -> TIME | C1: ='16U BOYS GOLD-9 TEAMS'!C13&"" -> LOCATION | D1: ='16U BOYS GOLD-9 TEAMS'!D13&"" -> GAME ID | E1: ='16U BOYS GOLD-9 TEAMS'!E13&"" -> WHITE TEAM | F1: ='16U BOYS GOLD-9 TEAMS'!F13&"" -> S | G1: ='16U BOYS GOLD-9 TEAMS'!G13&"" -> DARK TEAM | H1: ='16U BOYS GOLD-9 TEAMS'!H13&"" -> S | I1: ='16U BOYS GOLD-9 TEAMS'!I13&"" -> COMMENTS | J1: ='16U BOYS GOLD-9 TEAMS'!J13&"" -> DIVISION
A2: ='16U BOYS GOLD-9 TEAMS'!A14 -> 45724 | B2: ='16U BOYS GOLD-9 TEAMS'!B14 -> 0.39583333 | C2: ='16U BOYS GOLD-9 TEAMS'!C14&"" -> COSTA MESA HS | D2: ='16U BOYS GOLD-9 TEAMS'!D14&"" -> 16Bau01 | E2: ='16U BOYS GOLD-9 TEAMS'!E14&"" -> A1-SAN FRANCISCO | F2: ='16U BOYS GOLD-9 TEAMS'!F14&"" -> 17 | G2: ='16U BOYS GOLD-9 TEAMS'!G14&"" -> A3-FOOTHILL BLACK | H2: ='16U BOYS GOLD-9 TEAMS'!H14&"" -> 1 | I2: ='16U BOYS GOLD-9 TEAMS'!I14&"" -> A bracket A1,A3 | J2: ='16U BOYS GOLD-9 TEAMS'!J14&"" -> 16U_BOYS_GOLD
A3: ='16U BOYS GOLD-9 TEAMS'!A15 -> 45724 | B3: ='16U BOYS GOLD-9 TEAMS'!B15 -> 0.4375 | C3: ='16U BOYS GOLD-9 TEAMS'!C15&"" -> COSTA MESA HS | D3: ='16U BOYS GOLD-9 TEAMS'!D15&"" -> 16Bau02 | E3: ='16U BOYS GOLD-9 TEAMS'!E15&"" -> B1-LA PREMIER | F3: ='16U BOYS GOLD-9 TEAMS'!F15&"" -> 15 | G3: ='16U BOYS GOLD-9 TEAMS'!G15&"" -> B3-OCWP RED | H3: ='16U BOYS GOLD-9 TEAMS'!H15&"" -> 9 | I3: ='16U BOYS GOLD-9 TEAMS'!I15&"" -> B bracket B1,B3 | J3: ='16U BOYS GOLD-9 TEAMS'!J15&"" -> 16U_BOYS_GOLD
A4: ='16U BOYS GOLD-9 TEAMS'!A16 -> 45724 | B4: ='16U BOYS GOLD-9 TEAMS'!B16 -> 0.47916667 | C4: ='16U BOYS GOLD-9 TEAMS'!C16&"" -> COSTA MESA HS | D4: ='16U BOYS GOLD-9 TEAMS'!D16&"" -> 16Bau03 | E4: ='16U BOYS GOLD-9 TEAMS'!E16&"" -> C1-TROJAN | F4: ='16U BOYS GOLD-9 TEAMS'!F16&"" -> 2 | G4: ='16U BOYS GOLD-9 TEAMS'!G16&"" -> C2-CC UNITED BLUE | H4: ='16U BOYS GOLD-9 TEAMS'!H16&"" -> 9 | I4: ='16U BOYS GOLD-9 TEAMS'!I16&"" -> C bracket C1,C2 | J4: ='16U BOYS GOLD-9 TEAMS'!J16&"" -> 16U_BOYS_GOLD
A5: ='16U BOYS GOLD-9 TEAMS'!A17 -> 45724 | B5: ='16U BOYS GOLD-9 TEAMS'!B17 -> 0.52083333 | C5: ='16U BOYS GOLD-9 TEAMS'!C17&"" -> COSTA MESA HS | D5: ='16U BOYS GOLD-9 TEAMS'!D17&"" -> 16Bau04 | E5: ='16U BOYS GOLD-9 TEAMS'!E17&"" -> A2-MISSION B | F5: ='16U BOYS GOLD-9 TEAMS'!F17&"" -> 14 | G5: ='16U BOYS GOLD-9 TEAMS'!G17&"" -> A3-FOOTHILL BLACK | H5: ='16U BOYS GOLD-9 TEAMS'!H17&"" -> 5 | I5: ='16U BOYS GOLD-9 TEAMS'!I17&"" -> A bracket A2,A3 | J5: ='16U BOYS GOLD-9 TEAMS'!J17&"" -> 16U_BOYS_GOLD
A6: ='16U BOYS GOLD-9 TEAMS'!A18 -> 45724 | B6: ='16U BOYS GOLD-9 TEAMS'!B18 -> 0.5625 | C6: ='16U BOYS GOLD-9 TEAMS'!C18&"" -> COSTA MESA HS | D6: ='16U BOYS GOLD-9 TEAMS'!D18&"" -> 16Bau05 | E6: ='16U BOYS GOLD-9 TEAMS'!E18&"" -> B1-LA PREMIER | F6: ='16U BOYS GOLD-9 TEAMS'!F18&"" -> 14 | G6: ='16U BOYS GOLD-9 TEAMS'!G18&"" -> B2-PEGASUS WP | H6: ='16U BOYS GOLD-9 TEAMS'!H18&"" -> 10 | I6: ='16U BOYS GOLD-9 TEAMS'!I18&"" -> B bracket B1,B2 | J6: ='16U BOYS GOLD-9 TEAMS'!J18&"" -> 16U_BOYS_GOLD
A7: ='16U BOYS GOLD-9 TEAMS'!A19 -> 45724 | B7: ='16U BOYS GOLD-9 TEAMS'!B19 -> 0.60416667 | C7: ='16U BOYS GOLD-9 TEAMS'!C19&"" -> COSTA MESA HS | D7: ='16U BOYS GOLD-9 TEAMS'!D19&"" -> 16Bau06 | E7: ='16U BOYS GOLD-9 TEAMS'!E19&"" -> C2-CC UNITED BLUE | F7: ='16U BOYS GOLD-9 TEAMS'!F19&"" -> 10 | G7: ='16U BOYS GOLD-9 TEAMS'!G19&"" -> C3-SD SHORES GOLD | H7: ='16U BOYS GOLD-9 TEAMS'!H19&"" -> 8 | I7: ='16U BOYS GOLD-9 TEAMS'!I19&"" -> C bracket C2,C3 | J7: ='16U BOYS GOLD-9 TEAMS'!J19&"" -> 16U_BOYS_GOLD
A8: ='16U BOYS GOLD-9 TEAMS'!A20 -> 45724 | B8: ='16U BOYS GOLD-9 TEAMS'!B20 -> 0.64583333 | C8: ='16U BOYS GOLD-9 TEAMS'!C20&"" -> COSTA MESA HS | D8: ='16U BOYS GOLD-9 TEAMS'!D20&"" -> 16Bau07 | E8: ='16U BOYS GOLD-9 TEAMS'!E20&"" -> A1-SAN FRANCISCO | F8: ='16U BOYS GOLD-9 TEAMS'!F20&"" -> 12 | G8: ='16U BOYS GOLD-9 TEAMS'!G20&"" -> A2-MISSION B | H8: ='16U BOYS GOLD-9 TEAMS'!H20&"" -> 6 | I8: ='16U BOYS GOLD-9 TEAMS'!I20&"" -> A bracket A1,A2 | J8: ='16U BOYS GOLD-9 TEAMS'!J20&"" -> 16U_BOYS_GOLD
A9: ='16U BOYS GOLD-9 TEAMS'!A21 -> 45724 | B9: ='16U BOYS GOLD-9 TEAMS'!B21 -> 0.6875 | C9: ='16U BOYS GOLD-9 TEAMS'!C21&"" -> COSTA MESA HS | D9: ='16U BOYS GOLD-9 TEAMS'!D21&"" -> 16Bau08 | E9: ='16U BOYS GOLD-9 TEAMS'!E21&"" -> B2-PEGASUS WP | F9: ='16U BOYS GOLD-9 TEAMS'!F21&"" -> 9 | G9: ='16U BOYS GOLD-9 TEAMS'!G21&"" -> B3-OCWP RED | H9: ='16U BOYS GOLD-9 TEAMS'!H21&"" -> 4 | I9: ='16U BOYS GOLD-9 TEAMS'!I21&"" -> B bracket B2,B3 | J9: ='16U BOYS GOLD-9 TEAMS'!J21&"" -> 16U_BOYS_GOLD
A10: ='16U BOYS GOLD-9 TEAMS'!A22 -> 45724 | B10: ='16U BOYS GOLD-9 TEAMS'!B22 -> 0.72916667 | C10: ='16U BOYS GOLD-9 TEAMS'!C22&"" -> COSTA MESA HS | D10: ='16U BOYS GOLD-9 TEAMS'!D22&"" -> 16Bau09 | E10: ='16U BOYS GOLD-9 TEAMS'!E22&"" -> C1-TROJAN | F10: ='16U BOYS GOLD-9 TEAMS'!F22&"" -> 5 | G10: ='16U BOYS GOLD-9 TEAMS'!G22&"" -> C3-SD SHORES GOLD | H10: ='16U BOYS GOLD-9 TEAMS'!H22&"" -> 10 | I10: ='16U BOYS GOLD-9 TEAMS'!I22&"" -> C bracket C1,C3 | J10: ='16U BOYS GOLD-9 TEAMS'!J22&"" -> 16U_BOYS_GOLD
A11: ='16U BOYS GOLD-9 TEAMS'!A26 -> 45725 | B11: ='16U BOYS GOLD-9 TEAMS'!B26 -> 0.33333333 | C11: ='16U BOYS GOLD-9 TEAMS'!C26&"" -> COSTA MESA HS | D11: ='16U BOYS GOLD-9 TEAMS'!D26&"" -> 16Bau10 | E11: ='16U BOYS GOLD-9 TEAMS'!E26&"" -> D1(3rdA)-FOOTHILL BLACK | F11: ='16U BOYS GOLD-9 TEAMS'!F26&"" -> 5 | G11: ='16U BOYS GOLD-9 TEAMS'!G26&"" -> D3(3rdC)-TROJAN | H11: ='16U BOYS GOLD-9 TEAMS'!H26&"" -> 12 | I11: ='16U BOYS GOLD-9 TEAMS'!I26&"" -> D bracket (7th-9th) D1,D3 | J11: ='16U BOYS GOLD-9 TEAMS'!J26&"" -> 16U_BOYS_GOLD
A12: ='16U BOYS GOLD-9 TEAMS'!A27 -> 45725 | B12: ='16U BOYS GOLD-9 TEAMS'!B27 -> 0.375 | C12: ='16U BOYS GOLD-9 TEAMS'!C27&"" -> COSTA MESA HS | D12: ='16U BOYS GOLD-9 TEAMS'!D27&"" -> 16Bau12 | E12: ='16U BOYS GOLD-9 TEAMS'!E27&"" -> E1(2ndA)-MISSION B | F12: ='16U BOYS GOLD-9 TEAMS'!F27&"" -> 10 | G12: ='16U BOYS GOLD-9 TEAMS'!G27&"" -> E3(2ndC)-SD SHORES GOLD | H12: ='16U BOYS GOLD-9 TEAMS'!H27&"" -> 11 | I12: ='16U BOYS GOLD-9 TEAMS'!I27&"" -> E bracket (4th-6th) E1,E3 | J12: ='16U BOYS GOLD-9 TEAMS'!J27&"" -> 16U_BOYS_GOLD
A13: ='16U BOYS GOLD-9 TEAMS'!A28 -> 45725 | B13: ='16U BOYS GOLD-9 TEAMS'!B28 -> 0.41666667 | C13: ='16U BOYS GOLD-9 TEAMS'!C28&"" -> COSTA MESA HS | D13: ='16U BOYS GOLD-9 TEAMS'!D28&"" -> 16Bau11 | E13: ='16U BOYS GOLD-9 TEAMS'!E28&"" -> F1(1stA)-SAN FRANCISCO | F13: ='16U BOYS GOLD-9 TEAMS'!F28&"" -> 4 | G13: ='16U BOYS GOLD-9 TEAMS'!G28&"" -> F3(1stC)-CC UNITED BLUE | H13: ='16U BOYS GOLD-9 TEAMS'!H28&"" -> 9 | I13: ='16U BOYS GOLD-9 TEAMS'!I28&"" -> F bracket (1st-3rd) F1,F3 | J13: ='16U BOYS GOLD-9 TEAMS'!J28&"" -> 16U_BOYS_GOLD
A14: ='16U BOYS GOLD-9 TEAMS'!A29 -> 45725 | B14: ='16U BOYS GOLD-9 TEAMS'!B29 -> 0.45833333 | C14: ='16U BOYS GOLD-9 TEAMS'!C29&"" -> COSTA MESA HS | D14: ='16U BOYS GOLD-9 TEAMS'!D29&"" -> 16Bau13 | E14: ='16U BOYS GOLD-9 TEAMS'!E29&"" -> D2(3rdB)-OCWP RED | F14: ='16U BOYS GOLD-9 TEAMS'!F29&"" -> 7 | G14: ='16U BOYS GOLD-9 TEAMS'!G29&"" -> D3(3rdC)-TROJAN | H14: ='16U BOYS GOLD-9 TEAMS'!H29&"" -> 2 | I14: ='16U BOYS GOLD-9 TEAMS'!I29&"" -> D bracket (7th-9th) D2,D3 | J14: ='16U BOYS GOLD-9 TEAMS'!J29&"" -> 16U_BOYS_GOLD
A15: ='16U BOYS GOLD-9 TEAMS'!A30 -> 45725 | B15: ='16U BOYS GOLD-9 TEAMS'!B30 -> 0.5 | C15: ='16U BOYS GOLD-9 TEAMS'!C30&"" -> COSTA MESA HS | D15: ='16U BOYS GOLD-9 TEAMS'!D30&"" -> 16Bau14 | E15: ='16U BOYS GOLD-9 TEAMS'!E30&"" -> E2(2ndB)-PEGASUS | F15: ='16U BOYS GOLD-9 TEAMS'!F30&"" -> 7 | G15: ='16U BOYS GOLD-9 TEAMS'!G30&"" -> E3(2ndC)-SD SHORES GOLD | H15: ='16U BOYS GOLD-9 TEAMS'!H30&"" -> 17 | I15: ='16U BOYS GOLD-9 TEAMS'!I30&"" -> E bracket (4th-6th) E2,E3 | J15: ='16U BOYS GOLD-9 TEAMS'!J30&"" -> 16U_BOYS_GOLD
A16: ='16U BOYS GOLD-9 TEAMS'!A31 -> 45725 | B16: ='16U BOYS GOLD-9 TEAMS'!B31 -> 0.54166667 | C16: ='16U BOYS GOLD-9 TEAMS'!C31&"" -> COSTA MESA HS | D16: ='16U BOYS GOLD-9 TEAMS'!D31&"" -> 16Bau15 | E16: ='16U BOYS GOLD-9 TEAMS'!E31&"" -> F2(1stB)-LA PREMIER | F16: ='16U BOYS GOLD-9 TEAMS'!F31&"" -> 11 | G16: ='16U BOYS GOLD-9 TEAMS'!G31&"" -> F3(1stC)-CC UNITED BLUE | H16: ='16U BOYS GOLD-9 TEAMS'!H31&"" -> 6 | I16: ='16U BOYS GOLD-9 TEAMS'!I31&"" -> F bracket (1st-3rd) F2,F3 | J16: ='16U BOYS GOLD-9 TEAMS'!J31&"" -> 16U_BOYS_GOLD
A17: ='16U BOYS GOLD-9 TEAMS'!A32 -> 45725 | B17: ='16U BOYS GOLD-9 TEAMS'!B32 -> 0.58333333 | C17: ='16U BOYS GOLD-9 TEAMS'!C32&"" -> COSTA MESA HS | D17: ='16U BOYS GOLD-9 TEAMS'!D32&"" -> 16Bau16 | E17: ='16U BOYS GOLD-9 TEAMS'!E32&"" -> D1(3rdA)-FOOTHILL BLACK | F17: ='16U BOYS GOLD-9 TEAMS'!F32&"" -> 6 | G17: ='16U BOYS GOLD-9 TEAMS'!G32&"" -> D2(3rdB)-OCWP RED | H17: ='16U BOYS GOLD-9 TEAMS'!H32&"" -> 16 | I17: ='16U BOYS GOLD-9 TEAMS'!I32&"" -> D bracket (7th-9th) D1,D2 | J17: ='16U BOYS GOLD-9 TEAMS'!J32&"" -> 16U_BOYS_GOLD
A18: ='16U BOYS GOLD-9 TEAMS'!A33 -> 45725 | B18: ='16U BOYS GOLD-9 TEAMS'!B33 -> 0.625 | C18: ='16U BOYS GOLD-9 TEAMS'!C33&"" -> COSTA MESA HS | D18: ='16U BOYS GOLD-9 TEAMS'!D33&"" -> 16Bau17 | E18: ='16U BOYS GOLD-9 TEAMS'!E33&"" -> E1(2ndA)-MISSION B | F18: ='16U BOYS GOLD-9 TEAMS'!F33&"" -> 12 | G18: ='16U BOYS GOLD-9 TEAMS'!G33&"" -> E2(2ndB)-PEGASUS | H18: ='16U BOYS GOLD-9 TEAMS'!H33&"" -> 10 | I18: ='16U BOYS GOLD-9 TEAMS'!I33&"" -> E bracket (4th-6th) E1,E2 | J18: ='16U BOYS GOLD-9 TEAMS'!J33&"" -> 16U_BOYS_GOLD
A19: ='16U BOYS GOLD-9 TEAMS'!A34 -> 45725 | B19: ='16U BOYS GOLD-9 TEAMS'!B34 -> 0.66666667 | C19: ='16U BOYS GOLD-9 TEAMS'!C34&"" -> COSTA MESA HS | D19: ='16U BOYS GOLD-9 TEAMS'!D34&"" -> 16Bau18 | E19: ='16U BOYS GOLD-9 TEAMS'!E34&"" -> F1(1stA)-SAN FRANCISCO | F19: ='16U BOYS GOLD-9 TEAMS'!F34&"" -> 9 | G19: ='16U BOYS GOLD-9 TEAMS'!G34&"" -> F2(1stB)-LA PREMIER | H19: ='16U BOYS GOLD-9 TEAMS'!H34&"" -> 15 | I19: ='16U BOYS GOLD-9 TEAMS'!I34&"" -> F bracket (1st-3rd) F1,F2 | J19: ='16U BOYS GOLD-9 TEAMS'!J34&"" -> 16U_BOYS_GOLD
A20: ='16U BOYS PLATINUM-19 TEAMS'!A24 -> 45724 | B20: ='16U BOYS PLATINUM-19 TEAMS'!B24 -> 0.33333333 | C20: ='16U BOYS PLATINUM-19 TEAMS'!C24&"" -> WESTMINSTER HS | D20: ='16U BOYS PLATINUM-19 TEAMS'!D24&"" -> 16Bpt01 | E20: ='16U BOYS PLATINUM-19 TEAMS'!E24&"" -> C1-STANFORD | F20: ='16U BOYS PLATINUM-19 TEAMS'!F24&"" -> 18 | G20: ='16U BOYS PLATINUM-19 TEAMS'!G24&"" -> C3-CHAWP | H20: ='16U BOYS PLATINUM-19 TEAMS'!H24&"" -> 10 | I20: ='16U BOYS PLATINUM-19 TEAMS'!I24&"" -> C bracket C1,C3 | J20: ='16U BOYS PLATINUM-19 TEAMS'!J24&"" -> 16U_BOYS_PLATINUM
A21: ='16U BOYS PLATINUM-19 TEAMS'!A37 -> 45724 | B21: ='16U BOYS PLATINUM-19 TEAMS'!B37 -> 0.33333333 | C21: ='16U BOYS PLATINUM-19 TEAMS'!C37&"" -> ESTANCIA HS | D21: ='16U BOYS PLATINUM-19 TEAMS'!D37&"" -> 16Bpt02 | E21: ='16U BOYS PLATINUM-19 TEAMS'!E37&"" -> E1-MISSION A | F21: ='16U BOYS PLATINUM-19 TEAMS'!F37&"" -> 13 | G21: ='16U BOYS PLATINUM-19 TEAMS'!G37&"" -> E3-VANGUARD BLUE | H21: ='16U BOYS PLATINUM-19 TEAMS'!H37&"" -> 1 | I21: ='16U BOYS PLATINUM-19 TEAMS'!I37&"" -> E bracket E1,E3 | J21: ='16U BOYS PLATINUM-19 TEAMS'!J37&"" -> 16U_BOYS_PLATINUM
A22: ='16U BOYS PLATINUM-19 TEAMS'!A25 -> 45724 | B22: ='16U BOYS PLATINUM-19 TEAMS'!B25 -> 0.375 | C22: ='16U BOYS PLATINUM-19 TEAMS'!C25&"" -> WESTMINSTER HS | D22: ='16U BOYS PLATINUM-19 TEAMS'!D25&"" -> 16Bpt03 | E22: ='16U BOYS PLATINUM-19 TEAMS'!E25&"" -> A1-DEL MAR | F22: ='16U BOYS PLATINUM-19 TEAMS'!F25&"" -> 18 | G22: ='16U BOYS PLATINUM-19 TEAMS'!G25&"" -> A3-NORTH IRVINE BLACK | H22: ='16U BOYS PLATINUM-19 TEAMS'!H25&"" -> 9 | I22: ='16U BOYS PLATINUM-19 TEAMS'!I25&"" -> A bracket A1,A3 | J22: ='16U BOYS PLATINUM-19 TEAMS'!J25&"" -> 16U_BOYS_PLATINUM
A23: ='16U BOYS PLATINUM-19 TEAMS'!A38 -> 45724 | B23: ='16U BOYS PLATINUM-19 TEAMS'!B38 -> 0.375 | C23: ='16U BOYS PLATINUM-19 TEAMS'!C38&"" -> ESTANCIA HS | D23: ='16U BOYS PLATINUM-19 TEAMS'!D38&"" -> 16Bpt04 | E23: ='16U BOYS PLATINUM-19 TEAMS'!E38&"" -> D1-CC UNITED BLACK | F23: ='16U BOYS PLATINUM-19 TEAMS'!F38&"" -> 15 | G23: ='16U BOYS PLATINUM-19 TEAMS'!G38&"" -> D3-PATRIOT | H23: ='16U BOYS PLATINUM-19 TEAMS'!H38&"" -> 7 | I23: ='16U BOYS PLATINUM-19 TEAMS'!I38&"" -> D bracket D1,D3 | J23: ='16U BOYS PLATINUM-19 TEAMS'!J38&"" -> 16U_BOYS_PLATINUM
A24: ='16U BOYS PLATINUM-19 TEAMS'!A26 -> 45724 | B24: ='16U BOYS PLATINUM-19 TEAMS'!B26 -> 0.41666667 | C24: ='16U BOYS PLATINUM-19 TEAMS'!C26&"" -> WESTMINSTER HS | D24: ='16U BOYS PLATINUM-19 TEAMS'!D26&"" -> 16Bpt05 | E24: ='16U BOYS PLATINUM-19 TEAMS'!E26&"" -> B2-ORANGE COUNTY WPC BLUE | F24: ='16U BOYS PLATINUM-19 TEAMS'!F26&"" -> 15 | G24: ='16U BOYS PLATINUM-19 TEAMS'!G26&"" -> B3-ROSE BOWL RED | H24: ='16U BOYS PLATINUM-19 TEAMS'!H26&"" -> 8 | I24: ='16U BOYS PLATINUM-19 TEAMS'!I26&"" -> B bracket B2,B3 | J24: ='16U BOYS PLATINUM-19 TEAMS'!J26&"" -> 16U_BOYS_PLATINUM
A25: ='16U BOYS PLATINUM-19 TEAMS'!A39 -> 45724 | B25: ='16U BOYS PLATINUM-19 TEAMS'!B39 -> 0.41666667 | C25: ='16U BOYS PLATINUM-19 TEAMS'!C39&"" -> ESTANCIA HS | D25: ='16U BOYS PLATINUM-19 TEAMS'!D39&"" -> 16Bpt06 | E25: ='16U BOYS PLATINUM-19 TEAMS'!E39&"" -> F1-TROJAN | F25: ='16U BOYS PLATINUM-19 TEAMS'!F39&"" -> 10 | G25: ='16U BOYS PLATINUM-19 TEAMS'!G39&"" -> F4-FOOTHILL RED | H25: ='16U BOYS PLATINUM-19 TEAMS'!H39&"" -> 8 | I25: ='16U BOYS PLATINUM-19 TEAMS'!I39&"" -> W/L F1/F4 | J25: ='16U BOYS PLATINUM-19 TEAMS'!J39&"" -> 16U_BOYS_PLATINUM
A26: ='16U BOYS PLATINUM-19 TEAMS'!A40 -> 45724 | B26: ='16U BOYS PLATINUM-19 TEAMS'!B40 -> 0.45833333 | C26: ='16U BOYS PLATINUM-19 TEAMS'!C40&"" -> ESTANCIA HS | D26: ='16U BOYS PLATINUM-19 TEAMS'!D40&"" -> 16Bpt08 | E26: ='16U BOYS PLATINUM-19 TEAMS'!E40&"" -> E2-ATHERTON | F26: ='16U BOYS PLATINUM-19 TEAMS'!F40&"" -> 14 | G26: ='16U BOYS PLATINUM-19 TEAMS'!G40&"" -> E3-VANGUARD BLUE | H26: ='16U BOYS PLATINUM-19 TEAMS'!H40&"" -> 8 | I26: ='16U BOYS PLATINUM-19 TEAMS'!I40&"" -> E bracket E2,E3 | J26: ='16U BOYS PLATINUM-19 TEAMS'!J40&"" -> 16U_BOYS_PLATINUM
A27: ='16U BOYS PLATINUM-19 TEAMS'!A28 -> 45724 | B27: ='16U BOYS PLATINUM-19 TEAMS'!B28 -> 0.5 | C27: ='16U BOYS PLATINUM-19 TEAMS'!C28&"" -> WESTMINSTER HS | D27: ='16U BOYS PLATINUM-19 TEAMS'!D28&"" -> 16Bpt07 | E27: ='16U BOYS PLATINUM-19 TEAMS'!E28&"" -> C2-LA JOLLA UNITED NAVY | F27: ='16U BOYS PLATINUM-19 TEAMS'!F28&"" -> 15 | G27: ='16U BOYS PLATINUM-19 TEAMS'!G28&"" -> C3-CHAWP | H27: ='16U BOYS PLATINUM-19 TEAMS'!H28&"" -> 8 | I27: ='16U BOYS PLATINUM-19 TEAMS'!I28&"" -> C bracket C2,C3 | J27: ='16U BOYS PLATINUM-19 TEAMS'!J28&"" -> 16U_BOYS_PLATINUM
A28: ='16U BOYS PLATINUM-19 TEAMS'!A41 -> 45724 | B28: ='16U BOYS PLATINUM-19 TEAMS'!B41 -> 0.5 | C28: ='16U BOYS PLATINUM-19 TEAMS'!C41&"" -> ESTANCIA HS | D28: ='16U BOYS PLATINUM-19 TEAMS'!D41&"" -> 16Bpt10 | E28: ='16U BOYS PLATINUM-19 TEAMS'!E41&"" -> F2-SD SHORES BLACK | F28: ='16U BOYS PLATINUM-19 TEAMS'!F41&"" -> 13 | G28: ='16U BOYS PLATINUM-19 TEAMS'!G41&"" -> F3-TEXAS THUINDER | H28: ='16U BOYS PLATINUM-19 TEAMS'!H41&"" -> 7 | I28: ='16U BOYS PLATINUM-19 TEAMS'!I41&"" -> W/L F2/F3 | J28: ='16U BOYS PLATINUM-19 TEAMS'!J41&"" -> 16U_BOYS_PLATINUM
A29: ='16U BOYS PLATINUM-19 TEAMS'!A29 -> 45724 | B29: ='16U BOYS PLATINUM-19 TEAMS'!B29 -> 0.54166667 | C29: ='16U BOYS PLATINUM-19 TEAMS'!C29&"" -> WESTMINSTER HS | D29: ='16U BOYS PLATINUM-19 TEAMS'!D29&"" -> 16Bpt09 | E29: ='16U BOYS PLATINUM-19 TEAMS'!E29&"" -> A2-DIABLO RED | F29: ='16U BOYS PLATINUM-19 TEAMS'!F29&"" -> 8 | G29: ='16U BOYS PLATINUM-19 TEAMS'!G29&"" -> A3-NORTH IRVINE BLACK | H29: ='16U BOYS PLATINUM-19 TEAMS'!H29&"" -> 14 | I29: ='16U BOYS PLATINUM-19 TEAMS'!I29&"" -> A bracket A2,A3 | J29: ='16U BOYS PLATINUM-19 TEAMS'!J29&"" -> 16U_BOYS_PLATINUM
A30: ='16U BOYS PLATINUM-19 TEAMS'!A42 -> 45724 | B30: ='16U BOYS PLATINUM-19 TEAMS'!B42 -> 0.54166667 | C30: ='16U BOYS PLATINUM-19 TEAMS'!C42&"" -> ESTANCIA HS | D30: ='16U BOYS PLATINUM-19 TEAMS'!D42&"" -> 16Bpt12 | E30: ='16U BOYS PLATINUM-19 TEAMS'!E42&"" -> D2-NEWPORT | F30: ='16U BOYS PLATINUM-19 TEAMS'!F42&"" -> 11 | G30: ='16U BOYS PLATINUM-19 TEAMS'!G42&"" -> D3-PATRIOT | H30: ='16U BOYS PLATINUM-19 TEAMS'!H42&"" -> 6 | I30: ='16U BOYS PLATINUM-19 TEAMS'!I42&"" -> D bracket D2,D3 | J30: ='16U BOYS PLATINUM-19 TEAMS'!J42&"" -> 16U_BOYS_PLATINUM
A31: ='16U BOYS PLATINUM-19 TEAMS'!A30 -> 45724 | B31: ='16U BOYS PLATINUM-19 TEAMS'!B30 -> 0.58333333 | C31: ='16U BOYS PLATINUM-19 TEAMS'!C30&"" -> WESTMINSTER HS | D31: ='16U BOYS PLATINUM-19 TEAMS'!D30&"" -> 16Bpt11 | E31: ='16U BOYS PLATINUM-19 TEAMS'!E30&"" -> B1-CHANNEL ISLANDS UNITED GOLD | F31: ='16U BOYS PLATINUM-19 TEAMS'!F30&"" -> 17 | G31: ='16U BOYS PLATINUM-19 TEAMS'!G30&"" -> B3-ROSE BOWL RED | H31: ='16U BOYS PLATINUM-19 TEAMS'!H30&"" -> 5 | I31: ='16U BOYS PLATINUM-19 TEAMS'!I30&"" -> B bracket B1,B3 | J31: ='16U BOYS PLATINUM-19 TEAMS'!J30&"" -> 16U_BOYS_PLATINUM
A32: ='16U BOYS PLATINUM-19 TEAMS'!A43 -> 45724 | B32: ='16U BOYS PLATINUM-19 TEAMS'!B43 -> 0.58333333 | C32: ='16U BOYS PLATINUM-19 TEAMS'!C43&"" -> ESTANCIA HS | D32: ='16U BOYS PLATINUM-19 TEAMS'!D43&"" -> 16Bpt14 | E32: ='16U BOYS PLATINUM-19 TEAMS'!E43&"" -> E1-MISSION A | F32: ='16U BOYS PLATINUM-19 TEAMS'!F43&"" -> 8 | G32: ='16U BOYS PLATINUM-19 TEAMS'!G43&"" -> E2-ATHERTON | H32: ='16U BOYS PLATINUM-19 TEAMS'!H43&"" -> 5 | I32: ='16U BOYS PLATINUM-19 TEAMS'!I43&"" -> E bracket E1,E2 | J32: ='16U BOYS PLATINUM-19 TEAMS'!J43&"" -> 16U_BOYS_PLATINUM
A33: ='16U BOYS PLATINUM-19 TEAMS'!A31 -> 45724 | B33: ='16U BOYS PLATINUM-19 TEAMS'!B31 -> 0.625 | C33: ='16U BOYS PLATINUM-19 TEAMS'!C31&"" -> WESTMINSTER HS | D33: ='16U BOYS PLATINUM-19 TEAMS'!D31&"" -> 16Bpt13 | E33: ='16U BOYS PLATINUM-19 TEAMS'!E31&"" -> C1-STANFORD | F33: ='16U BOYS PLATINUM-19 TEAMS'!F31&"" -> 17 | G33: ='16U BOYS PLATINUM-19 TEAMS'!G31&"" -> C2-LA JOLLA UNITED NAVY | H33: ='16U BOYS PLATINUM-19 TEAMS'!H31&"" -> 10 | I33: ='16U BOYS PLATINUM-19 TEAMS'!I31&"" -> C bracket C1,C2 | J33: ='16U BOYS PLATINUM-19 TEAMS'!J31&"" -> 16U_BOYS_PLATINUM
A34: ='16U BOYS PLATINUM-19 TEAMS'!A44 -> 45724 | B34: ='16U BOYS PLATINUM-19 TEAMS'!B44 -> 0.625 | C34: ='16U BOYS PLATINUM-19 TEAMS'!C44&"" -> ESTANCIA HS | D34: ='16U BOYS PLATINUM-19 TEAMS'!D44&"" -> 16Bpt16 | E34: ='16U BOYS PLATINUM-19 TEAMS'!E44&"" -> W#6-TROJAN | F34: ='16U BOYS PLATINUM-19 TEAMS'!F44&"" -> 7 | G34: ='16U BOYS PLATINUM-19 TEAMS'!G44&"" -> W#10-SD SHORES BLACK | H34: ='16U BOYS PLATINUM-19 TEAMS'!H44&"" -> 9 | I34: ='16U BOYS PLATINUM-19 TEAMS'!I44&"" -> 1st/2ndF | J34: ='16U BOYS PLATINUM-19 TEAMS'!J44&"" -> 16U_BOYS_PLATINUM
A35: ='16U BOYS PLATINUM-19 TEAMS'!A32 -> 45724 | B35: ='16U BOYS PLATINUM-19 TEAMS'!B32 -> 0.66666667 | C35: ='16U BOYS PLATINUM-19 TEAMS'!C32&"" -> WESTMINSTER HS | D35: ='16U BOYS PLATINUM-19 TEAMS'!D32&"" -> 16Bpt15 | E35: ='16U BOYS PLATINUM-19 TEAMS'!E32&"" -> A1-DEL MAR | F35: ='16U BOYS PLATINUM-19 TEAMS'!F32&"" -> 19 | G35: ='16U BOYS PLATINUM-19 TEAMS'!G32&"" -> A2-DIABLO RED | H35: ='16U BOYS PLATINUM-19 TEAMS'!H32&"" -> 5 | I35: ='16U BOYS PLATINUM-19 TEAMS'!I32&"" -> A bracket A1,A2 | J35: ='16U BOYS PLATINUM-19 TEAMS'!J32&"" -> 16U_BOYS_PLATINUM
A36: ='16U BOYS PLATINUM-19 TEAMS'!A45 -> 45724 | B36: ='16U BOYS PLATINUM-19 TEAMS'!B45 -> 0.66666667 | C36: ='16U BOYS PLATINUM-19 TEAMS'!C45&"" -> ESTANCIA HS | D36: ='16U BOYS PLATINUM-19 TEAMS'!D45&"" -> 16Bpt18 | E36: ='16U BOYS PLATINUM-19 TEAMS'!E45&"" -> L#6-FOOTHILL RED | F36: ='16U BOYS PLATINUM-19 TEAMS'!F45&"" -> 9 | G36: ='16U BOYS PLATINUM-19 TEAMS'!G45&"" -> L#10-TEXAS THUINDER | H36: ='16U BOYS PLATINUM-19 TEAMS'!H45&"" -> 10 | I36: ='16U BOYS PLATINUM-19 TEAMS'!I45&"" -> 3rd/4thF | J36: ='16U BOYS PLATINUM-19 TEAMS'!J45&"" -> 16U_BOYS_PLATINUM
A37: ='16U BOYS PLATINUM-19 TEAMS'!A46 -> 45724 | B37: ='16U BOYS PLATINUM-19 TEAMS'!B46 -> 0.70833333 | C37: ='16U BOYS PLATINUM-19 TEAMS'!C46&"" -> ESTANCIA HS | D37: ='16U BOYS PLATINUM-19 TEAMS'!D46&"" -> 16Bpt20 | E37: ='16U BOYS PLATINUM-19 TEAMS'!E46&"" -> D1-CC UNITED BLACK | F37: ='16U BOYS PLATINUM-19 TEAMS'!F46&"" -> 17 | G37: ='16U BOYS PLATINUM-19 TEAMS'!G46&"" -> D2-NEWPORT | H37: ='16U BOYS PLATINUM-19 TEAMS'!H46&"" -> 6 | I37: ='16U BOYS PLATINUM-19 TEAMS'!I46&"" -> D bracket D1,D2 | J37: ='16U BOYS PLATINUM-19 TEAMS'!J46&"" -> 16U_BOYS_PLATINUM
A38: ='16U BOYS PLATINUM-19 TEAMS'!A34 -> 45724 | B38: ='16U BOYS PLATINUM-19 TEAMS'!B34 -> 0.75 | C38: ='16U BOYS PLATINUM-19 TEAMS'!C34&"" -> WESTMINSTER HS | D38: ='16U BOYS PLATINUM-19 TEAMS'!D34&"" -> 16Bpt17 | E38: ='16U BOYS PLATINUM-19 TEAMS'!E34&"" -> B1-CHANNEL ISLANDS UNITED GOLD | F38: ='16U BOYS PLATINUM-19 TEAMS'!F34&"" -> 13 | G38: ='16U BOYS PLATINUM-19 TEAMS'!G34&"" -> B2-ORANGE COUNTY WPC BLUE | H38: ='16U BOYS PLATINUM-19 TEAMS'!H34&"" -> 10 | I38: ='16U BOYS PLATINUM-19 TEAMS'!I34&"" -> B bracket B1,B2 | J38: ='16U BOYS PLATINUM-19 TEAMS'!J34&"" -> 16U_BOYS_PLATINUM
A39: ='16U BOYS PLATINUM-19 TEAMS'!A47 -> 45724 | B39: ='16U BOYS PLATINUM-19 TEAMS'!B47 -> 0.75 | C39: ='16U BOYS PLATINUM-19 TEAMS'!C47&"" -> ESTANCIA HS | D39: ='16U BOYS PLATINUM-19 TEAMS'!D47&"" -> 16Bpt21 | E39: ='16U BOYS PLATINUM-19 TEAMS'!E47&"" -> H2(1stE)-MISSION | F39: ='16U BOYS PLATINUM-19 TEAMS'!F47&"" -> 11 | G39: ='16U BOYS PLATINUM-19 TEAMS'!G47&"" -> H3(1stF)-SD SHORES BLACK | H39: ='16U BOYS PLATINUM-19 TEAMS'!H47&"" -> 8 | I39: ='16U BOYS PLATINUM-19 TEAMS'!I47&"" -> H bracket H2,H3 (1E,1F) | J39: ='16U BOYS PLATINUM-19 TEAMS'!J47&"" -> 16U_BOYS_PLATINUM
A40: ='16U BOYS PLATINUM-19 TEAMS'!A35 -> 45724 | B40: ='16U BOYS PLATINUM-19 TEAMS'!B35 -> 0.79166667 | C40: ='16U BOYS PLATINUM-19 TEAMS'!C35&"" -> WESTMINSTER HS | D40: ='16U BOYS PLATINUM-19 TEAMS'!D35&"" -> 16Bpt19 | E40: ='16U BOYS PLATINUM-19 TEAMS'!E35&"" -> G1(1stA)-DEL MAR | F40: ='16U BOYS PLATINUM-19 TEAMS'!F35&"" -> 13 | G40: ='16U BOYS PLATINUM-19 TEAMS'!G35&"" -> G3(1stC)-STANFORD | H40: ='16U BOYS PLATINUM-19 TEAMS'!H35&"" -> 14 | I40: ='16U BOYS PLATINUM-19 TEAMS'!I35&"" -> G bracket G1,G3 (1A,1C) | J40: ='16U BOYS PLATINUM-19 TEAMS'!J35&"" -> 16U_BOYS_PLATINUM
...

Sheet MASTER BY TIME
A1: ='16U BOYS GOLD-9 TEAMS'!A13 -> DATE | B1: ='16U BOYS GOLD-9 TEAMS'!B13 -> TIME | C1: ='16U BOYS GOLD-9 TEAMS'!C13&"" -> LOCATION | D1: ='16U BOYS GOLD-9 TEAMS'!D13&"" -> GAME ID | E1: ='16U BOYS GOLD-9 TEAMS'!E13&"" -> WHITE TEAM | F1: ='16U BOYS GOLD-9 TEAMS'!F13&"" -> S | G1: ='16U BOYS GOLD-9 TEAMS'!G13&"" -> DARK TEAM | H1: ='16U BOYS GOLD-9 TEAMS'!H13&"" -> S | I1: ='16U BOYS GOLD-9 TEAMS'!I13&"" -> COMMENTS | J1: ='16U BOYS GOLD-9 TEAMS'!J13&"" -> DIVISION
A2: ='18U BOYS-24 TEAMS'!A27 -> 45724 | B2: ='18U BOYS-24 TEAMS'!B27 -> 0.33333333 | C2: ='18U BOYS-24 TEAMS'!C27&"" -> EL TORO HS | D2: ='18U BOYS-24 TEAMS'!D27&"" -> 18B01 | E2: ='18U BOYS-24 TEAMS'!E27&"" -> 5-CC UNITED | F2: ='18U BOYS-24 TEAMS'!F27&"" -> 12 | G2: ='18U BOYS-24 TEAMS'!G27&"" -> 20-FOOTHILL RED | H2: ='18U BOYS-24 TEAMS'!H27&"" -> 7 | I2: ='18U BOYS-24 TEAMS'!I27&"" -> W/L C1/C4 | J2: ='18U BOYS-24 TEAMS'!J27&"" -> 18U_BOYS
A3: ='16U BOYS PLATINUM-19 TEAMS'!A37 -> 45724 | B3: ='16U BOYS PLATINUM-19 TEAMS'!B37 -> 0.33333333 | C3: ='16U BOYS PLATINUM-19 TEAMS'!C37&"" -> ESTANCIA HS | D3: ='16U BOYS PLATINUM-19 TEAMS'!D37&"" -> 16Bpt02 | E3: ='16U BOYS PLATINUM-19 TEAMS'!E37&"" -> E1-MISSION A | F3: ='16U BOYS PLATINUM-19 TEAMS'!F37&"" -> 13 | G3: ='16U BOYS PLATINUM-19 TEAMS'!G37&"" -> E3-VANGUARD BLUE | H3: ='16U BOYS PLATINUM-19 TEAMS'!H37&"" -> 1 | I3: ='16U BOYS PLATINUM-19 TEAMS'!I37&"" -> E bracket E1,E3 | J3: ='16U BOYS PLATINUM-19 TEAMS'!J37&"" -> 16U_BOYS_PLATINUM
A4: ='18U BOYS-24 TEAMS'!A42 -> 45724 | B4: ='18U BOYS-24 TEAMS'!B42 -> 0.33333333 | C4: ='18U BOYS-24 TEAMS'!C42&"" -> MARINA HS | D4: ='18U BOYS-24 TEAMS'!D42&"" -> 18B02 | E4: ='18U BOYS-24 TEAMS'!E42&"" -> 2-NORTH IRVINE BEAST BOYS | F4: ='18U BOYS-24 TEAMS'!F42&"" -> 18 | G4: ='18U BOYS-24 TEAMS'!G42&"" -> 23-TEXAS THUNDER | H4: ='18U BOYS-24 TEAMS'!H42&"" -> 7 | I4: ='18U BOYS-24 TEAMS'!I42&"" -> W/L D1/D4 | J4: ='18U BOYS-24 TEAMS'!J42&"" -> 18U_BOYS
A5: ='16U BOYS PLATINUM-19 TEAMS'!A24 -> 45724 | B5: ='16U BOYS PLATINUM-19 TEAMS'!B24 -> 0.33333333 | C5: ='16U BOYS PLATINUM-19 TEAMS'!C24&"" -> WESTMINSTER HS | D5: ='16U BOYS PLATINUM-19 TEAMS'!D24&"" -> 16Bpt01 | E5: ='16U BOYS PLATINUM-19 TEAMS'!E24&"" -> C1-STANFORD | F5: ='16U BOYS PLATINUM-19 TEAMS'!F24&"" -> 18 | G5: ='16U BOYS PLATINUM-19 TEAMS'!G24&"" -> C3-CHAWP | H5: ='16U BOYS PLATINUM-19 TEAMS'!H24&"" -> 10 | I5: ='16U BOYS PLATINUM-19 TEAMS'!I24&"" -> C bracket C1,C3 | J5: ='16U BOYS PLATINUM-19 TEAMS'!J24&"" -> 16U_BOYS_PLATINUM
A6: ='18U BOYS-24 TEAMS'!A28 -> 45724 | B6: ='18U BOYS-24 TEAMS'!B28 -> 0.375 | C6: ='18U BOYS-24 TEAMS'!C28&"" -> EL TORO HS | D6: ='18U BOYS-24 TEAMS'!D28&"" -> 18B03 | E6: ='18U BOYS-24 TEAMS'!E28&"" -> 8-SD SHORES BLACK | F6: ='18U BOYS-24 TEAMS'!F28&"" -> 12 | G6: ='18U BOYS-24 TEAMS'!G28&"" -> 17-CHAWP | H6: ='18U BOYS-24 TEAMS'!H28&"" -> 11 | I6: ='18U BOYS-24 TEAMS'!I28&"" -> W/L C2/C3 | J6: ='18U BOYS-24 TEAMS'!J28&"" -> 18U_BOYS
A7: ='16U BOYS PLATINUM-19 TEAMS'!A38 -> 45724 | B7: ='16U BOYS PLATINUM-19 TEAMS'!B38 -> 0.375 | C7: ='16U BOYS PLATINUM-19 TEAMS'!C38&"" -> ESTANCIA HS | D7: ='16U BOYS PLATINUM-19 TEAMS'!D38&"" -> 16Bpt04 | E7: ='16U BOYS PLATINUM-19 TEAMS'!E38&"" -> D1-CC UNITED BLACK | F7: ='16U BOYS PLATINUM-19 TEAMS'!F38&"" -> 15 | G7: ='16U BOYS PLATINUM-19 TEAMS'!G38&"" -> D3-PATRIOT | H7: ='16U BOYS PLATINUM-19 TEAMS'!H38&"" -> 7 | I7: ='16U BOYS PLATINUM-19 TEAMS'!I38&"" -> D bracket D1,D3 | J7: ='16U BOYS PLATINUM-19 TEAMS'!J38&"" -> 16U_BOYS_PLATINUM
A8: ='18U BOYS-24 TEAMS'!A43 -> 45724 | B8: ='18U BOYS-24 TEAMS'!B43 -> 0.375 | C8: ='18U BOYS-24 TEAMS'!C43&"" -> MARINA HS | D8: ='18U BOYS-24 TEAMS'!D43&"" -> 18B04 | E8: ='18U BOYS-24 TEAMS'!E43&"" -> 11-STANFORD | F8: ='18U BOYS-24 TEAMS'!F43&"" -> 14 | G8: ='18U BOYS-24 TEAMS'!G43&"" -> 14-LA JOLLA UNITED NAVY | H8: ='18U BOYS-24 TEAMS'!H43&"" -> 6 | I8: ='18U BOYS-24 TEAMS'!I43&"" -> W/L D2/D3 | J8: ='18U BOYS-24 TEAMS'!J43&"" -> 18U_BOYS
A9: ='18U BOYS-24 TEAMS'!A44 -> 45724 | B9: ='18U BOYS-24 TEAMS'!B44 -> 0.375 | C9: ='18U BOYS-24 TEAMS'!C44&"" -> TUSTIN HS | D9: ='18U BOYS-24 TEAMS'!D44&"" -> 18B08 | E9: ='18U BOYS-24 TEAMS'!E44&"" -> 10-SOCAL BLACK | F9: ='18U BOYS-24 TEAMS'!F44&"" -> 14 | G9: ='18U BOYS-24 TEAMS'!G44&"" -> 15-DIABLO RED | H9: ='18U BOYS-24 TEAMS'!H44&"" -> 6 | I9: ='18U BOYS-24 TEAMS'!I44&"" -> W/L E2/E3 | J9: ='18U BOYS-24 TEAMS'!J45&"" -> 18U_BOYS
A10: ='16U BOYS PLATINUM-19 TEAMS'!A25 -> 45724 | B10: ='16U BOYS PLATINUM-19 TEAMS'!B25 -> 0.375 | C10: ='16U BOYS PLATINUM-19 TEAMS'!C25&"" -> WESTMINSTER HS | D10: ='16U BOYS PLATINUM-19 TEAMS'!D25&"" -> 16Bpt03 | E10: ='16U BOYS PLATINUM-19 TEAMS'!E25&"" -> A1-DEL MAR | F10: ='16U BOYS PLATINUM-19 TEAMS'!F25&"" -> 18 | G10: ='16U BOYS PLATINUM-19 TEAMS'!G25&"" -> A3-NORTH IRVINE BLACK | H10: ='16U BOYS PLATINUM-19 TEAMS'!H25&"" -> 9 | I10: ='16U BOYS PLATINUM-19 TEAMS'!I25&"" -> A bracket A1,A3 | J10: ='16U BOYS PLATINUM-19 TEAMS'!J25&"" -> 16U_BOYS_PLATINUM
A11: ='16U BOYS GOLD-9 TEAMS'!A14 -> 45724 | B11: ='16U BOYS GOLD-9 TEAMS'!B14 -> 0.39583333 | C11: ='16U BOYS GOLD-9 TEAMS'!C14&"" -> COSTA MESA HS | D11: ='16U BOYS GOLD-9 TEAMS'!D14&"" -> 16Bau01 | E11: ='16U BOYS GOLD-9 TEAMS'!E14&"" -> A1-SAN FRANCISCO | F11: ='16U BOYS GOLD-9 TEAMS'!F14&"" -> 17 | G11: ='16U BOYS GOLD-9 TEAMS'!G14&"" -> A3-FOOTHILL BLACK | H11: ='16U BOYS GOLD-9 TEAMS'!H14&"" -> 1 | I11: ='16U BOYS GOLD-9 TEAMS'!I14&"" -> A bracket A1,A3 | J11: ='16U BOYS GOLD-9 TEAMS'!J14&"" -> 16U_BOYS_GOLD
A12: ='18U BOYS-24 TEAMS'!A29 -> 45724 | B12: ='18U BOYS-24 TEAMS'!B29 -> 0.41666667 | C12: ='18U BOYS-24 TEAMS'!C29&"" -> EL TORO HS | D12: ='18U BOYS-24 TEAMS'!D29&"" -> 18B05 | E12: ='18U BOYS-24 TEAMS'!E29&"" -> 1-LAMORINDA | F12: ='18U BOYS-24 TEAMS'!F29&"" -> 19 | G12: ='18U BOYS-24 TEAMS'!G29&"" -> 24-NORTH IRVINE VEGAS | H12: ='18U BOYS-24 TEAMS'!H29&"" -> 8 | I12: ='18U BOYS-24 TEAMS'!I29&"" -> W/L A1/A4 | J12: ='18U BOYS-24 TEAMS'!J29&"" -> 18U_BOYS
A13: ='16U BOYS PLATINUM-19 TEAMS'!A39 -> 45724 | B13: ='16U BOYS PLATINUM-19 TEAMS'!B39 -> 0.41666667 | C13: ='16U BOYS PLATINUM-19 TEAMS'!C39&"" -> ESTANCIA HS | D13: ='16U BOYS PLATINUM-19 TEAMS'!D39&"" -> 16Bpt06 | E13: ='16U BOYS PLATINUM-19 TEAMS'!E39&"" -> F1-TROJAN | F13: ='16U BOYS PLATINUM-19 TEAMS'!F39&"" -> 10 | G13: ='16U BOYS PLATINUM-19 TEAMS'!G39&"" -> F4-FOOTHILL RED | H13: ='16U BOYS PLATINUM-19 TEAMS'!H39&"" -> 8 | I13: ='16U BOYS PLATINUM-19 TEAMS'!I39&"" -> W/L F1/F4 | J13: ='16U BOYS PLATINUM-19 TEAMS'!J39&"" -> 16U_BOYS_PLATINUM
A14: ='18U BOYS-24 TEAMS'!A30 -> 45724 | B14: ='18U BOYS-24 TEAMS'!B30 -> 0.41666667 | C14: ='18U BOYS-24 TEAMS'!C30&"" -> MARINA HS | D14: ='18U BOYS-24 TEAMS'!D30&"" -> 18B11 | E14: ='18U BOYS-24 TEAMS'!E30&"" -> 9-SAN FRANCISCO | F14: ='18U BOYS-24 TEAMS'!F30&"" -> 13 | G14: ='18U BOYS-24 TEAMS'!G30&"" -> 16-IMPERIAL BLUE | H14: ='18U BOYS-24 TEAMS'!H30&"" -> 12 | I14: ='18U BOYS-24 TEAMS'!I30&"" -> W/L B2/B3 | J14: ='18U BOYS-24 TEAMS'!J30&"" -> 18U_BOYS
A15: ='18U BOYS-24 TEAMS'!A45 -> 45724 | B15: ='18U BOYS-24 TEAMS'!B45 -> 0.41666667 | C15: ='18U BOYS-24 TEAMS'!C45&"" -> TUSTIN HS | D15: ='18U BOYS-24 TEAMS'!D45&"" -> 18B06 | E15: ='18U BOYS-24 TEAMS'!E45&"" -> 3-DEL MAR | F15: ='18U BOYS-24 TEAMS'!F45&"" -> 13 | G15: ='18U BOYS-24 TEAMS'!G45&"" -> 22-ROSE BOWL RED | H15: ='18U BOYS-24 TEAMS'!H45&"" -> 5 | I15: ='18U BOYS-24 TEAMS'!I45&"" -> W/L E1/E4 | J15: ='18U BOYS-24 TEAMS'!J44&"" -> 18U_BOYS
A16: ='16U BOYS PLATINUM-19 TEAMS'!A26 -> 45724 | B16: ='16U BOYS PLATINUM-19 TEAMS'!B26 -> 0.41666667 | C16: ='16U BOYS PLATINUM-19 TEAMS'!C26&"" -> WESTMINSTER HS | D16: ='16U BOYS PLATINUM-19 TEAMS'!D26&"" -> 16Bpt05 | E16: ='16U BOYS PLATINUM-19 TEAMS'!E26&"" -> B2-ORANGE COUNTY WPC BLUE | F16: ='16U BOYS PLATINUM-19 TEAMS'!F26&"" -> 15 | G16: ='16U BOYS PLATINUM-19 TEAMS'!G26&"" -> B3-ROSE BOWL RED | H16: ='16U BOYS PLATINUM-19 TEAMS'!H26&"" -> 8 | I16: ='16U BOYS PLATINUM-19 TEAMS'!I26&"" -> B bracket B2,B3 | J16: ='16U BOYS PLATINUM-19 TEAMS'!J26&"" -> 16U_BOYS_PLATINUM
A17: ='16U BOYS GOLD-9 TEAMS'!A15 -> 45724 | B17: ='16U BOYS GOLD-9 TEAMS'!B15 -> 0.4375 | C17: ='16U BOYS GOLD-9 TEAMS'!C15&"" -> COSTA MESA HS | D17: ='16U BOYS GOLD-9 TEAMS'!D15&"" -> 16Bau02 | E17: ='16U BOYS GOLD-9 TEAMS'!E15&"" -> B1-LA PREMIER | F17: ='16U BOYS GOLD-9 TEAMS'!F15&"" -> 15 | G17: ='16U BOYS GOLD-9 TEAMS'!G15&"" -> B3-OCWP RED | H17: ='16U BOYS GOLD-9 TEAMS'!H15&"" -> 9 | I17: ='16U BOYS GOLD-9 TEAMS'!I15&"" -> B bracket B1,B3 | J17: ='16U BOYS GOLD-9 TEAMS'!J15&"" -> 16U_BOYS_GOLD
A18: ='18U BOYS-24 TEAMS'!A31 -> 45724 | B18: ='18U BOYS-24 TEAMS'!B31 -> 0.45833333 | C18: ='18U BOYS-24 TEAMS'!C31&"" -> EL TORO HS | D18: ='18U BOYS-24 TEAMS'!D31&"" -> 18B07 | E18: ='18U BOYS-24 TEAMS'!E31&"" -> 12-LA PREMIER | F18: ='18U BOYS-24 TEAMS'!F31&"" -> 8 | G18: ='18U BOYS-24 TEAMS'!G31&"" -> 13-VANGUARD BLUE | H18: ='18U BOYS-24 TEAMS'!H31&"" -> 13 | I18: ='18U BOYS-24 TEAMS'!I31&"" -> W/L A2/A3 | J18: ='18U BOYS-24 TEAMS'!J31&"" -> 18U_BOYS
A19: ='16U BOYS PLATINUM-19 TEAMS'!A40 -> 45724 | B19: ='16U BOYS PLATINUM-19 TEAMS'!B40 -> 0.45833333 | C19: ='16U BOYS PLATINUM-19 TEAMS'!C40&"" -> ESTANCIA HS | D19: ='16U BOYS PLATINUM-19 TEAMS'!D40&"" -> 16Bpt08 | E19: ='16U BOYS PLATINUM-19 TEAMS'!E40&"" -> E2-ATHERTON | F19: ='16U BOYS PLATINUM-19 TEAMS'!F40&"" -> 14 | G19: ='16U BOYS PLATINUM-19 TEAMS'!G40&"" -> E3-VANGUARD BLUE | H19: ='16U BOYS PLATINUM-19 TEAMS'!H40&"" -> 8 | I19: ='16U BOYS PLATINUM-19 TEAMS'!I40&"" -> E bracket E2,E3 | J19: ='16U BOYS PLATINUM-19 TEAMS'!J40&"" -> 16U_BOYS_PLATINUM
A20: ='18U BOYS-24 TEAMS'!A46 -> 45724 | B20: ='18U BOYS-24 TEAMS'!B46 -> 0.45833333 | C20: ='18U BOYS-24 TEAMS'!C46&"" -> TUSTIN HS | D20: ='18U BOYS-24 TEAMS'!D46&"" -> 18B10 | E20: ='18U BOYS-24 TEAMS'!E46&"" -> 6-CHANNEL ISLANDS UNITED GOLD | F20: ='18U BOYS-24 TEAMS'!F46&"" -> 10 | G20: ='18U BOYS-24 TEAMS'!G46&"" -> 19-MONARCHY | H20: ='18U BOYS-24 TEAMS'!H46&"" -> 4 | I20: ='18U BOYS-24 TEAMS'!I46&"" -> W/L F1/F4 | J20: ='18U BOYS-24 TEAMS'!J46&"" -> 18U_BOYS
A21: ='18U BOYS-24 TEAMS'!A32 -> 45724 | B21: ='18U BOYS-24 TEAMS'!B32 -> 0.45833333 | C21: ='18U BOYS-24 TEAMS'!C32&"" -> WESTMINSTER HS | D21: ='18U BOYS-24 TEAMS'!D32&"" -> 18B09 | E21: ='18U BOYS-24 TEAMS'!E32&"" -> 4-NEWPORT | F21: ='18U BOYS-24 TEAMS'!F32&"" -> 10 | G21: ='18U BOYS-24 TEAMS'!G32&"" -> 21-ORANGE COUNTY WPC BLUE | H21: ='18U BOYS-24 TEAMS'!H32&"" -> 5 | I21: ='18U BOYS-24 TEAMS'!I32&"" -> W/L B1/B4 | J21: ='18U BOYS-24 TEAMS'!J32&"" -> 18U_BOYS
A22: ='16U BOYS GOLD-9 TEAMS'!A16 -> 45724 | B22: ='16U BOYS GOLD-9 TEAMS'!B16 -> 0.47916667 | C22: ='16U BOYS GOLD-9 TEAMS'!C16&"" -> COSTA MESA HS | D22: ='16U BOYS GOLD-9 TEAMS'!D16&"" -> 16Bau03 | E22: ='16U BOYS GOLD-9 TEAMS'!E16&"" -> C1-TROJAN | F22: ='16U BOYS GOLD-9 TEAMS'!F16&"" -> 2 | G22: ='16U BOYS GOLD-9 TEAMS'!G16&"" -> C2-CC UNITED BLUE | H22: ='16U BOYS GOLD-9 TEAMS'!H16&"" -> 9 | I22: ='16U BOYS GOLD-9 TEAMS'!I16&"" -> C bracket C1,C2 | J22: ='16U BOYS GOLD-9 TEAMS'!J16&"" -> 16U_BOYS_GOLD
A23: ='18U BOYS-24 TEAMS'!A33 -> 45724 | B23: ='18U BOYS-24 TEAMS'!B33 -> 0.5 | C23: ='18U BOYS-24 TEAMS'!C33&"" -> EL TORO HS | D23: ='18U BOYS-24 TEAMS'!D33&"" -> 18B13 | E23: ='18U BOYS-24 TEAMS'!E33&"" -> L#1-FOOTHILL RED | F23: ='18U BOYS-24 TEAMS'!F33&"" -> 6 | G23: ='18U BOYS-24 TEAMS'!G33&"" -> L#3-CHAWP | H23: ='18U BOYS-24 TEAMS'!H33&"" -> 11 | I23: ='18U BOYS-24 TEAMS'!I33&"" -> 3rd/4thC | J23: ='18U BOYS-24 TEAMS'!J33&"" -> 18U_BOYS
A24: ='16U BOYS PLATINUM-19 TEAMS'!A41 -> 45724 | B24: ='16U BOYS PLATINUM-19 TEAMS'!B41 -> 0.5 | C24: ='16U BOYS PLATINUM-19 TEAMS'!C41&"" -> ESTANCIA HS | D24: ='16U BOYS PLATINUM-19 TEAMS'!D41&"" -> 16Bpt10 | E24: ='16U BOYS PLATINUM-19 TEAMS'!E41&"" -> F2-SD SHORES BLACK | F24: ='16U BOYS PLATINUM-19 TEAMS'!F41&"" -> 13 | G24: ='16U BOYS PLATINUM-19 TEAMS'!G41&"" -> F3-TEXAS THUINDER | H24: ='16U BOYS PLATINUM-19 TEAMS'!H41&"" -> 7 | I24: ='16U BOYS PLATINUM-19 TEAMS'!I41&"" -> W/L F2/F3 | J24: ='16U BOYS PLATINUM-19 TEAMS'!J41&"" -> 16U_BOYS_PLATINUM
A25: ='18U BOYS-24 TEAMS'!A47 -> 45724 | B25: ='18U BOYS-24 TEAMS'!B47 -> 0.5 | C25: ='18U BOYS-24 TEAMS'!C47&"" -> TUSTIN HS | D25: ='18U BOYS-24 TEAMS'!D47&"" -> 18B12 | E25: ='18U BOYS-24 TEAMS'!E47&"" -> 7-TROJAN | F25: ='18U BOYS-24 TEAMS'!F47&"" -> 12 | G25: ='18U BOYS-24 TEAMS'!G47&"" -> 18-PATRIOT | H25: ='18U BOYS-24 TEAMS'!H47&"" -> 10 | I25: ='18U BOYS-24 TEAMS'!I47&"" -> W/L F2/F3 | J25: ='18U BOYS-24 TEAMS'!J47&"" -> 18U_BOYS
A26: ='16U BOYS PLATINUM-19 TEAMS'!A28 -> 45724 | B26: ='16U BOYS PLATINUM-19 TEAMS'!B28 -> 0.5 | C26: ='16U BOYS PLATINUM-19 TEAMS'!C28&"" -> WESTMINSTER HS | D26: ='16U BOYS PLATINUM-19 TEAMS'!D28&"" -> 16Bpt07 | E26: ='16U BOYS PLATINUM-19 TEAMS'!E28&"" -> C2-LA JOLLA UNITED NAVY | F26: ='16U BOYS PLATINUM-19 TEAMS'!F28&"" -> 15 | G26: ='16U BOYS PLATINUM-19 TEAMS'!G28&"" -> C3-CHAWP | H26: ='16U BOYS PLATINUM-19 TEAMS'!H28&"" -> 8 | I26: ='16U BOYS PLATINUM-19 TEAMS'!I28&"" -> C bracket C2,C3 | J26: ='16U BOYS PLATINUM-19 TEAMS'!J28&"" -> 16U_BOYS_PLATINUM
A27: ='16U BOYS GOLD-9 TEAMS'!A17 -> 45724 | B27: ='16U BOYS GOLD-9 TEAMS'!B17 -> 0.52083333 | C27: ='16U BOYS GOLD-9 TEAMS'!C17&"" -> COSTA MESA HS | D27: ='16U BOYS GOLD-9 TEAMS'!D17&"" -> 16Bau04 | E27: ='16U BOYS GOLD-9 TEAMS'!E17&"" -> A2-MISSION B | F27: ='16U BOYS GOLD-9 TEAMS'!F17&"" -> 14 | G27: ='16U BOYS GOLD-9 TEAMS'!G17&"" -> A3-FOOTHILL BLACK | H27: ='16U BOYS GOLD-9 TEAMS'!H17&"" -> 5 | I27: ='16U BOYS GOLD-9 TEAMS'!I17&"" -> A bracket A2,A3 | J27: ='16U BOYS GOLD-9 TEAMS'!J17&"" -> 16U_BOYS_GOLD
A28: ='18U BOYS-24 TEAMS'!A34 -> 45724 | B28: ='18U BOYS-24 TEAMS'!B34 -> 0.54166667 | C28: ='18U BOYS-24 TEAMS'!C34&"" -> EL TORO HS | D28: ='18U BOYS-24 TEAMS'!D34&"" -> 18B15 | E28: ='18U BOYS-24 TEAMS'!E34&"" -> W#1-CC UNITED | F28: ='18U BOYS-24 TEAMS'!F34&"" -> 14 | G28: ='18U BOYS-24 TEAMS'!G34&"" -> W#3-SD SHORES BLACK | H28: ='18U BOYS-24 TEAMS'!H34&"" -> 12 | I28: ='18U BOYS-24 TEAMS'!I34&"" -> 1st/2ndC | J28: ='18U BOYS-24 TEAMS'!J34&"" -> 18U_BOYS
A29: ='16U BOYS PLATINUM-19 TEAMS'!A42 -> 45724 | B29: ='16U BOYS PLATINUM-19 TEAMS'!B42 -> 0.54166667 | C29: ='16U BOYS PLATINUM-19 TEAMS'!C42&"" -> ESTANCIA HS | D29: ='16U BOYS PLATINUM-19 TEAMS'!D42&"" -> 16Bpt12 | E29: ='16U BOYS PLATINUM-19 TEAMS'!E42&"" -> D2-NEWPORT | F29: ='16U BOYS PLATINUM-19 TEAMS'!F42&"" -> 11 | G29: ='16U BOYS PLATINUM-19 TEAMS'!G42&"" -> D3-PATRIOT | H29: ='16U BOYS PLATINUM-19 TEAMS'!H42&"" -> 6 | I29: ='16U BOYS PLATINUM-19 TEAMS'!I42&"" -> D bracket D2,D3 | J29: ='16U BOYS PLATINUM-19 TEAMS'!J42&"" -> 16U_BOYS_PLATINUM
A30: ='18U BOYS-24 TEAMS'!A48 -> 45724 | B30: ='18U BOYS-24 TEAMS'!B48 -> 0.54166667 | C30: ='18U BOYS-24 TEAMS'!C48&"" -> TUSTIN HS | D30: ='18U BOYS-24 TEAMS'!D48&"" -> 18B14 | E30: ='18U BOYS-24 TEAMS'!E48&"" -> L#2-TEXAS THUNDER | F30: ='18U BOYS-24 TEAMS'!F48&"" -> 5.5 | G30: ='18U BOYS-24 TEAMS'!G48&"" -> L#4-LA JOLLA UNITED NAVY | H30: ='18U BOYS-24 TEAMS'!H48&"" -> 5.4 | I30: ='18U BOYS-24 TEAMS'!I48&"" -> 3rd/4thD | J30: ='18U BOYS-24 TEAMS'!J48&"" -> 18U_BOYS
A31: ='16U BOYS PLATINUM-19 TEAMS'!A29 -> 45724 | B31: ='16U BOYS PLATINUM-19 TEAMS'!B29 -> 0.54166667 | C31: ='16U BOYS PLATINUM-19 TEAMS'!C29&"" -> WESTMINSTER HS | D31: ='16U BOYS PLATINUM-19 TEAMS'!D29&"" -> 16Bpt09 | E31: ='16U BOYS PLATINUM-19 TEAMS'!E29&"" -> A2-DIABLO RED | F31: ='16U BOYS PLATINUM-19 TEAMS'!F29&"" -> 8 | G31: ='16U BOYS PLATINUM-19 TEAMS'!G29&"" -> A3-NORTH IRVINE BLACK | H31: ='16U BOYS PLATINUM-19 TEAMS'!H29&"" -> 14 | I31: ='16U BOYS PLATINUM-19 TEAMS'!I29&"" -> A bracket A2,A3 | J31: ='16U BOYS PLATINUM-19 TEAMS'!J29&"" -> 16U_BOYS_PLATINUM
A32: ='16U BOYS GOLD-9 TEAMS'!A18 -> 45724 | B32: ='16U BOYS GOLD-9 TEAMS'!B18 -> 0.5625 | C32: ='16U BOYS GOLD-9 TEAMS'!C18&"" -> COSTA MESA HS | D32: ='16U BOYS GOLD-9 TEAMS'!D18&"" -> 16Bau05 | E32: ='16U BOYS GOLD-9 TEAMS'!E18&"" -> B1-LA PREMIER | F32: ='16U BOYS GOLD-9 TEAMS'!F18&"" -> 14 | G32: ='16U BOYS GOLD-9 TEAMS'!G18&"" -> B2-PEGASUS WP | H32: ='16U BOYS GOLD-9 TEAMS'!H18&"" -> 10 | I32: ='16U BOYS GOLD-9 TEAMS'!I18&"" -> B bracket B1,B2 | J32: ='16U BOYS GOLD-9 TEAMS'!J18&"" -> 16U_BOYS_GOLD
A33: ='18U BOYS-24 TEAMS'!A35 -> 45724 | B33: ='18U BOYS-24 TEAMS'!B35 -> 0.58333333 | C33: ='18U BOYS-24 TEAMS'!C35&"" -> EL TORO HS | D33: ='18U BOYS-24 TEAMS'!D35&"" -> 18B17 | E33: ='18U BOYS-24 TEAMS'!E35&"" -> L#5-NORTH IRVINE VEGAS | F33: ='18U BOYS-24 TEAMS'!F35&"" -> 8 | G33: ='18U BOYS-24 TEAMS'!G35&"" -> L#7-LA PREMIER | H33: ='18U BOYS-24 TEAMS'!H35&"" -> 9 | I33: ='18U BOYS-24 TEAMS'!I35&"" -> 3rd/4thA | J33: ='18U BOYS-24 TEAMS'!J35&"" -> 18U_BOYS
A34: ='16U BOYS PLATINUM-19 TEAMS'!A43 -> 45724 | B34: ='16U BOYS PLATINUM-19 TEAMS'!B43 -> 0.58333333 | C34: ='16U BOYS PLATINUM-19 TEAMS'!C43&"" -> ESTANCIA HS | D34: ='16U BOYS PLATINUM-19 TEAMS'!D43&"" -> 16Bpt14 | E34: ='16U BOYS PLATINUM-19 TEAMS'!E43&"" -> E1-MISSION A | F34: ='16U BOYS PLATINUM-19 TEAMS'!F43&"" -> 8 | G34: ='16U BOYS PLATINUM-19 TEAMS'!G43&"" -> E2-ATHERTON | H34: ='16U BOYS PLATINUM-19 TEAMS'!H43&"" -> 5 | I34: ='16U BOYS PLATINUM-19 TEAMS'!I43&"" -> E bracket E1,E2 | J34: ='16U BOYS PLATINUM-19 TEAMS'!J43&"" -> 16U_BOYS_PLATINUM
A35: ='18U BOYS-24 TEAMS'!A49 -> 45724 | B35: ='18U BOYS-24 TEAMS'!B49 -> 0.58333333 | C35: ='18U BOYS-24 TEAMS'!C49&"" -> TUSTIN HS | D35: ='18U BOYS-24 TEAMS'!D49&"" -> 18B16 | E35: ='18U BOYS-24 TEAMS'!E49&"" -> W#2-NORTH IRVINE BEAST BOYS | F35: ='18U BOYS-24 TEAMS'!F49&"" -> 10 | G35: ='18U BOYS-24 TEAMS'!G49&"" -> W#4-STANFORD | H35: ='18U BOYS-24 TEAMS'!H49&"" -> 13 | I35: ='18U BOYS-24 TEAMS'!I49&"" -> 1st/2ndD | J35: ='18U BOYS-24 TEAMS'!J49&"" -> 18U_BOYS
A36: ='16U BOYS PLATINUM-19 TEAMS'!A30 -> 45724 | B36: ='16U BOYS PLATINUM-19 TEAMS'!B30 -> 0.58333333 | C36: ='16U BOYS PLATINUM-19 TEAMS'!C30&"" -> WESTMINSTER HS | D36: ='16U BOYS PLATINUM-19 TEAMS'!D30&"" -> 16Bpt11 | E36: ='16U BOYS PLATINUM-19 TEAMS'!E30&"" -> B1-CHANNEL ISLANDS UNITED GOLD | F36: ='16U BOYS PLATINUM-19 TEAMS'!F30&"" -> 17 | G36: ='16U BOYS PLATINUM-19 TEAMS'!G30&"" -> B3-ROSE BOWL RED | H36: ='16U BOYS PLATINUM-19 TEAMS'!H30&"" -> 5 | I36: ='16U BOYS PLATINUM-19 TEAMS'!I30&"" -> B bracket B1,B3 | J36: ='16U BOYS PLATINUM-19 TEAMS'!J30&"" -> 16U_BOYS_PLATINUM
A37: ='16U BOYS GOLD-9 TEAMS'!A19 -> 45724 | B37: ='16U BOYS GOLD-9 TEAMS'!B19 -> 0.60416667 | C37: ='16U BOYS GOLD-9 TEAMS'!C19&"" -> COSTA MESA HS | D37: ='16U BOYS GOLD-9 TEAMS'!D19&"" -> 16Bau06 | E37: ='16U BOYS GOLD-9 TEAMS'!E19&"" -> C2-CC UNITED BLUE | F37: ='16U BOYS GOLD-9 TEAMS'!F19&"" -> 10 | G37: ='16U BOYS GOLD-9 TEAMS'!G19&"" -> C3-SD SHORES GOLD | H37: ='16U BOYS GOLD-9 TEAMS'!H19&"" -> 8 | I37: ='16U BOYS GOLD-9 TEAMS'!I19&"" -> C bracket C2,C3 | J37: ='16U BOYS GOLD-9 TEAMS'!J19&"" -> 16U_BOYS_GOLD
A38: ='18U BOYS-24 TEAMS'!A36 -> 45724 | B38: ='18U BOYS-24 TEAMS'!B36 -> 0.625 | C38: ='18U BOYS-24 TEAMS'!C36&"" -> EL TORO HS | D38: ='18U BOYS-24 TEAMS'!D36&"" -> 18B19 | E38: ='18U BOYS-24 TEAMS'!E36&"" -> W#5-LAMORINDA | F38: ='18U BOYS-24 TEAMS'!F36&"" -> 12 | G38: ='18U BOYS-24 TEAMS'!G36&"" -> W#7-VANGUARD BLUE | H38: ='18U BOYS-24 TEAMS'!H36&"" -> 5 | I38: ='18U BOYS-24 TEAMS'!I36&"" -> 1st/2ndA | J38: ='18U BOYS-24 TEAMS'!J36&"" -> 18U_BOYS
A39: ='16U BOYS PLATINUM-19 TEAMS'!A44 -> 45724 | B39: ='16U BOYS PLATINUM-19 TEAMS'!B44 -> 0.625 | C39: ='16U BOYS PLATINUM-19 TEAMS'!C44&"" -> ESTANCIA HS | D39: ='16U BOYS PLATINUM-19 TEAMS'!D44&"" -> 16Bpt16 | E39: ='16U BOYS PLATINUM-19 TEAMS'!E44&"" -> W#6-TROJAN | F39: ='16U BOYS PLATINUM-19 TEAMS'!F44&"" -> 7 | G39: ='16U BOYS PLATINUM-19 TEAMS'!G44&"" -> W#10-SD SHORES BLACK | H39: ='16U BOYS PLATINUM-19 TEAMS'!H44&"" -> 9 | I39: ='16U BOYS PLATINUM-19 TEAMS'!I44&"" -> 1st/2ndF | J39: ='16U BOYS PLATINUM-19 TEAMS'!J44&"" -> 16U_BOYS_PLATINUM
A40: ='18U BOYS-24 TEAMS'!A50 -> 45724 | B40: ='18U BOYS-24 TEAMS'!B50 -> 0.625 | C40: ='18U BOYS-24 TEAMS'!C50&"" -> TUSTIN HS | D40: ='18U BOYS-24 TEAMS'!D50&"" -> 18B20 | E40: ='18U BOYS-24 TEAMS'!E50&"" -> W#6-DEL MAR | F40: ='18U BOYS-24 TEAMS'!F50&"" -> 10 | G40: ='18U BOYS-24 TEAMS'!G50&"" -> W#8-SOCAL BLACK | H40: ='18U BOYS-24 TEAMS'!H50&"" -> 9 | I40: ='18U BOYS-24 TEAMS'!I50&"" -> 1st/2nd E | J40: ='18U BOYS-24 TEAMS'!J50&"" -> 18U_BOYS
...

Sheet TEAM LISTING AND BRACKETS
A1: 2025 NEWPORT SPRING INVITE
A2: CC UNITED BLUE | B2: 16U_GOLD | D2: A | E2: B | F2: C
A3: FOOTHILL BLACK | B3: 16U_GOLD | D3: A1-SAN FRANCISCO | E3: B1-LA PREMIER | F3: C1-TROJAN
A4: LA PEMIER | B4: 16U_GOLD | D4: A2-MISSION B | E4: B2-PEGASUS WP | F4: C2-CC UNITED BLUE
A5: MISSION B | B5: 16U_GOLD | D5: A3-FOOTHILL BLACK | E5: B3-OCWP RED | F5: C3-SD SHORES GOLD
A6: OCWP RED | B6: 16U_GOLD
A7: PEGASUS WP | B7: 16U_GOLD | D7: D | E7: E | F7: F
A8: SD SHORES GOLD | B8: 16U_GOLD | D8: D1(3rdA)- | E8: E1(2ndA)- | F8: F1(1stA)-
A9: SAN FRANCISCO | B9: 16U_GOLD | D9: D2(3rdB)- | E9: E2(2ndB)- | F9: F2(1stB)-
A10: TROJAN | B10: 16U_GOLD | C10: 9 | D10: D3(3rdC)- | E10: E3(2ndC)- | F10: F3(1stC)-
A12: ATHERTON | B12: 16U_PLATINUM | D12: A | E12: B | F12: C | G12: D | H12: E | I12: F
A13: CC UNITED BLACK | B13: 16U_PLATINUM | D13: 1 | E13: 4 | F13: 5 | G13: 2 | H13: 3 | I13: 6
A14: CHANNEL ISLANDS GOLD | B14: 16U_PLATINUM | D14: 12 | E14: 9 | F14: 8 | G14: 11 | H14: 10 | I14: 7
A15: CHAWP | B15: 16U_PLATINUM | D15: 13 | E15: 16 | F15: 17 | G15: 14 | H15: 15 | I15: 18
A16: DEL MAR | B16: 16U_PLATINUM | I16: 19
A17: DIABLO RED | B17: 16U_PLATINUM | D17: A | E17: B | F17: C | G17: D | H17: E | I17: F
A18: FOOTHILL RED | B18: 16U_PLATINUM | D18: A1-DEL MAR | E18: B1-CHANNEL ISLANDS GOLD | F18: C1-STANFORD | G18: D1-CC UNITED BLACK | H18: E1-MISSION A | I18: F1-TROJAN
A19: LA JOLLA UNITED NAVY | B19: 16U_PLATINUM | D19: A2-DIABLO RED | E19: B2-ORANGE COUNTY WPC BLUE | F19: C2-LA JOLLA UNITED NAVY | G19: D2-NEWPORT | H19: E2-ATHERTON | I19: F2-SD SHORES BLACK
A20: MISSION A | B20: 16U_PLATINUM | D20: A3-NORTH IRVINE BLACK | E20: B3-ROSE BOWL RED | F20: C3-CHAWP | G20: D3-PATRIOT | H20: E3-VANGUARD BLUE | I20: F3-TEXAS THUINDER
A21: NEWPORT | B21: 16U_PLATINUM | I21: F4-FOOTHILL RED
A22: NORTH IRVINE BLACK | B22: 16U_PLATINUM
A23: OCWP BLUE | B23: 16U_PLATINUM | D23: G (1st-6th) | E23: H (1st-6th) | F23: I (7th-12th) | G23: J (7th-12th) | H23: K (13th-18th) | I23: L (13th-19th)
A24: PATRIOT | B24: 16U_PLATINUM | D24: G1(1stA)- | E24: H1(1stD)- | F24: I1(2ndA)- | G24: J1(2ndD)- | H24: K1(3rdA)- | I24: L1(3rdD)-
A25: ROSE BOWL RED | B25: 16U_PLATINUM | D25: G2(1stB)- | E25: H2(1stE)- | F25: I2(2ndB)- | G25: J2(2ndE)- | H25: K2(3rdB)- | I25: L2(3rdE)-
A26: SD SHORES BLACK | B26: 16U_PLATINUM | D26: G3(1stC)- | E26: =IF(I53="","H3(1stF)-",IF(I53>K54,_xlfn.CONCAT("H3(1stF)-",RIGHT(H53,LEN(H53) - FIND("-",H53))), _xlfn.CONCAT("H3(1stF)-",RIGHT(J54,LEN(J54) - FIND("-",J54))))) -> H3(1stF)- | F26: I3(2ndC)- | G26: =IF(I53="","J3(2ndF)-",IF(I53<K54,_xlfn.CONCAT("J3(2ndF)-",RIGHT(H53,LEN(H53) - FIND("-",H53))), _xlfn.CONCAT("J3(2ndF)-",RIGHT(J54,LEN(J54) - FIND("-",J54))))) -> #VALUE! | H26: K3(3rdC)- | I26: =IF(I54="","L3(3rdF)-",IF(I54>K55,_xlfn.CONCAT("L3(3rdF)-",RIGHT(H54,LEN(H54) - FIND("-",H54))), _xlfn.CONCAT("L3(3rdF)-",RIGHT(J55,LEN(J55) - FIND("-",J55))))) -> #VALUE!
A27: STANFORD | B27: 16U_PLATINUM | I27: =IF(I54="","L4(4thF)-",IF(I54<K55,_xlfn.CONCAT("L4(4thF)-",RIGHT(H54,LEN(H54) - FIND("-",H54))), _xlfn.CONCAT("L4(4thF)-",RIGHT(J55,LEN(J55) - FIND("-",J55))))) -> #VALUE!
A28: TEXAS THUNDER | B28: 16U_PLATINUM | D28: N Overall 3rd | E28: O Overall 1st | F28: P Overall 5th
A29: TROJAN | B29: 16U_PLATINUM | D29: N1(2ndG)- | E29: O1(1stG)- | F29: P1(3rdG)-
A30: VANGUARD BLUE | B30: 16U_PLATINUM | C30: 19 | D30: N2(2ndH)- | E30: O2(1stH)- | F30: P2(3rdH)-
A32: FOOTHILL BLACK | B32: 18U_GOLD | D32: A
A33: IMPERIAL GREEN | B33: 18U_GOLD | D33: A1-IMPERIAL GREEN
A34: NORTH IRVINE BLACK | B34: 18U_GOLD | D34: A2-NORTH IRVINE BLACK
A35: OCWP RED | B35: 18U_GOLD | D35: A3-FOOTHILL BLACK
C36: 4 | D36: A4-ORANGE COUNTY WPC RED
A38: CC UNITED | B38: 18U_PLATINUM | D38: A | E38: B | F38: C | G38: D | H38: E | I38: F
A39: CHANNEL ISLANDS GOLD | B39: 18U_PLATINUM | D39: 1 | E39: 4 | F39: 5 | G39: 2 | H39: 3 | I39: 6
A40: CHAWP | B40: 18U_PLATINUM | D40: 12 | E40: 9 | F40: 8 | G40: 11 | H40: 10 | I40: 7
A41: DEL MAR | B41: 18U_PLATINUM | D41: 13 | E41: 16 | F41: 17 | G41: 14 | H41: 15 | I41: 18
A42: DIABLO RED | B42: 18U_PLATINUM | E42: 21 | F42: 20 | G42: 23 | H42: 22 | I42: 19
A43: FOOTHILL RED | B43: 18U_PLATINUM
...

Sheet MASTER BY LOCATION
A1: ='16U BOYS GOLD-9 TEAMS'!A13 -> DATE | B1: ='16U BOYS GOLD-9 TEAMS'!B13 -> TIME | C1: ='16U BOYS GOLD-9 TEAMS'!C13&"" -> LOCATION | D1: ='16U BOYS GOLD-9 TEAMS'!D13&"" -> GAME ID | E1: ='16U BOYS GOLD-9 TEAMS'!E13&"" -> WHITE TEAM | F1: ='16U BOYS GOLD-9 TEAMS'!F13&"" -> S | G1: ='16U BOYS GOLD-9 TEAMS'!G13&"" -> DARK TEAM | H1: ='16U BOYS GOLD-9 TEAMS'!H13&"" -> S | I1: ='16U BOYS GOLD-9 TEAMS'!I13&"" -> COMMENTS | J1: ='16U BOYS GOLD-9 TEAMS'!J13&"" -> DIVISION
A2: ='16U BOYS GOLD-9 TEAMS'!A14 -> 45724 | B2: ='16U BOYS GOLD-9 TEAMS'!B14 -> 0.39583333 | C2: ='16U BOYS GOLD-9 TEAMS'!C14&"" -> COSTA MESA HS | D2: ='16U BOYS GOLD-9 TEAMS'!D14&"" -> 16Bau01 | E2: ='16U BOYS GOLD-9 TEAMS'!E14&"" -> A1-SAN FRANCISCO | F2: ='16U BOYS GOLD-9 TEAMS'!F14&"" -> 17 | G2: ='16U BOYS GOLD-9 TEAMS'!G14&"" -> A3-FOOTHILL BLACK | H2: ='16U BOYS GOLD-9 TEAMS'!H14&"" -> 1 | I2: ='16U BOYS GOLD-9 TEAMS'!I14&"" -> A bracket A1,A3 | J2: ='16U BOYS GOLD-9 TEAMS'!J14&"" -> 16U_BOYS_GOLD
A3: ='16U BOYS GOLD-9 TEAMS'!A15 -> 45724 | B3: ='16U BOYS GOLD-9 TEAMS'!B15 -> 0.4375 | C3: ='16U BOYS GOLD-9 TEAMS'!C15&"" -> COSTA MESA HS | D3: ='16U BOYS GOLD-9 TEAMS'!D15&"" -> 16Bau02 | E3: ='16U BOYS GOLD-9 TEAMS'!E15&"" -> B1-LA PREMIER | F3: ='16U BOYS GOLD-9 TEAMS'!F15&"" -> 15 | G3: ='16U BOYS GOLD-9 TEAMS'!G15&"" -> B3-OCWP RED | H3: ='16U BOYS GOLD-9 TEAMS'!H15&"" -> 9 | I3: ='16U BOYS GOLD-9 TEAMS'!I15&"" -> B bracket B1,B3 | J3: ='16U BOYS GOLD-9 TEAMS'!J15&"" -> 16U_BOYS_GOLD
A4: ='16U BOYS GOLD-9 TEAMS'!A16 -> 45724 | B4: ='16U BOYS GOLD-9 TEAMS'!B16 -> 0.47916667 | C4: ='16U BOYS GOLD-9 TEAMS'!C16&"" -> COSTA MESA HS | D4: ='16U BOYS GOLD-9 TEAMS'!D16&"" -> 16Bau03 | E4: ='16U BOYS GOLD-9 TEAMS'!E16&"" -> C1-TROJAN | F4: ='16U BOYS GOLD-9 TEAMS'!F16&"" -> 2 | G4: ='16U BOYS GOLD-9 TEAMS'!G16&"" -> C2-CC UNITED BLUE | H4: ='16U BOYS GOLD-9 TEAMS'!H16&"" -> 9 | I4: ='16U BOYS GOLD-9 TEAMS'!I16&"" -> C bracket C1,C2 | J4: ='16U BOYS GOLD-9 TEAMS'!J16&"" -> 16U_BOYS_GOLD
A5: ='16U BOYS GOLD-9 TEAMS'!A17 -> 45724 | B5: ='16U BOYS GOLD-9 TEAMS'!B17 -> 0.52083333 | C5: ='16U BOYS GOLD-9 TEAMS'!C17&"" -> COSTA MESA HS | D5: ='16U BOYS GOLD-9 TEAMS'!D17&"" -> 16Bau04 | E5: ='16U BOYS GOLD-9 TEAMS'!E17&"" -> A2-MISSION B | F5: ='16U BOYS GOLD-9 TEAMS'!F17&"" -> 14 | G5: ='16U BOYS GOLD-9 TEAMS'!G17&"" -> A3-FOOTHILL BLACK | H5: ='16U BOYS GOLD-9 TEAMS'!H17&"" -> 5 | I5: ='16U BOYS GOLD-9 TEAMS'!I17&"" -> A bracket A2,A3 | J5: ='16U BOYS GOLD-9 TEAMS'!J17&"" -> 16U_BOYS_GOLD
A6: ='16U BOYS GOLD-9 TEAMS'!A18 -> 45724 | B6: ='16U BOYS GOLD-9 TEAMS'!B18 -> 0.5625 | C6: ='16U BOYS GOLD-9 TEAMS'!C18&"" -> COSTA MESA HS | D6: ='16U BOYS GOLD-9 TEAMS'!D18&"" -> 16Bau05 | E6: ='16U BOYS GOLD-9 TEAMS'!E18&"" -> B1-LA PREMIER | F6: ='16U BOYS GOLD-9 TEAMS'!F18&"" -> 14 | G6: ='16U BOYS GOLD-9 TEAMS'!G18&"" -> B2-PEGASUS WP | H6: ='16U BOYS GOLD-9 TEAMS'!H18&"" -> 10 | I6: ='16U BOYS GOLD-9 TEAMS'!I18&"" -> B bracket B1,B2 | J6: ='16U BOYS GOLD-9 TEAMS'!J18&"" -> 16U_BOYS_GOLD
A7: ='16U BOYS GOLD-9 TEAMS'!A19 -> 45724 | B7: ='16U BOYS GOLD-9 TEAMS'!B19 -> 0.60416667 | C7: ='16U BOYS GOLD-9 TEAMS'!C19&"" -> COSTA MESA HS | D7: ='16U BOYS GOLD-9 TEAMS'!D19&"" -> 16Bau06 | E7: ='16U BOYS GOLD-9 TEAMS'!E19&"" -> C2-CC UNITED BLUE | F7: ='16U BOYS GOLD-9 TEAMS'!F19&"" -> 10 | G7: ='16U BOYS GOLD-9 TEAMS'!G19&"" -> C3-SD SHORES GOLD | H7: ='16U BOYS GOLD-9 TEAMS'!H19&"" -> 8 | I7: ='16U BOYS GOLD-9 TEAMS'!I19&"" -> C bracket C2,C3 | J7: ='16U BOYS GOLD-9 TEAMS'!J19&"" -> 16U_BOYS_GOLD
A8: ='16U BOYS GOLD-9 TEAMS'!A20 -> 45724 | B8: ='16U BOYS GOLD-9 TEAMS'!B20 -> 0.64583333 | C8: ='16U BOYS GOLD-9 TEAMS'!C20&"" -> COSTA MESA HS | D8: ='16U BOYS GOLD-9 TEAMS'!D20&"" -> 16Bau07 | E8: ='16U BOYS GOLD-9 TEAMS'!E20&"" -> A1-SAN FRANCISCO | F8: ='16U BOYS GOLD-9 TEAMS'!F20&"" -> 12 | G8: ='16U BOYS GOLD-9 TEAMS'!G20&"" -> A2-MISSION B | H8: ='16U BOYS GOLD-9 TEAMS'!H20&"" -> 6 | I8: ='16U BOYS GOLD-9 TEAMS'!I20&"" -> A bracket A1,A2 | J8: ='16U BOYS GOLD-9 TEAMS'!J20&"" -> 16U_BOYS_GOLD
A9: ='16U BOYS GOLD-9 TEAMS'!A21 -> 45724 | B9: ='16U BOYS GOLD-9 TEAMS'!B21 -> 0.6875 | C9: ='16U BOYS GOLD-9 TEAMS'!C21&"" -> COSTA MESA HS | D9: ='16U BOYS GOLD-9 TEAMS'!D21&"" -> 16Bau08 | E9: ='16U BOYS GOLD-9 TEAMS'!E21&"" -> B2-PEGASUS WP | F9: ='16U BOYS GOLD-9 TEAMS'!F21&"" -> 9 | G9: ='16U BOYS GOLD-9 TEAMS'!G21&"" -> B3-OCWP RED | H9: ='16U BOYS GOLD-9 TEAMS'!H21&"" -> 4 | I9: ='16U BOYS GOLD-9 TEAMS'!I21&"" -> B bracket B2,B3 | J9: ='16U BOYS GOLD-9 TEAMS'!J21&"" -> 16U_BOYS_GOLD
A10: ='16U BOYS GOLD-9 TEAMS'!A22 -> 45724 | B10: ='16U BOYS GOLD-9 TEAMS'!B22 -> 0.72916667 | C10: ='16U BOYS GOLD-9 TEAMS'!C22&"" -> COSTA MESA HS | D10: ='16U BOYS GOLD-9 TEAMS'!D22&"" -> 16Bau09 | E10: ='16U BOYS GOLD-9 TEAMS'!E22&"" -> C1-TROJAN | F10: ='16U BOYS GOLD-9 TEAMS'!F22&"" -> 5 | G10: ='16U BOYS GOLD-9 TEAMS'!G22&"" -> C3-SD SHORES GOLD | H10: ='16U BOYS GOLD-9 TEAMS'!H22&"" -> 10 | I10: ='16U BOYS GOLD-9 TEAMS'!I22&"" -> C bracket C1,C3 | J10: ='16U BOYS GOLD-9 TEAMS'!J22&"" -> 16U_BOYS_GOLD
A11: ='16U BOYS GOLD-9 TEAMS'!A26 -> 45725 | B11: ='16U BOYS GOLD-9 TEAMS'!B26 -> 0.33333333 | C11: ='16U BOYS GOLD-9 TEAMS'!C26&"" -> COSTA MESA HS | D11: ='16U BOYS GOLD-9 TEAMS'!D26&"" -> 16Bau10 | E11: ='16U BOYS GOLD-9 TEAMS'!E26&"" -> D1(3rdA)-FOOTHILL BLACK | F11: ='16U BOYS GOLD-9 TEAMS'!F26&"" -> 5 | G11: ='16U BOYS GOLD-9 TEAMS'!G26&"" -> D3(3rdC)-TROJAN | H11: ='16U BOYS GOLD-9 TEAMS'!H26&"" -> 12 | I11: ='16U BOYS GOLD-9 TEAMS'!I26&"" -> D bracket (7th-9th) D1,D3 | J11: ='16U BOYS GOLD-9 TEAMS'!J26&"" -> 16U_BOYS_GOLD
A12: ='16U BOYS GOLD-9 TEAMS'!A27 -> 45725 | B12: ='16U BOYS GOLD-9 TEAMS'!B27 -> 0.375 | C12: ='16U BOYS GOLD-9 TEAMS'!C27&"" -> COSTA MESA HS | D12: ='16U BOYS GOLD-9 TEAMS'!D27&"" -> 16Bau12 | E12: ='16U BOYS GOLD-9 TEAMS'!E27&"" -> E1(2ndA)-MISSION B | F12: ='16U BOYS GOLD-9 TEAMS'!F27&"" -> 10 | G12: ='16U BOYS GOLD-9 TEAMS'!G27&"" -> E3(2ndC)-SD SHORES GOLD | H12: ='16U BOYS GOLD-9 TEAMS'!H27&"" -> 11 | I12: ='16U BOYS GOLD-9 TEAMS'!I27&"" -> E bracket (4th-6th) E1,E3 | J12: ='16U BOYS GOLD-9 TEAMS'!J27&"" -> 16U_BOYS_GOLD
A13: ='16U BOYS GOLD-9 TEAMS'!A28 -> 45725 | B13: ='16U BOYS GOLD-9 TEAMS'!B28 -> 0.41666667 | C13: ='16U BOYS GOLD-9 TEAMS'!C28&"" -> COSTA MESA HS | D13: ='16U BOYS GOLD-9 TEAMS'!D28&"" -> 16Bau11 | E13: ='16U BOYS GOLD-9 TEAMS'!E28&"" -> F1(1stA)-SAN FRANCISCO | F13: ='16U BOYS GOLD-9 TEAMS'!F28&"" -> 4 | G13: ='16U BOYS GOLD-9 TEAMS'!G28&"" -> F3(1stC)-CC UNITED BLUE | H13: ='16U BOYS GOLD-9 TEAMS'!H28&"" -> 9 | I13: ='16U BOYS GOLD-9 TEAMS'!I28&"" -> F bracket (1st-3rd) F1,F3 | J13: ='16U BOYS GOLD-9 TEAMS'!J28&"" -> 16U_BOYS_GOLD
A14: ='16U BOYS GOLD-9 TEAMS'!A29 -> 45725 | B14: ='16U BOYS GOLD-9 TEAMS'!B29 -> 0.45833333 | C14: ='16U BOYS GOLD-9 TEAMS'!C29&"" -> COSTA MESA HS | D14: ='16U BOYS GOLD-9 TEAMS'!D29&"" -> 16Bau13 | E14: ='16U BOYS GOLD-9 TEAMS'!E29&"" -> D2(3rdB)-OCWP RED | F14: ='16U BOYS GOLD-9 TEAMS'!F29&"" -> 7 | G14: ='16U BOYS GOLD-9 TEAMS'!G29&"" -> D3(3rdC)-TROJAN | H14: ='16U BOYS GOLD-9 TEAMS'!H29&"" -> 2 | I14: ='16U BOYS GOLD-9 TEAMS'!I29&"" -> D bracket (7th-9th) D2,D3 | J14: ='16U BOYS GOLD-9 TEAMS'!J29&"" -> 16U_BOYS_GOLD
A15: ='16U BOYS GOLD-9 TEAMS'!A30 -> 45725 | B15: ='16U BOYS GOLD-9 TEAMS'!B30 -> 0.5 | C15: ='16U BOYS GOLD-9 TEAMS'!C30&"" -> COSTA MESA HS | D15: ='16U BOYS GOLD-9 TEAMS'!D30&"" -> 16Bau14 | E15: ='16U BOYS GOLD-9 TEAMS'!E30&"" -> E2(2ndB)-PEGASUS | F15: ='16U BOYS GOLD-9 TEAMS'!F30&"" -> 7 | G15: ='16U BOYS GOLD-9 TEAMS'!G30&"" -> E3(2ndC)-SD SHORES GOLD | H15: ='16U BOYS GOLD-9 TEAMS'!H30&"" -> 17 | I15: ='16U BOYS GOLD-9 TEAMS'!I30&"" -> E bracket (4th-6th) E2,E3 | J15: ='16U BOYS GOLD-9 TEAMS'!J30&"" -> 16U_BOYS_GOLD
A16: ='16U BOYS GOLD-9 TEAMS'!A31 -> 45725 | B16: ='16U BOYS GOLD-9 TEAMS'!B31 -> 0.54166667 | C16: ='16U BOYS GOLD-9 TEAMS'!C31&"" -> COSTA MESA HS | D16: ='16U BOYS GOLD-9 TEAMS'!D31&"" -> 16Bau15 | E16: ='16U BOYS GOLD-9 TEAMS'!E31&"" -> F2(1stB)-LA PREMIER | F16: ='16U BOYS GOLD-9 TEAMS'!F31&"" -> 11 | G16: ='16U BOYS GOLD-9 TEAMS'!G31&"" -> F3(1stC)-CC UNITED BLUE | H16: ='16U BOYS GOLD-9 TEAMS'!H31&"" -> 6 | I16: ='16U BOYS GOLD-9 TEAMS'!I31&"" -> F bracket (1st-3rd) F2,F3 | J16: ='16U BOYS GOLD-9 TEAMS'!J31&"" -> 16U_BOYS_GOLD
A17: ='16U BOYS GOLD-9 TEAMS'!A32 -> 45725 | B17: ='16U BOYS GOLD-9 TEAMS'!B32 -> 0.58333333 | C17: ='16U BOYS GOLD-9 TEAMS'!C32&"" -> COSTA MESA HS | D17: ='16U BOYS GOLD-9 TEAMS'!D32&"" -> 16Bau16 | E17: ='16U BOYS GOLD-9 TEAMS'!E32&"" -> D1(3rdA)-FOOTHILL BLACK | F17: ='16U BOYS GOLD-9 TEAMS'!F32&"" -> 6 | G17: ='16U BOYS GOLD-9 TEAMS'!G32&"" -> D2(3rdB)-OCWP RED | H17: ='16U BOYS GOLD-9 TEAMS'!H32&"" -> 16 | I17: ='16U BOYS GOLD-9 TEAMS'!I32&"" -> D bracket (7th-9th) D1,D2 | J17: ='16U BOYS GOLD-9 TEAMS'!J32&"" -> 16U_BOYS_GOLD
A18: ='16U BOYS GOLD-9 TEAMS'!A33 -> 45725 | B18: ='16U BOYS GOLD-9 TEAMS'!B33 -> 0.625 | C18: ='16U BOYS GOLD-9 TEAMS'!C33&"" -> COSTA MESA HS | D18: ='16U BOYS GOLD-9 TEAMS'!D33&"" -> 16Bau17 | E18: ='16U BOYS GOLD-9 TEAMS'!E33&"" -> E1(2ndA)-MISSION B | F18: ='16U BOYS GOLD-9 TEAMS'!F33&"" -> 12 | G18: ='16U BOYS GOLD-9 TEAMS'!G33&"" -> E2(2ndB)-PEGASUS | H18: ='16U BOYS GOLD-9 TEAMS'!H33&"" -> 10 | I18: ='16U BOYS GOLD-9 TEAMS'!I33&"" -> E bracket (4th-6th) E1,E2 | J18: ='16U BOYS GOLD-9 TEAMS'!J33&"" -> 16U_BOYS_GOLD
A19: ='16U BOYS GOLD-9 TEAMS'!A34 -> 45725 | B19: ='16U BOYS GOLD-9 TEAMS'!B34 -> 0.66666667 | C19: ='16U BOYS GOLD-9 TEAMS'!C34&"" -> COSTA MESA HS | D19: ='16U BOYS GOLD-9 TEAMS'!D34&"" -> 16Bau18 | E19: ='16U BOYS GOLD-9 TEAMS'!E34&"" -> F1(1stA)-SAN FRANCISCO | F19: ='16U BOYS GOLD-9 TEAMS'!F34&"" -> 9 | G19: ='16U BOYS GOLD-9 TEAMS'!G34&"" -> F2(1stB)-LA PREMIER | H19: ='16U BOYS GOLD-9 TEAMS'!H34&"" -> 15 | I19: ='16U BOYS GOLD-9 TEAMS'!I34&"" -> F bracket (1st-3rd) F1,F2 | J19: ='16U BOYS GOLD-9 TEAMS'!J34&"" -> 16U_BOYS_GOLD
A20: ='18U BOYS-24 TEAMS'!A27 -> 45724 | B20: ='18U BOYS-24 TEAMS'!B27 -> 0.33333333 | C20: ='18U BOYS-24 TEAMS'!C27&"" -> EL TORO HS | D20: ='18U BOYS-24 TEAMS'!D27&"" -> 18B01 | E20: ='18U BOYS-24 TEAMS'!E27&"" -> 5-CC UNITED | F20: ='18U BOYS-24 TEAMS'!F27&"" -> 12 | G20: ='18U BOYS-24 TEAMS'!G27&"" -> 20-FOOTHILL RED | H20: ='18U BOYS-24 TEAMS'!H27&"" -> 7 | I20: ='18U BOYS-24 TEAMS'!I27&"" -> W/L C1/C4 | J20: ='18U BOYS-24 TEAMS'!J27&"" -> 18U_BOYS
A21: ='18U BOYS-24 TEAMS'!A28 -> 45724 | B21: ='18U BOYS-24 TEAMS'!B28 -> 0.375 | C21: ='18U BOYS-24 TEAMS'!C28&"" -> EL TORO HS | D21: ='18U BOYS-24 TEAMS'!D28&"" -> 18B03 | E21: ='18U BOYS-24 TEAMS'!E28&"" -> 8-SD SHORES BLACK | F21: ='18U BOYS-24 TEAMS'!F28&"" -> 12 | G21: ='18U BOYS-24 TEAMS'!G28&"" -> 17-CHAWP | H21: ='18U BOYS-24 TEAMS'!H28&"" -> 11 | I21: ='18U BOYS-24 TEAMS'!I28&"" -> W/L C2/C3 | J21: ='18U BOYS-24 TEAMS'!J28&"" -> 18U_BOYS
A22: ='18U BOYS-24 TEAMS'!A29 -> 45724 | B22: ='18U BOYS-24 TEAMS'!B29 -> 0.41666667 | C22: ='18U BOYS-24 TEAMS'!C29&"" -> EL TORO HS | D22: ='18U BOYS-24 TEAMS'!D29&"" -> 18B05 | E22: ='18U BOYS-24 TEAMS'!E29&"" -> 1-LAMORINDA | F22: ='18U BOYS-24 TEAMS'!F29&"" -> 19 | G22: ='18U BOYS-24 TEAMS'!G29&"" -> 24-NORTH IRVINE VEGAS | H22: ='18U BOYS-24 TEAMS'!H29&"" -> 8 | I22: ='18U BOYS-24 TEAMS'!I29&"" -> W/L A1/A4 | J22: ='18U BOYS-24 TEAMS'!J29&"" -> 18U_BOYS
A23: ='18U BOYS-24 TEAMS'!A31 -> 45724 | B23: ='18U BOYS-24 TEAMS'!B31 -> 0.45833333 | C23: ='18U BOYS-24 TEAMS'!C31&"" -> EL TORO HS | D23: ='18U BOYS-24 TEAMS'!D31&"" -> 18B07 | E23: ='18U BOYS-24 TEAMS'!E31&"" -> 12-LA PREMIER | F23: ='18U BOYS-24 TEAMS'!F31&"" -> 8 | G23: ='18U BOYS-24 TEAMS'!G31&"" -> 13-VANGUARD BLUE | H23: ='18U BOYS-24 TEAMS'!H31&"" -> 13 | I23: ='18U BOYS-24 TEAMS'!I31&"" -> W/L A2/A3 | J23: ='18U BOYS-24 TEAMS'!J31&"" -> 18U_BOYS
A24: ='18U BOYS-24 TEAMS'!A33 -> 45724 | B24: ='18U BOYS-24 TEAMS'!B33 -> 0.5 | C24: ='18U BOYS-24 TEAMS'!C33&"" -> EL TORO HS | D24: ='18U BOYS-24 TEAMS'!D33&"" -> 18B13 | E24: ='18U BOYS-24 TEAMS'!E33&"" -> L#1-FOOTHILL RED | F24: ='18U BOYS-24 TEAMS'!F33&"" -> 6 | G24: ='18U BOYS-24 TEAMS'!G33&"" -> L#3-CHAWP | H24: ='18U BOYS-24 TEAMS'!H33&"" -> 11 | I24: ='18U BOYS-24 TEAMS'!I33&"" -> 3rd/4thC | J24: ='18U BOYS-24 TEAMS'!J33&"" -> 18U_BOYS
A25: ='18U BOYS-24 TEAMS'!A34 -> 45724 | B25: ='18U BOYS-24 TEAMS'!B34 -> 0.54166667 | C25: ='18U BOYS-24 TEAMS'!C34&"" -> EL TORO HS | D25: ='18U BOYS-24 TEAMS'!D34&"" -> 18B15 | E25: ='18U BOYS-24 TEAMS'!E34&"" -> W#1-CC UNITED | F25: ='18U BOYS-24 TEAMS'!F34&"" -> 14 | G25: ='18U BOYS-24 TEAMS'!G34&"" -> W#3-SD SHORES BLACK | H25: ='18U BOYS-24 TEAMS'!H34&"" -> 12 | I25: ='18U BOYS-24 TEAMS'!I34&"" -> 1st/2ndC | J25: ='18U BOYS-24 TEAMS'!J34&"" -> 18U_BOYS
A26: ='18U BOYS-24 TEAMS'!A35 -> 45724 | B26: ='18U BOYS-24 TEAMS'!B35 -> 0.58333333 | C26: ='18U BOYS-24 TEAMS'!C35&"" -> EL TORO HS | D26: ='18U BOYS-24 TEAMS'!D35&"" -> 18B17 | E26: ='18U BOYS-24 TEAMS'!E35&"" -> L#5-NORTH IRVINE VEGAS | F26: ='18U BOYS-24 TEAMS'!F35&"" -> 8 | G26: ='18U BOYS-24 TEAMS'!G35&"" -> L#7-LA PREMIER | H26: ='18U BOYS-24 TEAMS'!H35&"" -> 9 | I26: ='18U BOYS-24 TEAMS'!I35&"" -> 3rd/4thA | J26: ='18U BOYS-24 TEAMS'!J35&"" -> 18U_BOYS
A27: ='18U BOYS-24 TEAMS'!A36 -> 45724 | B27: ='18U BOYS-24 TEAMS'!B36 -> 0.625 | C27: ='18U BOYS-24 TEAMS'!C36&"" -> EL TORO HS | D27: ='18U BOYS-24 TEAMS'!D36&"" -> 18B19 | E27: ='18U BOYS-24 TEAMS'!E36&"" -> W#5-LAMORINDA | F27: ='18U BOYS-24 TEAMS'!F36&"" -> 12 | G27: ='18U BOYS-24 TEAMS'!G36&"" -> W#7-VANGUARD BLUE | H27: ='18U BOYS-24 TEAMS'!H36&"" -> 5 | I27: ='18U BOYS-24 TEAMS'!I36&"" -> 1st/2ndA | J27: ='18U BOYS-24 TEAMS'!J36&"" -> 18U_BOYS
