Workbook

Sheet RAW ENTRIES
A1: RECORD | B1: CLUB | C1: CLUB# | D1: CONTACT | E1: CONTACT USWP# | F1: CELL | G1: EMAIL | H1: TEAM | I1: TEAM CONTACT | J1: DIV | K1: DUE | L1: COMMENTS
A2: 13 | B2: Capital | C2: 30226 | D2: miras jelic | E2: 575862 | F2: 8042181512 | G2: mirkesu@yahoo.com | H2: Capital | I2: miras jelic 804 2181512 | J2: 16U BOYS PLATINUM | K2: 1295
A3: 14 | B3: Capital | C3: 30226 | D3: miras jelic | E3: 575862 | F3: 8042181512 | G3: mirkesu@yahoo.com | H3: Capital | I3: miras jelic 804 2181512 | J3: 14U BOYS SILVER | K3: 1295
A4: 15 | B4: Capital | C4: 30226 | D4: miras jelic | E4: 575862 | F4: 8042181512 | G4: mirkesu@yahoo.com | H4: Capital | I4: miras jelic 804 2181512 | J4: 16U BOYS PLATINUM | K4: 1295
A5: 16 | B5: Shadow Water Polo Club | C5: Canadian | D5: Moataz Salem | E5: Canadian | F5: 4169909913 | G5: shadowboyswp@gmail.com | H5: Shadow Men | I5: Moataz Salem 416-990-9913 | J5: 19U BOYS PLATINUM | K5: 1295 | L5: Shadow water Polo 19U Men Team is a Canadian Team,
A6: 17 | B6: St. Louis Area Polo (SLAP) | C6: 12 | D6: Miguel Figueras | E6: 12585 | F6: 5153713146 | G6: eiznof@gmail.com | H6: St. Louis Area Polo (SLAP) | I6: Miguel Figueras 515-371-3146 | J6: 16U BOYS GOLD | K6: 1295 | L6: Per Brad's ok, we will have 4 players on the roster who will still be 16 at the time of the tournament but will turn 17 prior to August 1st, 2026
A7: 18 | B7: Davis Water Polo Club | C7: 79 | D7: Carolyn Walker | E7: 706176 | F7: 9257083783 | G7: Carolynkwalker@gmail.com | H7: Davis 10U Mix | I7: Ashley Macedo - 805-618-6788 | J7: 10U COED GOLD | K7: 1095
A8: 19 | B8: Davis Water Polo Club | C8: 79 | D8: Carolyn Walker | E8: 706176 | F8: 9257083783 | G8: Carolynkwalker@gmail.com | H8: Davis 12U Girls | I8: Carolyn Walker 925-708-3783 | J8: 12U GIRLS PLATINUM | K8: 1295
A9: 20 | B9: Davis Water Polo Club | C9: 79 | D9: Carolyn Walker | E9: 706176 | F9: 9257083783 | G9: Carolynkwalker@gmail.com | H9: Davis 12U Boys | I9: Scott Strong 916 -765-1792 | J9: 12U BOYS PLATINUM | K9: 1295
A10: 21 | B10: Davis Water Polo Club | C10: 79 | D10: Carolyn Walker | E10: 706176 | F10: 9257083783 | G10: Carolynkwalker@gmail.com | H10: 14U Girls | I10: Mary Rhodes 805-588-5002 | J10: 14U GIRLS PLATINUM | K10: 1295
A11: 22 | B11: Davis Water Polo Club | C11: 79 | D11: Carolyn Walker | E11: 706176 | F11: 9257083783 | G11: Carolynkwalker@gmail.com | H11: 14U Boys | I11: Nick Alden 408-821-9539 | J11: 14U BOYS GOLD | K11: 1295
A12: 23 | B12: Davis Water Polo Club | C12: 79 | D12: Carolyn Walker | E12: 706176 | F12: 9257083783 | G12: Carolynkwalker@gmail.com | H12: Davis 16U Blue | I12: Tracy Stapleton - 530-400-2167 | J12: 16U BOYS GOLD | K12: 1295
A13: 24 | B13: Davis Water Polo Club | C13: 79 | D13: Carolyn Walker | E13: 706176 | F13: 9257083783 | G13: Carolynkwalker@gmail.com | H13: Davis 16U White | I13: Tracy Stapleton - 530-400-2167 | J13: 16U BOYS SILVER | K13: 1295
A14: 25 | B14: Triton Aquatics | C14: 34352 | D14: Alex Lazzereschi | E14: 523427 | F14: 925.596.4746 | G14: alex@tritonaquatics.org | H14: Gold | I14: Alex Lazzereschi - 925.596.4746 | J14: 14U BOYS SILVER | K14: 1295
A15: 26 | B15: Triton Aquatics | C15: 34352 | D15: Alex Lazzereschi | E15: 523427 | F15: 925.596.4746 | G15: alex@tritonaquatics.org | H15: Gold | I15: Alex Lazzereschi - 925.596.4746 | J15: 16U BOYS SILVER | K15: 1295
A16: 27 | B16: Stanford | C16: 570 | D16: Emily Stiling | E16: 716532 | F16: 5593468971 | G16: estiling@stanfordwpc.com | H16: 10u Stanford Red | I16: Emily Stiling (559-346-8971) | J16: 10U BOYS | K16: 1095 | L16: 10u - 1 team 12u - 3 teams 14u - 2 teams We will be submitting 1x more 14u team + 2x 16u teams
A17: 28 | B17: Stanford | C17: 570 | D17: Emily Stiling | E17: 716532 | F17: 5593468971 | G17: estiling@stanfordwpc.com | H17: 12u Stanford Red | I17: Emily Stiling (559-346-8971) | J17: 12U BOYS PLATINUM | K17: 1295 | L17: 10u - 1 team 12u - 3 teams 14u - 2 teams We will be submitting 1x more 14u team + 2x 16u teams
A18: 29 | B18: Stanford | C18: 570 | D18: Emily Stiling | E18: 716532 | F18: 5593468971 | G18: estiling@stanfordwpc.com | H18: 12u Stanford Black | I18: Emily Stiling (559-346-8971) | J18: 12U BOYS GOLD | K18: 1295 | L18: 10u - 1 team 12u - 3 teams 14u - 2 teams We will be submitting 1x more 14u team + 2x 16u teams
A19: 30 | B19: Stanford | C19: 570 | D19: Emily Stiling | E19: 716532 | F19: 5593468971 | G19: estiling@stanfordwpc.com | H19: 12u Stanford White | I19: Emily Stiling (559-346-8971) | J19: 12U BOYS GOLD | K19: 1295 | L19: 10u - 1 team 12u - 3 teams 14u - 2 teams We will be submitting 1x more 14u team + 2x 16u teams
A20: 31 | B20: Stanford | C20: 570 | D20: Emily Stiling | E20: 716532 | F20: 5593468971 | G20: estiling@stanfordwpc.com | H20: 14u Stanford Red | I20: Emily Stiling (559-346-8971) | J20: 14U BOYS PLATINUM | K20: 1295 | L20: 10u - 1 team 12u - 3 teams 14u - 2 teams We will be submitting 1x more 14u team + 2x 16u teams
A21: 32 | B21: Stanford | C21: 570 | D21: Emily Stiling | E21: 716532 | F21: 5593468971 | G21: estiling@stanfordwpc.com | H21: 14u Stanford Black | I21: Emily Stiling (559-346-8971) | J21: 14U BOYS GOLD | K21: 1295 | L21: 10u - 1 team 12u - 3 teams 14u - 2 teams We will be submitting 1x more 14u team + 2x 16u teams
A22: 33 | B22: Stanford | C22: 570 | D22: Emily Stiling | E22: 716532 | F22: 5593468971 | G22: estiling@stanfordwpc.com | H22: 13's Stanford | I22: Emily Stiling (55)3468971 | J22: 14U BOYS GOLD | K22: 1295
A23: 34 | B23: Stanford | C23: 570 | D23: Emily Stiling | E23: 716532 | F23: 5593468971 | G23: estiling@stanfordwpc.com | H23: 16u Black Stanford | I23: Emily Stiling (55)3468971 | J23: 16U BOYS GOLD | K23: 1295
A24: 35 | B24: Stanford | C24: 570 | D24: Emily Stiling | E24: 716532 | F24: 5593468971 | G24: estiling@stanfordwpc.com | H24: 16u White Stanford | I24: Emily Stiling (55)3468971 | J24: 16U BOYS SILVER | K24: 1295
A25: 36 | B25: Stanford | C25: 570 | D25: Emily Stiling | E25: 716532 | F25: 5593468971 | G25: estiling@stanfordwpc.com | H25: 13's Stanford | I25: Emily Stiling (55)3468971 | J25: 14U BOYS GOLD | K25: 1295
A26: 37 | B26: Stanford | C26: 570 | D26: Emily Stiling | E26: 716532 | F26: 5593468971 | G26: estiling@stanfordwpc.com | H26: 16u Black Stanford | I26: Emily Stiling (55)3468971 | J26: 16U BOYS GOLD | K26: 1295
A27: 38 | B27: Stanford | C27: 570 | D27: Emily Stiling | E27: 716532 | F27: 5593468971 | G27: estiling@stanfordwpc.com | H27: 16u White Stanford | I27: Emily Stiling (55)3468971 | J27: 16U BOYS SILVER | K27: 1295
A28: 39 | B28: Mid-Pen WPC | C28: 24253 | D28: Steven Canalez | E28: 461255 | F28: (408) 616-9628 | G28: steven.canalez@gmail.com | H28: Mid-Pen 18U | I28: Bruno Antonino [Cell: (650) 713-1670] | J28: 19U BOYS GOLD | K28: 1295
A29: 40 | B29: Mid-Pen WPC | C29: 24253 | D29: Steven Canalez | E29: 461255 | F29: (408) 616-9628 | G29: steven.canalez@gmail.com | H29: Mid-Pen 16U | I29: Steven Canalez [Cell: (408) 616-9628] | J29: 16U BOYS SILVER | K29: 1295
A30: 41 | B30: Honolulu Water Polo | C30: 17214 | D30: Kale Ai | E30: 412736 | F30: 8082306053 | G30: kaleai@hnlwaterpolo.org | H30: HNLWP Blue | I30: Kale Ai 8082306053 | J30: 14U BOYS GOLD | K30: 1295 | L30: We are flying back to honolulu on Sunday 02/01/26 at 4:30pm from LAX. Kindly requesting our games finish by 1:00pm so we can safely make it to the airport on time.
A31: 42 | B31: Honolulu Water Polo | C31: 17214 | D31: Kale Ai | E31: 412736 | F31: 8082306053 | G31: kaleai@hnlwaterpolo.org | H31: HNLWP Green | I31: Kale Ai 8082306053 | J31: 14U BOYS SILVER | K31: 1295 | L31: We are flying back to honolulu on Sunday 02/01/26 at 4:30pm from LAX. Kindly requesting our games finish by 1:00pm so we can safely make it to the airport on time.
A32: 43 | B32: Honolulu Water Polo | C32: 17214 | D32: Kale Ai | E32: 412736 | F32: 8082306053 | G32: kaleai@hnlwaterpolo.org | H32: HNLWP | I32: Kale Ai 8082306053 | J32: 14U GIRLS GOLD | K32: 1295 | L32: We are flying back to honolulu on Sunday 02/01/26 at 4:30pm from LAX. Kindly requesting our games finish by 1:00pm so we can safely make it to the airport on time.
A33: 46 | B33: Pacific Valley Premier | C33: 34095 | D33: Eve Okamura | E33: 480121 | F33: 4085503356 | G33: eveeokamura@gmail.com | H33: Pacific Valley Premier | I33: 4085503356 | J33: HIGH SCHOOL GIRLS | K33: 1295
A34: 47 | B34: California Republic | C34: 26152 | D34: Tyson Frenn | E34: 396489 | F34: 7073197139 | G34: calrepublicwpc@gmail.com | H34: Cal Republic | I34: Damien Lawrence 209-406-6854 | J34: 16U BOYS GOLD | K34: 1295
A35: 48 | B35: CT Premier WPC | C35: 34969 | D35: Scott Schulte | E35: 15630 | F35: 917-562-9610 | G35: admin@ctpremierwpc.com | H35: CT Premier WPC 16U | I35: Gabriel Maldonado 203-543-8925 | J35: 16U BOYS GOLD | K35: 1295 | L35: We are not sure if we want to enter our 18U team in the Platinum or Gold division, we are still deciding.
A36: 49 | B36: CT Premier WPC | C36: 34969 | D36: Scott Schulte | E36: 15630 | F36: 917-562-9610 | G36: admin@ctpremierwpc.com | H36: CT Premier WPC 14U | I36: Valentin Horvath 929-610-3725 | J36: 14U BOYS GOLD | K36: 1295 | L36: We are not sure if we want to enter our 18U team in the Platinum or Gold division, we are still deciding.
A37: 50 | B37: CT Premier WPC | C37: 34969 | D37: Scott Schulte | E37: 15630 | F37: 917-562-9610 | G37: admin@ctpremierwpc.com | H37: CT Premier WPC 18U | I37: Scott Schulte 917-562-9610 | J37: 19U BOYS PLATINUM | K37: 1295 | L37: We are not sure if we want to enter our 18U team in the Platinum or Gold division, we are still deciding.
A38: 51 | B38: Yolo Polo | C38: 35474 | D38: Kevin Friedman | E38: 635 | F38: 415.871.6328 | G38: Kevin@YoloPolo.org | H38: Yolo 10u Mixed Black | I38: Kevin Friedman 415.871.6328 | J38: 10U COED PLATINUM | K38: 1095 | L38: Please share the DRAFT schedule / matchups. This will be the first travel tournament for a number of our families and we hope to have reasonable matchups in the appropriate flights. Last year, we did not receive a notification that there was a new
A39: 52 | B39: Yolo Polo | C39: 35474 | D39: Kevin Friedman | E39: 635 | F39: 415.871.6328 | G39: Kevin@YoloPolo.org | H39: Yolo 10u Mixed Yellow | I39: Trevor Rose 530.400.3128 | J39: 10U COED GOLD | K39: 1095 | L39: Please share the DRAFT schedule / matchups. This will be the first travel tournament for a number of our families and we hope to have reasonable matchups in the appropriate flights. Last year, we did not receive a notification that there was a new
A40: 53 | B40: Yolo Polo | C40: 35474 | D40: Kevin Friedman | E40: 635 | F40: 415.871.6328 | G40: Kevin@YoloPolo.org | H40: Yolo 12u Mixed Black | I40: Katie Walsh 510.406.1970 | J40: 12U COED | K40: 1295 | L40: Please share the DRAFT schedule / matchups. This will be the first travel tournament for a number of our families and we hope to have reasonable matchups in the appropriate flights. Last year, we did not receive a notification that there was a new
...

Sheet MEDALS
A1: ='10U COED GOLD-16 TEAMS CUSTOM'!A9 -> DATE | B1: ='10U COED GOLD-16 TEAMS CUSTOM'!B9 -> TIME | C1: ='10U COED GOLD-16 TEAMS CUSTOM'!C9&"" -> LOCATION | D1: ='10U COED GOLD-16 TEAMS CUSTOM'!D9&"" -> GAME ID | E1: ='10U COED GOLD-16 TEAMS CUSTOM'!E9&"" -> WHITE TEAM | F1: ='10U COED GOLD-16 TEAMS CUSTOM'!F9&"" -> S | G1: ='10U COED GOLD-16 TEAMS CUSTOM'!G9&"" -> DARK TEAM | H1: ='10U COED GOLD-16 TEAMS CUSTOM'!H9&"" -> S | I1: ='10U COED GOLD-16 TEAMS CUSTOM'!I9&"" -> COMMENTS | J1: ='10U COED GOLD-16 TEAMS CUSTOM'!J9&"" -> DIVISION
L2: ='10U COED GOLD-16 TEAMS CUSTOM'!I46&"" -> 1st | M2: ='10U COED GOLD-16 TEAMS CUSTOM'!J46&"" -> DAVIS
A3: ='10U COED GOLD-16 TEAMS CUSTOM'!A40 -> 46054 | B3: ='10U COED GOLD-16 TEAMS CUSTOM'!B40 -> 0.52083333 | C3: ='10U COED GOLD-16 TEAMS CUSTOM'!C40&"" -> WOOLLETT FAR LEFT | D3: ='10U COED GOLD-16 TEAMS CUSTOM'!D40&"" -> 10Cau29 | E3: ='10U COED GOLD-16 TEAMS CUSTOM'!E40&"" -> L#21-YOLO YELLOW | F3: ='10U COED GOLD-16 TEAMS CUSTOM'!F40&"" -> 11.2 | G3: ='10U COED GOLD-16 TEAMS CUSTOM'!G40&"" -> L#22-SOUTH BAY UNITED | H3: ='10U COED GOLD-16 TEAMS CUSTOM'!H40&"" -> 11.1 | I3: ='10U COED GOLD-16 TEAMS CUSTOM'!I40&"" -> 3rd Coed | J3: ='10U COED GOLD-16 TEAMS CUSTOM'!J40&"" -> 10U_COED_GOLD | L3: ='10U COED GOLD-16 TEAMS CUSTOM'!I47&"" -> 2nd | M3: ='10U COED GOLD-16 TEAMS CUSTOM'!J47&"" -> LA JOLLA UNITED
A4: ='10U COED GOLD-16 TEAMS CUSTOM'!A42 -> 46054 | B4: ='10U COED GOLD-16 TEAMS CUSTOM'!B42 -> 0.55208333 | C4: ='10U COED GOLD-16 TEAMS CUSTOM'!C42&"" -> WOOLLETT FAR LEFT | D4: ='10U COED GOLD-16 TEAMS CUSTOM'!D42&"" -> 10Cau30 | E4: ='10U COED GOLD-16 TEAMS CUSTOM'!E42&"" -> W#21-LA JOLLA UNITED | F4: ='10U COED GOLD-16 TEAMS CUSTOM'!F42&"" -> 7 | G4: ='10U COED GOLD-16 TEAMS CUSTOM'!G42&"" -> W#22-DAVIS | H4: ='10U COED GOLD-16 TEAMS CUSTOM'!H42&"" -> 13 | I4: ='10U COED GOLD-16 TEAMS CUSTOM'!I42&"" -> 1st Coed | J4: ='10U COED GOLD-16 TEAMS CUSTOM'!J42&"" -> 10U_COED_GOLD | L4: ='10U COED GOLD-16 TEAMS CUSTOM'!I48&"" -> 3rd | M4: ='10U COED GOLD-16 TEAMS CUSTOM'!J48&"" -> YOLO YELLOW
M5: ='10U COED GOLD-16 TEAMS CUSTOM'!J50&""
A6: ='10U COED GOLD-16 TEAMS CUSTOM'!A14 -> 46053 | B6: ='10U COED GOLD-16 TEAMS CUSTOM'!B14 -> 0.45833333 | C6: ='10U COED GOLD-16 TEAMS CUSTOM'!C14&"" -> WOOLLETT FAR LEFT | D6: ='10U COED GOLD-16 TEAMS CUSTOM'!D14&"" -> 10Cau05 | E6: ='10U COED GOLD-16 TEAMS CUSTOM'!E14&"" -> G1-LAMORINDA BLUE (A) (girls) | F6: ='10U COED GOLD-16 TEAMS CUSTOM'!F14&"" -> 19 | G6: ='10U COED GOLD-16 TEAMS CUSTOM'!G14&"" -> G4-SAN CLEMENTE RED (girls) | H6: ='10U COED GOLD-16 TEAMS CUSTOM'!H14&"" -> 1 | I6: ='10U COED GOLD-16 TEAMS CUSTOM'!I14&"" -> girls 1st-4th | J6: 10U GIRLS | L6: ='10U COED GOLD-16 TEAMS CUSTOM'!I51&"" -> 1st | M6: ='10U COED GOLD-16 TEAMS CUSTOM'!J51&"" -> LAMORINDA BLUE (A) (girls)
A7: ='10U COED GOLD-16 TEAMS CUSTOM'!A16 -> 46053 | B7: ='10U COED GOLD-16 TEAMS CUSTOM'!B16 -> 0.48958333 | C7: ='10U COED GOLD-16 TEAMS CUSTOM'!C16&"" -> WOOLLETT FAR LEFT | D7: ='10U COED GOLD-16 TEAMS CUSTOM'!D16&"" -> 10Cau06 | E7: ='10U COED GOLD-16 TEAMS CUSTOM'!E16&"" -> G2-DEL MAR BLUE (girls) | F7: ='10U COED GOLD-16 TEAMS CUSTOM'!F16&"" -> 12 | G7: ='10U COED GOLD-16 TEAMS CUSTOM'!G16&"" -> G3-680 RED (girls) | H7: ='10U COED GOLD-16 TEAMS CUSTOM'!H16&"" -> 5 | I7: ='10U COED GOLD-16 TEAMS CUSTOM'!I16&"" -> girls 1st-4th | J7: 10U GIRLS | L7: ='10U COED GOLD-16 TEAMS CUSTOM'!I52&"" -> 2nd | M7: ='10U COED GOLD-16 TEAMS CUSTOM'!J52&"" -> DEL MAR BLUE (girls)
A8: ='10U COED GOLD-16 TEAMS CUSTOM'!A22 -> 46053 | B8: ='10U COED GOLD-16 TEAMS CUSTOM'!B22 -> 0.64583333 | C8: ='10U COED GOLD-16 TEAMS CUSTOM'!C22&"" -> WOOLLETT FAR LEFT | D8: ='10U COED GOLD-16 TEAMS CUSTOM'!D22&"" -> 10Cau11 | E8: ='10U COED GOLD-16 TEAMS CUSTOM'!E22&"" -> G1-LAMORINDA BLUE (A) (girls) | F8: ='10U COED GOLD-16 TEAMS CUSTOM'!F22&"" -> 17 | G8: ='10U COED GOLD-16 TEAMS CUSTOM'!G22&"" -> G3-680 RED (girls) | H8: ='10U COED GOLD-16 TEAMS CUSTOM'!H22&"" -> 3 | I8: ='10U COED GOLD-16 TEAMS CUSTOM'!I22&"" -> girls 1st-4th | J8: 10U GIRLS | L8: ='10U COED GOLD-16 TEAMS CUSTOM'!I53&"" -> 3rd | M8: ='10U COED GOLD-16 TEAMS CUSTOM'!J53&"" -> 680 RED (girls)
A9: ='10U COED GOLD-16 TEAMS CUSTOM'!A24 -> 46053 | B9: ='10U COED GOLD-16 TEAMS CUSTOM'!B24 -> 0.67708333 | C9: ='10U COED GOLD-16 TEAMS CUSTOM'!C24&"" -> WOOLLETT FAR LEFT | D9: ='10U COED GOLD-16 TEAMS CUSTOM'!D24&"" -> 10Cau12 | E9: ='10U COED GOLD-16 TEAMS CUSTOM'!E24&"" -> G2-DEL MAR BLUE (girls) | F9: ='10U COED GOLD-16 TEAMS CUSTOM'!F24&"" -> 17 | G9: ='10U COED GOLD-16 TEAMS CUSTOM'!G24&"" -> G4-SAN CLEMENTE RED (girls) | H9: ='10U COED GOLD-16 TEAMS CUSTOM'!H24&"" -> 4 | I9: ='10U COED GOLD-16 TEAMS CUSTOM'!I24&"" -> girls 1st-4th | J9: 10U GIRLS
A10: ='10U COED GOLD-16 TEAMS CUSTOM'!A29 -> 46054 | B10: ='10U COED GOLD-16 TEAMS CUSTOM'!B29 -> 0.33333333 | C10: ='10U COED GOLD-16 TEAMS CUSTOM'!C29&"" -> WOOLLETT FAR LEFT | D10: ='10U COED GOLD-16 TEAMS CUSTOM'!D29&"" -> 10Cau17 | E10: ='10U COED GOLD-16 TEAMS CUSTOM'!E29&"" -> G1-LAMORINDA BLUE (A) (girls) | F10: ='10U COED GOLD-16 TEAMS CUSTOM'!F29&"" -> 8 | G10: ='10U COED GOLD-16 TEAMS CUSTOM'!G29&"" -> G2-DEL MAR BLUE (girls) | H10: ='10U COED GOLD-16 TEAMS CUSTOM'!H29&"" -> 2 | I10: ='10U COED GOLD-16 TEAMS CUSTOM'!I29&"" -> girls 1st-4th | J10: 10U GIRLS
A11: ='10U COED GOLD-16 TEAMS CUSTOM'!A31 -> 46054 | B11: ='10U COED GOLD-16 TEAMS CUSTOM'!B31 -> 0.36458333 | C11: ='10U COED GOLD-16 TEAMS CUSTOM'!C31&"" -> WOOLLETT FAR LEFT | D11: ='10U COED GOLD-16 TEAMS CUSTOM'!D31&"" -> 10Cau18 | E11: ='10U COED GOLD-16 TEAMS CUSTOM'!E31&"" -> G3-680 RED (girls) | F11: ='10U COED GOLD-16 TEAMS CUSTOM'!F31&"" -> 11 | G11: ='10U COED GOLD-16 TEAMS CUSTOM'!G31&"" -> G4-SAN CLEMENTE RED (girls) | H11: ='10U COED GOLD-16 TEAMS CUSTOM'!H31&"" -> 8 | I11: ='10U COED GOLD-16 TEAMS CUSTOM'!I31&"" -> girls 1st-4th | J11: 10U GIRLS
J14: 2 sets medals here | L14: ='10U COED PLATINUM-8 TEAMS'!I32&"" -> 1st | M14: ='10U COED PLATINUM-8 TEAMS'!J32&"" -> NORTH IRVINE BLACK
A15: ='10U COED PLATINUM-8 TEAMS'!A29 -> 46054 | B15: ='10U COED PLATINUM-8 TEAMS'!B29 -> 0.64583333 | C15: ='10U COED PLATINUM-8 TEAMS'!C29&"" -> WOOLLETT FAR LEFT | D15: ='10U COED PLATINUM-8 TEAMS'!D29&"" -> 10Cpt15 | E15: ='10U COED PLATINUM-8 TEAMS'!E29&"" -> 2ndA-CHANNEL ISLANDS UNITED | F15: ='10U COED PLATINUM-8 TEAMS'!F29&"" -> 9 | G15: ='10U COED PLATINUM-8 TEAMS'!G29&"" -> 2ndB-CHULA VISTA PREMIER | H15: ='10U COED PLATINUM-8 TEAMS'!H29&"" -> 8 | I15: ='10U COED PLATINUM-8 TEAMS'!I29&"" -> 3rd | J15: ='10U COED PLATINUM-8 TEAMS'!J29&"" -> 10U_COED_PLATINUM | L15: ='10U COED PLATINUM-8 TEAMS'!I33&"" -> 2nd | M15: ='10U COED PLATINUM-8 TEAMS'!J33&"" -> ORANGE COUNTY WPC BLUE
A16: ='10U COED PLATINUM-8 TEAMS'!A30 -> 46054 | B16: ='10U COED PLATINUM-8 TEAMS'!B30 -> 0.67708333 | C16: ='10U COED PLATINUM-8 TEAMS'!C30&"" -> WOOLLETT FAR LEFT | D16: ='10U COED PLATINUM-8 TEAMS'!D30&"" -> 10Cpt16 | E16: ='10U COED PLATINUM-8 TEAMS'!E30&"" -> 1stA-NORTH IRVINE BLACK | F16: ='10U COED PLATINUM-8 TEAMS'!F30&"" -> 8 | G16: ='10U COED PLATINUM-8 TEAMS'!G30&"" -> 1stB-ORANGE COUNTY WPC BLUE | H16: ='10U COED PLATINUM-8 TEAMS'!H30&"" -> 4 | I16: ='10U COED PLATINUM-8 TEAMS'!I30&"" -> 1st | J16: ='10U COED PLATINUM-8 TEAMS'!J30&"" -> 10U_COED_PLATINUM | L16: ='10U COED PLATINUM-8 TEAMS'!I34&"" -> 3rd | M16: ='10U COED PLATINUM-8 TEAMS'!J34&"" -> CHANNEL ISLANDS UNITED
L19: ='10U BOYS-8 TEAMS'!I31&"" -> 1st | M19: ='10U BOYS-8 TEAMS'!J31&"" -> 680 RED
A20: ='10U BOYS-8 TEAMS'!A28 -> 46054 | B20: ='10U BOYS-8 TEAMS'!B28 -> 0.58333333 | C20: ='10U BOYS-8 TEAMS'!C28&"" -> WOOLLETT FAR LEFT | D20: ='10U BOYS-8 TEAMS'!D28&"" -> 10B15 | E20: ='10U BOYS-8 TEAMS'!E28&"" -> 2ndA-LAMORINDA BLUE (A) | F20: ='10U BOYS-8 TEAMS'!F28&"" -> 6 | G20: ='10U BOYS-8 TEAMS'!G28&"" -> 2ndB-SAN CLEMENTE RED | H20: ='10U BOYS-8 TEAMS'!H28&"" -> 14 | I20: ='10U BOYS-8 TEAMS'!I28&"" -> 3rd | J20: ='10U BOYS-8 TEAMS'!J28&"" -> 10U_BOYS | L20: ='10U BOYS-8 TEAMS'!I32&"" -> 2nd | M20: ='10U BOYS-8 TEAMS'!J32&"" -> CC UNITED BLACK
A21: ='10U BOYS-8 TEAMS'!A29 -> 46054 | B21: ='10U BOYS-8 TEAMS'!B29 -> 0.61458333 | C21: ='10U BOYS-8 TEAMS'!C29&"" -> WOOLLETT FAR LEFT | D21: ='10U BOYS-8 TEAMS'!D29&"" -> 10B16 | E21: ='10U BOYS-8 TEAMS'!E29&"" -> 1stA-680 RED | F21: ='10U BOYS-8 TEAMS'!F29&"" -> 6 | G21: ='10U BOYS-8 TEAMS'!G29&"" -> 1stB-CC UNITED BLACK | H21: ='10U BOYS-8 TEAMS'!H29&"" -> 3 | I21: ='10U BOYS-8 TEAMS'!I29&"" -> 1st | J21: ='10U BOYS-8 TEAMS'!J29&"" -> 10U_BOYS | L21: ='10U BOYS-8 TEAMS'!I33&"" -> 3rd | M21: ='10U BOYS-8 TEAMS'!J33&"" -> SAN CLEMENTE RED
L24: ='12U GIRLS PLATINUM-12 TEAMS'!I40&"" -> 1st | M24: ='12U GIRLS PLATINUM-12 TEAMS'!J40&"" -> 680 RED
A25: ='12U GIRLS PLATINUM-12 TEAMS'!A37 -> 46054 | B25: ='12U GIRLS PLATINUM-12 TEAMS'!B37 -> 0.63888889 | C25: ='12U GIRLS PLATINUM-12 TEAMS'!C37&"" -> WOOLLETT FAR RIGHT | D25: ='12U GIRLS PLATINUM-12 TEAMS'!D37&"" -> 12Gpt17 | E25: ='12U GIRLS PLATINUM-12 TEAMS'!E37&"" -> L#13-SHAQ | F25: ='12U GIRLS PLATINUM-12 TEAMS'!F37&"" -> 3 | G25: ='12U GIRLS PLATINUM-12 TEAMS'!G37&"" -> L#14-NEWPORT BEACH | H25: ='12U GIRLS PLATINUM-12 TEAMS'!H37&"" -> 2 | I25: ='12U GIRLS PLATINUM-12 TEAMS'!I37&"" -> 3rd | J25: ='12U GIRLS PLATINUM-12 TEAMS'!J37&"" -> 12U_GIRLS_PLATINUM | L25: ='12U GIRLS PLATINUM-12 TEAMS'!I41&"" -> 2nd | M25: ='12U GIRLS PLATINUM-12 TEAMS'!J41&"" -> BACK BAY NAVY
A26: ='12U GIRLS PLATINUM-12 TEAMS'!A38 -> 46054 | B26: ='12U GIRLS PLATINUM-12 TEAMS'!B38 -> 0.67361111 | C26: ='12U GIRLS PLATINUM-12 TEAMS'!C38&"" -> WOOLLETT FAR RIGHT | D26: ='12U GIRLS PLATINUM-12 TEAMS'!D38&"" -> 12Gpt18 | E26: ='12U GIRLS PLATINUM-12 TEAMS'!E38&"" -> W#13-BACK BAY NAVY | F26: ='12U GIRLS PLATINUM-12 TEAMS'!F38&"" -> 4 | G26: ='12U GIRLS PLATINUM-12 TEAMS'!G38&"" -> W#14-680 RED | H26: ='12U GIRLS PLATINUM-12 TEAMS'!H38&"" -> 13 | I26: ='12U GIRLS PLATINUM-12 TEAMS'!I38&"" -> 1st | J26: ='12U GIRLS PLATINUM-12 TEAMS'!J38&"" -> 12U_GIRLS_PLATINUM | L26: ='12U GIRLS PLATINUM-12 TEAMS'!I42&"" -> 3rd | M26: ='12U GIRLS PLATINUM-12 TEAMS'!J42&"" -> SHAQ
L29: ='12U BOYS GOLD-24 TEAMS'!I73&"" -> 1st | M29: ='12U BOYS GOLD-24 TEAMS'!J73&"" -> ORANGE COUNTY WPC BLUE
A30: ='12U BOYS GOLD-24 TEAMS'!A67 -> 46054 | B30: ='12U BOYS GOLD-24 TEAMS'!B67 -> 0.67361111 | C30: ='12U BOYS GOLD-24 TEAMS'!C67&"" -> BECKMAN HS 1 | D30: ='12U BOYS GOLD-24 TEAMS'!D67&"" -> 12Bau25 | E30: ='12U BOYS GOLD-24 TEAMS'!E67&"" -> L#24-SAN CLEMENTE BLACK | F30: ='12U BOYS GOLD-24 TEAMS'!F67&"" -> 8 | G30: ='12U BOYS GOLD-24 TEAMS'!G67&"" -> L#24A-680 BLUE | H30: ='12U BOYS GOLD-24 TEAMS'!H67&"" -> 6 | I30: ='12U BOYS GOLD-24 TEAMS'!I67&"" -> 3rd | J30: ='12U BOYS GOLD-24 TEAMS'!J67&"" -> 12U_BOYS_GOLD | L30: ='12U BOYS GOLD-24 TEAMS'!I74&"" -> 2nd | M30: ='12U BOYS GOLD-24 TEAMS'!J74&"" -> FOOTHILL RED
A31: ='12U BOYS GOLD-24 TEAMS'!A68 -> 46054 | B31: ='12U BOYS GOLD-24 TEAMS'!B68 -> 0.70833333 | C31: ='12U BOYS GOLD-24 TEAMS'!C68&"" -> BECKMAN HS 1 | D31: ='12U BOYS GOLD-24 TEAMS'!D68&"" -> 12Bau26 | E31: ='12U BOYS GOLD-24 TEAMS'!E68&"" -> W#24-ORANGE COUNTY WPC BLUE | F31: ='12U BOYS GOLD-24 TEAMS'!F68&"" -> 19 | G31: ='12U BOYS GOLD-24 TEAMS'!G68&"" -> W#24A-FOOTHILL RED | H31: ='12U BOYS GOLD-24 TEAMS'!H68&"" -> 5 | I31: ='12U BOYS GOLD-24 TEAMS'!I68&"" -> 1st | J31: ='12U BOYS GOLD-24 TEAMS'!J68&"" -> 12U_BOYS_GOLD | L31: ='12U BOYS GOLD-24 TEAMS'!I75&"" -> 3rd | M31: ='12U BOYS GOLD-24 TEAMS'!J75&"" -> SAN CLEMENTE BLACK
L34: ='12U BOYS PLATINUM-10 TEAMS'!I37&"" -> 1st | M34: ='12U BOYS PLATINUM-10 TEAMS'!J37&"" -> MISSION WPC A
A35: ='12U BOYS PLATINUM-10 TEAMS'!A32 -> 46054 | B35: ='12U BOYS PLATINUM-10 TEAMS'!B32 -> 0.53472222 | C35: ='12U BOYS PLATINUM-10 TEAMS'!C32&"" -> BECKMAN HS 1 | D35: ='12U BOYS PLATINUM-10 TEAMS'!D32&"" -> 12Bpt20 | E35: ='12U BOYS PLATINUM-10 TEAMS'!E32&"" -> L#15-ORWP A | F35: ='12U BOYS PLATINUM-10 TEAMS'!F32&"" -> 4 | G35: ='12U BOYS PLATINUM-10 TEAMS'!G32&"" -> L#16-CC UNITED BLACK | H35: ='12U BOYS PLATINUM-10 TEAMS'!H32&"" -> 16 | I35: ='12U BOYS PLATINUM-10 TEAMS'!I32&"" -> 3rd | J35: ='12U BOYS PLATINUM-10 TEAMS'!J32&"" -> 12U_BOYS_PLATINUM | L35: ='12U BOYS PLATINUM-10 TEAMS'!I38&"" -> 2nd | M35: ='12U BOYS PLATINUM-10 TEAMS'!J38&"" -> STANFORD RED
A36: ='12U BOYS PLATINUM-10 TEAMS'!A33 -> 46054 | B36: ='12U BOYS PLATINUM-10 TEAMS'!B33 -> 0.56944444 | C36: ='12U BOYS PLATINUM-10 TEAMS'!C33&"" -> BECKMAN HS 1 | D36: ='12U BOYS PLATINUM-10 TEAMS'!D33&"" -> 12Bpt21 | E36: ='12U BOYS PLATINUM-10 TEAMS'!E33&"" -> W#15-MISSION WPC A | F36: ='12U BOYS PLATINUM-10 TEAMS'!F33&"" -> 18 | G36: ='12U BOYS PLATINUM-10 TEAMS'!G33&"" -> W#16-STANFORD RED | H36: ='12U BOYS PLATINUM-10 TEAMS'!H33&"" -> 4 | I36: ='12U BOYS PLATINUM-10 TEAMS'!I33&"" -> 1st | J36: ='12U BOYS PLATINUM-10 TEAMS'!J33&"" -> 12U_BOYS_PLATINUM | L36: ='12U BOYS PLATINUM-10 TEAMS'!I39&"" -> 3rd | M36: ='12U BOYS PLATINUM-10 TEAMS'!J39&"" -> CC UNITED BLACK
L39: ='12U COED-7 TEAMS'!I33&"" -> 1st | M39: ='12U COED-7 TEAMS'!J33&"" -> YOLO BLACK
A40: ='12U COED-7 TEAMS'!A31 -> 46054 | B40: ='12U COED-7 TEAMS'!B31 -> 0.74305556 | C40: ='12U COED-7 TEAMS'!C31&"" -> WOOLLETT FAR RIGHT | D40: ='12U COED-7 TEAMS'!D31&"" -> 12C14 | E40: ='12U COED-7 TEAMS'!E31&"" -> L#11-LA CITY UNITED | F40: ='12U COED-7 TEAMS'!F31&"" -> 15 | G40: ='12U COED-7 TEAMS'!G31&"" -> L#12-PALOS VERDES | H40: ='12U COED-7 TEAMS'!H31&"" -> 8 | I40: ='12U COED-7 TEAMS'!I31&"" -> 3rd | J40: ='12U COED-7 TEAMS'!J31&"" -> 12U_COED | L40: ='12U COED-7 TEAMS'!I34&"" -> 2nd | M40: ='12U COED-7 TEAMS'!J34&"" -> SET
A41: ='12U COED-7 TEAMS'!A30 -> 46054 | B41: ='12U COED-7 TEAMS'!B30 -> 0.70833333 | C41: ='12U COED-7 TEAMS'!C30&"" -> WOOLLETT FAR RIGHT | D41: ='12U COED-7 TEAMS'!D30&"" -> 12C15 | E41: ='12U COED-7 TEAMS'!E30&"" -> W#11-SET | F41: ='12U COED-7 TEAMS'!F30&"" -> 7 | G41: ='12U COED-7 TEAMS'!G30&"" -> W#12-YOLO BLACK | H41: ='12U COED-7 TEAMS'!H30&"" -> 21 | I41: ='12U COED-7 TEAMS'!I30&"" -> 1st | J41: ='12U COED-7 TEAMS'!J30&"" -> 12U_COED | L41: ='12U COED-7 TEAMS'!I35&"" -> 3rd | M41: ='12U COED-7 TEAMS'!J35&"" -> LA CITY UNITED
L44: ='14U GIRLS GOLD-14 TEAMS'!I43&"" -> 1st | M44: ='14U GIRLS GOLD-14 TEAMS'!J43&"" -> GOLD COAST
A45: ='14U GIRLS GOLD-14 TEAMS'!A39 -> 46054 | B45: ='14U GIRLS GOLD-14 TEAMS'!B39 -> 0.63888889 | C45: ='14U GIRLS GOLD-14 TEAMS'!C39&"" -> SAN CLEMENTE HS | D45: ='14U GIRLS GOLD-14 TEAMS'!D39&"" -> 14Gau21 | E45: ='14U GIRLS GOLD-14 TEAMS'!E39&"" -> L#15-NORTH IRVINE | F45: ='14U GIRLS GOLD-14 TEAMS'!F39&"" -> 9 | G45: ='14U GIRLS GOLD-14 TEAMS'!G39&"" -> L#17-ROGUE 619 | H45: ='14U GIRLS GOLD-14 TEAMS'!H39&"" -> 18 | I45: ='14U GIRLS GOLD-14 TEAMS'!I39&"" -> 3rd | J45: ='14U GIRLS GOLD-14 TEAMS'!J39&"" -> 14U_GIRLS_GOLD | L45: ='14U GIRLS GOLD-14 TEAMS'!I44&"" -> 2nd | M45: ='14U GIRLS GOLD-14 TEAMS'!J44&"" -> PASADENA AC
A46: ='14U GIRLS GOLD-14 TEAMS'!A40 -> 46054 | B46: ='14U GIRLS GOLD-14 TEAMS'!B40 -> 0.67361111 | C46: ='14U GIRLS GOLD-14 TEAMS'!C40&"" -> SAN CLEMENTE HS | D46: ='14U GIRLS GOLD-14 TEAMS'!D40&"" -> 14Gau22 | E46: ='14U GIRLS GOLD-14 TEAMS'!E40&"" -> W#15-PASADENA AC | F46: ='14U GIRLS GOLD-14 TEAMS'!F40&"" -> 9 | G46: ='14U GIRLS GOLD-14 TEAMS'!G40&"" -> W#17-GOLD COAST | H46: ='14U GIRLS GOLD-14 TEAMS'!H40&"" -> 16 | I46: ='14U GIRLS GOLD-14 TEAMS'!I40&"" -> 1st | J46: ='14U GIRLS GOLD-14 TEAMS'!J40&"" -> 14U_GIRLS_GOLD | L46: ='14U GIRLS GOLD-14 TEAMS'!I45&"" -> 3rd | M46: ='14U GIRLS GOLD-14 TEAMS'!J45&"" -> ROGUE 619
L49: ='14U GIRLS PLATINUM-10 TEAMS'!I36&"" -> 1st | M49: ='14U GIRLS PLATINUM-10 TEAMS'!J36&"" -> SANTA CRUZ BLACK
A50: ='14U GIRLS PLATINUM-10 TEAMS'!A31 -> 46054 | B50: ='14U GIRLS PLATINUM-10 TEAMS'!B31 -> 0.56944444 | C50: ='14U GIRLS PLATINUM-10 TEAMS'!C31&"" -> ALISO NIGUEL HS | D50: ='14U GIRLS PLATINUM-10 TEAMS'!D31&"" -> 14Gpt20 | E50: ='14U GIRLS PLATINUM-10 TEAMS'!E31&"" -> L#15-SOUTH COAST RED (A) | F50: ='14U GIRLS PLATINUM-10 TEAMS'!F31&"" -> 6.2 | G50: ='14U GIRLS PLATINUM-10 TEAMS'!G31&"" -> L#16-PATRIOT RED | H50: ='14U GIRLS PLATINUM-10 TEAMS'!H31&"" -> 6.1 | I50: ='14U GIRLS PLATINUM-10 TEAMS'!I31&"" -> 3rd | J50: ='14U GIRLS PLATINUM-10 TEAMS'!J31&"" -> 14U_GIRLS_PLATINUM | L50: ='14U GIRLS PLATINUM-10 TEAMS'!I37&"" -> 2nd | M50: ='14U GIRLS PLATINUM-10 TEAMS'!J37&"" -> CDM PINK
A51: ='14U GIRLS PLATINUM-10 TEAMS'!A32 -> 46054 | B51: ='14U GIRLS PLATINUM-10 TEAMS'!B32 -> 0.60416667 | C51: ='14U GIRLS PLATINUM-10 TEAMS'!C32&"" -> ALISO NIGUEL HS | D51: ='14U GIRLS PLATINUM-10 TEAMS'!D32&"" -> 14Gpt21 | E51: ='14U GIRLS PLATINUM-10 TEAMS'!E32&"" -> W#15-CDM PINK | F51: ='14U GIRLS PLATINUM-10 TEAMS'!F32&"" -> 5 | G51: ='14U GIRLS PLATINUM-10 TEAMS'!G32&"" -> W#16-SANTA CRUZ BLACK | H51: ='14U GIRLS PLATINUM-10 TEAMS'!H32&"" -> 6 | I51: ='14U GIRLS PLATINUM-10 TEAMS'!I32&"" -> 1st | J51: ='14U GIRLS PLATINUM-10 TEAMS'!J32&"" -> 14U_GIRLS_PLATINUM | L51: ='14U GIRLS PLATINUM-10 TEAMS'!I38&"" -> 3rd | M51: ='14U GIRLS PLATINUM-10 TEAMS'!J38&"" -> SOUTH COAST RED (A)
L54: ='14U BOYS SILVER-18 TEAMS'!I68&"" -> 1st | M54: ='14U BOYS SILVER-18 TEAMS'!J68&"" -> POWAY VALLEY BLACK
A55: ='14U BOYS SILVER-18 TEAMS'!A53 -> 46054 | B55: ='14U BOYS SILVER-18 TEAMS'!B53 -> 0.63888889 | C55: ='14U BOYS SILVER-18 TEAMS'!C53&"" -> COSTA MESA HS 1 | D55: ='14U BOYS SILVER-18 TEAMS'!D53&"" -> 14Bag37 | E55: ='14U BOYS SILVER-18 TEAMS'!E53&"" -> 2ndG-PASADENA AC | F55: ='14U BOYS SILVER-18 TEAMS'!F53&"" -> 15 | G55: ='14U BOYS SILVER-18 TEAMS'!G53&"" -> 2ndH-SAND CANYON | H55: ='14U BOYS SILVER-18 TEAMS'!H53&"" -> 14 | I55: ='14U BOYS SILVER-18 TEAMS'!I53&"" -> overall 3rd | J55: ='14U BOYS SILVER-18 TEAMS'!J53&"" -> 14U_BOYS_SILVER | L55: ='14U BOYS SILVER-18 TEAMS'!I69&"" -> 2nd | M55: ='14U BOYS SILVER-18 TEAMS'!J69&"" -> GOLD COAST
A56: ='14U BOYS SILVER-18 TEAMS'!A54 -> 46054 | B56: ='14U BOYS SILVER-18 TEAMS'!B54 -> 0.67361111 | C56: ='14U BOYS SILVER-18 TEAMS'!C54&"" -> COSTA MESA HS 1 | D56: ='14U BOYS SILVER-18 TEAMS'!D54&"" -> 14Bag38 | E56: ='14U BOYS SILVER-18 TEAMS'!E54&"" -> 1stG-POWAY VALLEY BLACK | F56: ='14U BOYS SILVER-18 TEAMS'!F54&"" -> 11 | G56: ='14U BOYS SILVER-18 TEAMS'!G54&"" -> 1stH-GOLD COAST | H56: ='14U BOYS SILVER-18 TEAMS'!H54&"" -> 6 | I56: ='14U BOYS SILVER-18 TEAMS'!I54&"" -> overall 1st | J56: ='14U BOYS SILVER-18 TEAMS'!J54&"" -> 14U_BOYS_SILVER | L56: ='14U BOYS SILVER-18 TEAMS'!I70&"" -> 3rd | M56: ='14U BOYS SILVER-18 TEAMS'!J70&"" -> PASADENA AC
L59: ='14U BOYS GOLD-26 TEAMS'!I89&"" -> 1st | M59: ='14U BOYS GOLD-26 TEAMS'!J89&"" -> MISSION WPC B
A60: ='14U BOYS GOLD-26 TEAMS'!A64 -> 46054 | B60: ='14U BOYS GOLD-26 TEAMS'!B64 -> 0.60416667 | C60: ='14U BOYS GOLD-26 TEAMS'!C64&"" -> ESTANCIA HS 2 | D60: ='14U BOYS GOLD-26 TEAMS'!D64&"" -> 14Bau35 | E60: ='14U BOYS GOLD-26 TEAMS'!E64&"" -> Q1(2ndJ)-NORTHWEST | F60: ='14U BOYS GOLD-26 TEAMS'!F64&"" -> 13 | G60: ='14U BOYS GOLD-26 TEAMS'!G64&"" -> Q2(2ndK)-VANGUARD SILVER | H60: ='14U BOYS GOLD-26 TEAMS'!H64&"" -> 14 | I60: ='14U BOYS GOLD-26 TEAMS'!I64&"" -> overall 3rd | J60: ='14U BOYS GOLD-26 TEAMS'!J64&"" -> 14U_BOYS_GOLD | L60: ='14U BOYS GOLD-26 TEAMS'!I90&"" -> 2nd | M60: ='14U BOYS GOLD-26 TEAMS'!J90&"" -> SHORE AQUATICS
...

Sheet TEAM LISTING AND BRACKETS
A1: TEAM | B1: DIV | G1: 3rdA | H1: 3rdD
A2: See Below and ADVISE BY WED Jan 20 5pm! | D2: G (girls) | E2: GIRLS, RR THEN FOR MEDALS | G2: 3rdB | H2: 3rdC
A3: 680 RED (girls) | B3: 10U_COED_GOLD | D3: G1-LAMORINDA BLUE (A) (girls) | E3: THEN INTERACT WITH COED GOLD
A4: DEL MAR BLUE (girls) | B4: 10U_COED_GOLD | D4: G2-DEL MAR BLUE (girls) | G4: G1 | H4: 3rdD
A5: LAMORINDA BLUE (A) (girls) | B5: 10U_COED_GOLD | D5: G3-680 RED (girls) | G5: G2 | H5: 3rdC
A6: SAN CLEMENTE RED (girls) | B6: 10U_COED_GOLD | C6: 4 | D6: G4-SAN CLEMENTE RED (girls) | G6: G3 | H6: 3rdB
D7: CUSTOM COMBO | G7: G4 | H7: 3rdA
A8: DAVIS | B8: 10U_COED_GOLD | D8: A | E8: B | F8: C | G8: D
A9: DEL MAR WHITE | B9: 10U_COED_GOLD | D9: A1-LA JOLLA UNITED | E9: B1-DAVIS | F9: C1-SOUTH COAST RED | G9: D1-TROJAN
A10: LA JOLLA UNITED | B10: 10U_COED_GOLD | D10: A2-LOYOLA WPC | E10: B2-ORANGE COUNTY WPC RED | F10: C2-SOUTH BAY UNITED | G10: D2-PATRIOT WHITE
A11: LAMORINDA C | B11: 10U_COED_GOLD | D11: A3-LAMORINDA C | E11: B3-DEL MAR WHITE | F11: C3-SAN CLEMENTE BLACK | G11: D3-YOLO YELLOW
A12: LOYOLA WPC | B12: 10U_COED_GOLD
A13: ORANGE COUNTY WPC RED | B13: 10U_COED_GOLD
A14: PATRIOT WHITE | B14: 10U_COED_GOLD
A15: SAN CLEMENTE BLACK | B15: 10U_COED_GOLD
A16: SOUTH BAY UNITED | B16: 10U_COED_GOLD
A17: SOUTH COAST RED | B17: 10U_COED_GOLD
A18: TROJAN | B18: 10U_COED_GOLD
A19: YOLO YELLOW | B19: 10U_COED_GOLD | C19: 12
A21: CHANNEL ISLANDS UNITED | B21: 10U_COED_PLATINUM | D21: A | E21: B
A22: CHULA VISTA PREMIER | B22: 10U_COED_PLATINUM | D22: A1-CHANNEL ISLANDS UNITED | E22: B1-ORANGE COUNTY WPC BLUE
A23: FOOTHILL RED | B23: 10U_COED_PLATINUM | D23: A2-FOOTHILL RED | E23: B2-CHULA VISTA PREMIER
A24: LAMORINDA GOLD (B) | B24: 10U_COED_PLATINUM | D24: A3-YOLO BLACK | E24: B3-PATRIOT RED
A25: NORTH IRVINE BLACK | B25: 10U_COED_PLATINUM | D25: A4-NORTH IRVINE BLACK | E25: B4-LAMORINDA GOLD (B)
A26: ORANGE COUNTY WPC BLUE | B26: 10U_COED_PLATINUM
A27: PATRIOT RED | B27: 10U_COED_PLATINUM
A28: YOLO BLACK | B28: 10U_COED_PLATINUM | C28: 8
A30: 680 BLUE | B30: 10U_BOYS | D30: avoid intra-club play on day 1, and 5-8
A31: 680 RED | B31: 10U_BOYS | D31: A | E31: B
A32: CC UNITED BLACK | B32: 10U_BOYS | D32: A1-LAMORINDA BLUE (A) | E32: B1-CC UNITED BLACK
A33: CC UNITED BLUE | B33: 10U_BOYS | D33: A2-680 RED | E33: B2-SAN CLEMENTE RED
A34: LA PREMIER | B34: 10U_BOYS | D34: A3-LA PREMIER | E34: B3-STANFORD RED
A35: LAMORINDA BLUE (A) | B35: 10U_BOYS | D35: A4-CC UNITED BLUE | E35: B4-680 BLUE
A36: SAN CLEMENTE RED | B36: 10U_BOYS
A37: STANFORD RED | B37: 10U_BOYS | C37: 8
A39: 680 RED | B39: 12U_GIRLS_PLATINUM | D39: A | E39: B | F39: C | G39: D
A40: BACK BAY NAVY | B40: 12U_GIRLS_PLATINUM | D40: A1-BACK BAY NAVY | E40: B1-680 RED | F40: C1-NEWPORT BEACH | G40: D1-SHAQ
A41: DAVIS | B41: 12U_GIRLS_PLATINUM | D41: A2-GOLD COAST | E41: B2-SOUTH COAST RED | F41: C2-DAVIS | G41: D2-LA JOLLA UNITED
A42: GOLD COAST | B42: 12U_GIRLS_PLATINUM | D42: A3-LAMORINDA C | E42: B3-ORANGE COUNTY WPC BLUE | F42: C3-LAMORINDA B | G42: D3-NORTH IRVINE
A43: LA JOLLA UNITED | B43: 12U_GIRLS_PLATINUM
...

Sheet MASTER BY DIVISION
A1: ='10U COED GOLD-16 TEAMS CUSTOM'!A9 -> DATE | B1: ='10U COED GOLD-16 TEAMS CUSTOM'!B9 -> TIME | C1: ='10U COED GOLD-16 TEAMS CUSTOM'!C9&"" -> LOCATION | D1: ='10U COED GOLD-16 TEAMS CUSTOM'!D9&"" -> GAME ID | E1: ='10U COED GOLD-16 TEAMS CUSTOM'!E9&"" -> WHITE TEAM | F1: ='10U COED GOLD-16 TEAMS CUSTOM'!F9&"" -> S | G1: ='10U COED GOLD-16 TEAMS CUSTOM'!G9&"" -> DARK TEAM | H1: ='10U COED GOLD-16 TEAMS CUSTOM'!H9&"" -> S | I1: ='10U COED GOLD-16 TEAMS CUSTOM'!I9&"" -> COMMENTS | J1: ='10U COED GOLD-16 TEAMS CUSTOM'!J9&"" -> DIVISION | K1: SORTKEY
A2: ='10U COED GOLD-16 TEAMS CUSTOM'!A10 -> 46053 | B2: ='10U COED GOLD-16 TEAMS CUSTOM'!B10 -> 0.33333333 | C2: ='10U COED GOLD-16 TEAMS CUSTOM'!C10&"" -> EL TORO HS 2 | D2: ='10U COED GOLD-16 TEAMS CUSTOM'!D10&"" -> 10Cau01 | E2: ='10U COED GOLD-16 TEAMS CUSTOM'!E10&"" -> D1-TROJAN | F2: ='10U COED GOLD-16 TEAMS CUSTOM'!F10&"" -> 13 | G2: ='10U COED GOLD-16 TEAMS CUSTOM'!G10&"" -> D3-YOLO YELLOW | H2: ='10U COED GOLD-16 TEAMS CUSTOM'!H10&"" -> 15 | I2: ='10U COED GOLD-16 TEAMS CUSTOM'!I10&"" -> D bracket D1,D3 | J2: ='10U COED GOLD-16 TEAMS CUSTOM'!J10&"" -> 10U_COED_GOLD | K2: =TEXT(DATE(2025, MONTH(A2), DAY(A2)) + TIME(HOUR(B2), MINUTE(B2), 0), "yyyymmddhhmm") -> 202501310800
A3: ='10U COED GOLD-16 TEAMS CUSTOM'!A11 -> 46053 | B3: ='10U COED GOLD-16 TEAMS CUSTOM'!B11 -> 0.36458333 | C3: ='10U COED GOLD-16 TEAMS CUSTOM'!C11&"" -> EL TORO HS 2 | D3: ='10U COED GOLD-16 TEAMS CUSTOM'!D11&"" -> 10Cau02 | E3: ='10U COED GOLD-16 TEAMS CUSTOM'!E11&"" -> A1-LA JOLLA UNITED | F3: ='10U COED GOLD-16 TEAMS CUSTOM'!F11&"" -> 18 | G3: ='10U COED GOLD-16 TEAMS CUSTOM'!G11&"" -> A3-LAMORINDA C | H3: ='10U COED GOLD-16 TEAMS CUSTOM'!H11&"" -> 8 | I3: ='10U COED GOLD-16 TEAMS CUSTOM'!I11&"" -> A bracket A1,A3 | J3: ='10U COED GOLD-16 TEAMS CUSTOM'!J11&"" -> 10U_COED_GOLD | K3: =TEXT(DATE(2025, MONTH(A3), DAY(A3)) + TIME(HOUR(B3), MINUTE(B3), 0), "yyyymmddhhmm") -> 202501310845
A4: ='10U COED GOLD-16 TEAMS CUSTOM'!A12 -> 46053 | B4: ='10U COED GOLD-16 TEAMS CUSTOM'!B12 -> 0.39583333 | C4: ='10U COED GOLD-16 TEAMS CUSTOM'!C12&"" -> EL TORO HS 2 | D4: ='10U COED GOLD-16 TEAMS CUSTOM'!D12&"" -> 10Cau03 | E4: ='10U COED GOLD-16 TEAMS CUSTOM'!E12&"" -> B1-DAVIS | F4: ='10U COED GOLD-16 TEAMS CUSTOM'!F12&"" -> 16 | G4: ='10U COED GOLD-16 TEAMS CUSTOM'!G12&"" -> B3-DEL MAR WHITE | H4: ='10U COED GOLD-16 TEAMS CUSTOM'!H12&"" -> 5 | I4: ='10U COED GOLD-16 TEAMS CUSTOM'!I12&"" -> B bracket B1,B3 | J4: ='10U COED GOLD-16 TEAMS CUSTOM'!J12&"" -> 10U_COED_GOLD | K4: =TEXT(DATE(2026, MONTH(A4), DAY(A4)) + TIME(HOUR(B4), MINUTE(B4), 0), "yyyymmddhhmm") -> 202601310930
A5: ='10U COED GOLD-16 TEAMS CUSTOM'!A13 -> 46053 | B5: ='10U COED GOLD-16 TEAMS CUSTOM'!B13 -> 0.42708333 | C5: ='10U COED GOLD-16 TEAMS CUSTOM'!C13&"" -> EL TORO HS 2 | D5: ='10U COED GOLD-16 TEAMS CUSTOM'!D13&"" -> 10Cau04 | E5: ='10U COED GOLD-16 TEAMS CUSTOM'!E13&"" -> C1-SOUTH COAST RED | F5: ='10U COED GOLD-16 TEAMS CUSTOM'!F13&"" -> 6 | G5: ='10U COED GOLD-16 TEAMS CUSTOM'!G13&"" -> C3-SAN CLEMENTE BLACK | H5: ='10U COED GOLD-16 TEAMS CUSTOM'!H13&"" -> 18 | I5: ='10U COED GOLD-16 TEAMS CUSTOM'!I13&"" -> C bracket C1,C3 | J5: ='10U COED GOLD-16 TEAMS CUSTOM'!J13&"" -> 10U_COED_GOLD | K5: =TEXT(DATE(2026, MONTH(A5), DAY(A5)) + TIME(HOUR(B5), MINUTE(B5), 0), "yyyymmddhhmm") -> 202601311015
A6: ='10U COED GOLD-16 TEAMS CUSTOM'!A14 -> 46053 | B6: ='10U COED GOLD-16 TEAMS CUSTOM'!B14 -> 0.45833333 | C6: ='10U COED GOLD-16 TEAMS CUSTOM'!C14&"" -> WOOLLETT FAR LEFT | D6: ='10U COED GOLD-16 TEAMS CUSTOM'!D14&"" -> 10Cau05 | E6: ='10U COED GOLD-16 TEAMS CUSTOM'!E14&"" -> G1-LAMORINDA BLUE (A) (girls) | F6: ='10U COED GOLD-16 TEAMS CUSTOM'!F14&"" -> 19 | G6: ='10U COED GOLD-16 TEAMS CUSTOM'!G14&"" -> G4-SAN CLEMENTE RED (girls) | H6: ='10U COED GOLD-16 TEAMS CUSTOM'!H14&"" -> 1 | I6: ='10U COED GOLD-16 TEAMS CUSTOM'!I14&"" -> girls 1st-4th | J6: ='10U COED GOLD-16 TEAMS CUSTOM'!J14&"" -> 10U_COED_GOLD | K6: =TEXT(DATE(2026, MONTH(A6), DAY(A6)) + TIME(HOUR(B6), MINUTE(B6), 0), "yyyymmddhhmm") -> 202601311100
A7: ='10U COED GOLD-16 TEAMS CUSTOM'!A15 -> 46053 | B7: ='10U COED GOLD-16 TEAMS CUSTOM'!B15 -> 0.45833333 | C7: ='10U COED GOLD-16 TEAMS CUSTOM'!C15&"" -> EL TORO HS 2 | D7: ='10U COED GOLD-16 TEAMS CUSTOM'!D15&"" -> 10Cau07 | E7: ='10U COED GOLD-16 TEAMS CUSTOM'!E15&"" -> D2-PATRIOT WHITE | F7: ='10U COED GOLD-16 TEAMS CUSTOM'!F15&"" -> 5 | G7: ='10U COED GOLD-16 TEAMS CUSTOM'!G15&"" -> D3-YOLO YELLOW | H7: ='10U COED GOLD-16 TEAMS CUSTOM'!H15&"" -> 16 | I7: ='10U COED GOLD-16 TEAMS CUSTOM'!I15&"" -> D bracket D2,D3 | J7: ='10U COED GOLD-16 TEAMS CUSTOM'!J15&"" -> 10U_COED_GOLD | K7: =TEXT(DATE(2026, MONTH(A7), DAY(A7)) + TIME(HOUR(B7), MINUTE(B7), 0), "yyyymmddhhmm") -> 202601311100
A8: ='10U COED GOLD-16 TEAMS CUSTOM'!A16 -> 46053 | B8: ='10U COED GOLD-16 TEAMS CUSTOM'!B16 -> 0.48958333 | C8: ='10U COED GOLD-16 TEAMS CUSTOM'!C16&"" -> WOOLLETT FAR LEFT | D8: ='10U COED GOLD-16 TEAMS CUSTOM'!D16&"" -> 10Cau06 | E8: ='10U COED GOLD-16 TEAMS CUSTOM'!E16&"" -> G2-DEL MAR BLUE (girls) | F8: ='10U COED GOLD-16 TEAMS CUSTOM'!F16&"" -> 12 | G8: ='10U COED GOLD-16 TEAMS CUSTOM'!G16&"" -> G3-680 RED (girls) | H8: ='10U COED GOLD-16 TEAMS CUSTOM'!H16&"" -> 5 | I8: ='10U COED GOLD-16 TEAMS CUSTOM'!I16&"" -> girls 1st-4th | J8: ='10U COED GOLD-16 TEAMS CUSTOM'!J16&"" -> 10U_COED_GOLD | K8: =TEXT(DATE(2026, MONTH(A8), DAY(A8)) + TIME(HOUR(B8), MINUTE(B8), 0), "yyyymmddhhmm") -> 202601311145
A9: ='10U COED GOLD-16 TEAMS CUSTOM'!A17 -> 46053 | B9: ='10U COED GOLD-16 TEAMS CUSTOM'!B17 -> 0.48958333 | C9: ='10U COED GOLD-16 TEAMS CUSTOM'!C17&"" -> EL TORO HS 2 | D9: ='10U COED GOLD-16 TEAMS CUSTOM'!D17&"" -> 10Cau08 | E9: ='10U COED GOLD-16 TEAMS CUSTOM'!E17&"" -> A2-LOYOLA WPC | F9: ='10U COED GOLD-16 TEAMS CUSTOM'!F17&"" -> 17 | G9: ='10U COED GOLD-16 TEAMS CUSTOM'!G17&"" -> A3-LAMORINDA C | H9: ='10U COED GOLD-16 TEAMS CUSTOM'!H17&"" -> 1 | I9: ='10U COED GOLD-16 TEAMS CUSTOM'!I17&"" -> A bracket A2,A3 | J9: ='10U COED GOLD-16 TEAMS CUSTOM'!J17&"" -> 10U_COED_GOLD | K9: =TEXT(DATE(2026, MONTH(A9), DAY(A9)) + TIME(HOUR(B9), MINUTE(B9), 0), "yyyymmddhhmm") -> 202601311145
A10: ='10U COED GOLD-16 TEAMS CUSTOM'!A18 -> 46053 | B10: ='10U COED GOLD-16 TEAMS CUSTOM'!B18 -> 0.52083333 | C10: ='10U COED GOLD-16 TEAMS CUSTOM'!C18&"" -> EL TORO HS 2 | D10: ='10U COED GOLD-16 TEAMS CUSTOM'!D18&"" -> 10Cau09 | E10: ='10U COED GOLD-16 TEAMS CUSTOM'!E18&"" -> B2-ORANGE COUNTY WPC RED | F10: ='10U COED GOLD-16 TEAMS CUSTOM'!F18&"" -> 19 | G10: ='10U COED GOLD-16 TEAMS CUSTOM'!G18&"" -> B3-DEL MAR WHITE | H10: ='10U COED GOLD-16 TEAMS CUSTOM'!H18&"" -> 6 | I10: ='10U COED GOLD-16 TEAMS CUSTOM'!I18&"" -> B bracket B2,B3 | J10: ='10U COED GOLD-16 TEAMS CUSTOM'!J18&"" -> 10U_COED_GOLD | K10: =TEXT(DATE(2026, MONTH(A10), DAY(A10)) + TIME(HOUR(B10), MINUTE(B10), 0), "yyyymmddhhmm") -> 202601311230
A11: ='10U COED GOLD-16 TEAMS CUSTOM'!A19 -> 46053 | B11: ='10U COED GOLD-16 TEAMS CUSTOM'!B19 -> 0.55208333 | C11: ='10U COED GOLD-16 TEAMS CUSTOM'!C19&"" -> EL TORO HS 2 | D11: ='10U COED GOLD-16 TEAMS CUSTOM'!D19&"" -> 10Cau10 | E11: ='10U COED GOLD-16 TEAMS CUSTOM'!E19&"" -> C2-SOUTH BAY UNITED | F11: ='10U COED GOLD-16 TEAMS CUSTOM'!F19&"" -> 11 | G11: ='10U COED GOLD-16 TEAMS CUSTOM'!G19&"" -> C3-SAN CLEMENTE BLACK | H11: ='10U COED GOLD-16 TEAMS CUSTOM'!H19&"" -> 8 | I11: ='10U COED GOLD-16 TEAMS CUSTOM'!I19&"" -> C bracket C2,C3 | J11: ='10U COED GOLD-16 TEAMS CUSTOM'!J19&"" -> 10U_COED_GOLD | K11: =TEXT(DATE(2026, MONTH(A11), DAY(A11)) + TIME(HOUR(B11), MINUTE(B11), 0), "yyyymmddhhmm") -> 202601311315
A12: ='10U COED GOLD-16 TEAMS CUSTOM'!A20 -> 46053 | B12: ='10U COED GOLD-16 TEAMS CUSTOM'!B20 -> 0.58333333 | C12: ='10U COED GOLD-16 TEAMS CUSTOM'!C20&"" -> BECKMAN HS 2 | D12: ='10U COED GOLD-16 TEAMS CUSTOM'!D20&"" -> 10Cau13 | E12: ='10U COED GOLD-16 TEAMS CUSTOM'!E20&"" -> D1-TROJAN | F12: ='10U COED GOLD-16 TEAMS CUSTOM'!F20&"" -> 1 | G12: ='10U COED GOLD-16 TEAMS CUSTOM'!G20&"" -> D2-PATRIOT WHITE | H12: ='10U COED GOLD-16 TEAMS CUSTOM'!H20&"" -> 2 | I12: ='10U COED GOLD-16 TEAMS CUSTOM'!I20&"" -> D bracket D1,D2 | J12: ='10U COED GOLD-16 TEAMS CUSTOM'!J20&"" -> 10U_COED_GOLD | K12: =TEXT(DATE(2026, MONTH(A12), DAY(A12)) + TIME(HOUR(B12), MINUTE(B12), 0), "yyyymmddhhmm") -> 202601311400
A13: ='10U COED GOLD-16 TEAMS CUSTOM'!A21 -> 46053 | B13: ='10U COED GOLD-16 TEAMS CUSTOM'!B21 -> 0.61458333 | C13: ='10U COED GOLD-16 TEAMS CUSTOM'!C21&"" -> BECKMAN HS 2 | D13: ='10U COED GOLD-16 TEAMS CUSTOM'!D21&"" -> 10Cau14 | E13: ='10U COED GOLD-16 TEAMS CUSTOM'!E21&"" -> A1-LA JOLLA UNITED | F13: ='10U COED GOLD-16 TEAMS CUSTOM'!F21&"" -> 9 | G13: ='10U COED GOLD-16 TEAMS CUSTOM'!G21&"" -> A2-LOYOLA WPC | H13: ='10U COED GOLD-16 TEAMS CUSTOM'!H21&"" -> 7 | I13: ='10U COED GOLD-16 TEAMS CUSTOM'!I21&"" -> A bracket A1,A2 | J13: ='10U COED GOLD-16 TEAMS CUSTOM'!J21&"" -> 10U_COED_GOLD | K13: =TEXT(DATE(2026, MONTH(A13), DAY(A13)) + TIME(HOUR(B13), MINUTE(B13), 0), "yyyymmddhhmm") -> 202601311445
A14: ='10U COED GOLD-16 TEAMS CUSTOM'!A22 -> 46053 | B14: ='10U COED GOLD-16 TEAMS CUSTOM'!B22 -> 0.64583333 | C14: ='10U COED GOLD-16 TEAMS CUSTOM'!C22&"" -> WOOLLETT FAR LEFT | D14: ='10U COED GOLD-16 TEAMS CUSTOM'!D22&"" -> 10Cau11 | E14: ='10U COED GOLD-16 TEAMS CUSTOM'!E22&"" -> G1-LAMORINDA BLUE (A) (girls) | F14: ='10U COED GOLD-16 TEAMS CUSTOM'!F22&"" -> 17 | G14: ='10U COED GOLD-16 TEAMS CUSTOM'!G22&"" -> G3-680 RED (girls) | H14: ='10U COED GOLD-16 TEAMS CUSTOM'!H22&"" -> 3 | I14: ='10U COED GOLD-16 TEAMS CUSTOM'!I22&"" -> girls 1st-4th | J14: ='10U COED GOLD-16 TEAMS CUSTOM'!J22&"" -> 10U_COED_GOLD | K14: =TEXT(DATE(2026, MONTH(A14), DAY(A14)) + TIME(HOUR(B14), MINUTE(B14), 0), "yyyymmddhhmm") -> 202601311530
A15: ='10U COED GOLD-16 TEAMS CUSTOM'!A23 -> 46053 | B15: ='10U COED GOLD-16 TEAMS CUSTOM'!B23 -> 0.64583333 | C15: ='10U COED GOLD-16 TEAMS CUSTOM'!C23&"" -> BECKMAN HS 2 | D15: ='10U COED GOLD-16 TEAMS CUSTOM'!D23&"" -> 10Cau15 | E15: ='10U COED GOLD-16 TEAMS CUSTOM'!E23&"" -> B1-DAVIS | F15: ='10U COED GOLD-16 TEAMS CUSTOM'!F23&"" -> 14 | G15: ='10U COED GOLD-16 TEAMS CUSTOM'!G23&"" -> B2-ORANGE COUNTY WPC RED | H15: ='10U COED GOLD-16 TEAMS CUSTOM'!H23&"" -> 6 | I15: ='10U COED GOLD-16 TEAMS CUSTOM'!I23&"" -> B bracket B1,B2 | J15: ='10U COED GOLD-16 TEAMS CUSTOM'!J23&"" -> 10U_COED_GOLD | K15: =TEXT(DATE(2026, MONTH(A15), DAY(A15)) + TIME(HOUR(B15), MINUTE(B15), 0), "yyyymmddhhmm") -> 202601311530
... A17: ='10U COED GOLD-16 TEAMS CUSTOM'!A25 -> 46053 | B17: ='10U COED GOLD-16 TEAMS CUSTOM'!B25 -> 0.67708333 | C17: ='10U COED GOLD-16 TEAMS CUSTOM'!C25&"" -> BECKMAN HS 2 | D17: ='10U COED GOLD-16 TEAMS CUSTOM'!D25&"" -> 10Cau16 | E17: ='10U COED GOLD-16 TEAMS CUSTOM'!E25&"" -> C1-SOUTH COAST RED | F17: ='10U COED GOLD-16 TEAMS CUSTOM'!F25&"" -> 10 | G17: ='10U COED GOLD-16 TEAMS CUSTOM'!G25&"" -> C2-SOUTH BAY UNITED | H17: ='10U COED GOLD-16 TEAMS CUSTOM'!H25&"" -> 14 | I17: ='10U COED GOLD-16 TEAMS CUSTOM'!I25&"" -> C bracket C1,C2 | J17: ='10U COED GOLD-16 TEAMS CUSTOM'!J25&"" -> 10U_COED_GOLD | K17: =TEXT(DATE(2026, MONTH(A17), DAY(A17)) + TIME(HOUR(B17), MINUTE(B17), 0), "yyyymmddhhmm") -> 202601311615
A18: ='10U COED GOLD-16 TEAMS CUSTOM'!A29 -> 46054 | B18: ='10U COED GOLD-16 TEAMS CUSTOM'!B29 -> 0.33333333 | C18: ='10U COED GOLD-16 TEAMS CUSTOM'!C29&"" -> WOOLLETT FAR LEFT | D18: ='10U COED GOLD-16 TEAMS CUSTOM'!D29&"" -> 10Cau17 | E18: ='10U COED GOLD-16 TEAMS CUSTOM'!E29&"" -> G1-LAMORINDA BLUE (A) (girls) | F18: ='10U COED GOLD-16 TEAMS CUSTOM'!F29&"" -> 8 | G18: ='10U COED GOLD-16 TEAMS CUSTOM'!G29&"" -> G2-DEL MAR BLUE (girls) | H18: ='10U COED GOLD-16 TEAMS CUSTOM'!H29&"" -> 2 | I18: ='10U COED GOLD-16 TEAMS CUSTOM'!I29&"" -> girls 1st-4th | J18: ='10U COED GOLD-16 TEAMS CUSTOM'!J29&"" -> 10U_COED_GOLD | K18: =TEXT(DATE(2026, MONTH(A18), DAY(A18)) + TIME(HOUR(B18), MINUTE(B18), 0), "yyyymmddhhmm") -> 202602010800
A19: ='10U COED GOLD-16 TEAMS CUSTOM'!A30 -> 46054 | B19: ='10U COED GOLD-16 TEAMS CUSTOM'!B30 -> 0.33333333 | C19: ='10U COED GOLD-16 TEAMS CUSTOM'!C30&"" -> EL TORO HS 2 | D19: ='10U COED GOLD-16 TEAMS CUSTOM'!D30&"" -> 10Cau19 | E19: ='10U COED GOLD-16 TEAMS CUSTOM'!E30&"" -> 2ndA-LOYOLA WPC | F19: ='10U COED GOLD-16 TEAMS CUSTOM'!F30&"" -> 18 | G19: ='10U COED GOLD-16 TEAMS CUSTOM'!G30&"" -> 2ndD-TROJAN | H19: ='10U COED GOLD-16 TEAMS CUSTOM'!H30&"" -> 7 | I19: ='10U COED GOLD-16 TEAMS CUSTOM'!I30&"" -> 5-8 coed semi | J19: ='10U COED GOLD-16 TEAMS CUSTOM'!J30&"" -> 10U_COED_GOLD | K19: =TEXT(DATE(2026, MONTH(A19), DAY(A19)) + TIME(HOUR(B19), MINUTE(B19), 0), "yyyymmddhhmm") -> 202602010800
A20: ='10U COED GOLD-16 TEAMS CUSTOM'!A31 -> 46054 | B20: ='10U COED GOLD-16 TEAMS CUSTOM'!B31 -> 0.36458333 | C20: ='10U COED GOLD-16 TEAMS CUSTOM'!C31&"" -> WOOLLETT FAR LEFT | D20: ='10U COED GOLD-16 TEAMS CUSTOM'!D31&"" -> 10Cau18 | E20: ='10U COED GOLD-16 TEAMS CUSTOM'!E31&"" -> G3-680 RED (girls) | F20: ='10U COED GOLD-16 TEAMS CUSTOM'!F31&"" -> 11 | G20: ='10U COED GOLD-16 TEAMS CUSTOM'!G31&"" -> G4-SAN CLEMENTE RED (girls) | H20: ='10U COED GOLD-16 TEAMS CUSTOM'!H31&"" -> 8 | I20: ='10U COED GOLD-16 TEAMS CUSTOM'!I31&"" -> girls 1st-4th | J20: ='10U COED GOLD-16 TEAMS CUSTOM'!J31&"" -> 10U_COED_GOLD | K20: =TEXT(DATE(2026, MONTH(A20), DAY(A20)) + TIME(HOUR(B20), MINUTE(B20), 0), "yyyymmddhhmm") -> 202602010845
A21: ='10U COED GOLD-16 TEAMS CUSTOM'!A32 -> 46054 | B21: ='10U COED GOLD-16 TEAMS CUSTOM'!B32 -> 0.36458333 | C21: ='10U COED GOLD-16 TEAMS CUSTOM'!C32&"" -> EL TORO HS 2 | D21: ='10U COED GOLD-16 TEAMS CUSTOM'!D32&"" -> 10Cau20 | E21: ='10U COED GOLD-16 TEAMS CUSTOM'!E32&"" -> 2ndB-ORANGE COUNTY WPC RED | F21: ='10U COED GOLD-16 TEAMS CUSTOM'!F32&"" -> 13 | G21: ='10U COED GOLD-16 TEAMS CUSTOM'!G32&"" -> 2ndC-SAN CLEMENTE BLACK | H21: ='10U COED GOLD-16 TEAMS CUSTOM'!H32&"" -> 19 | I21: ='10U COED GOLD-16 TEAMS CUSTOM'!I32&"" -> 5-8 coed semi | J21: ='10U COED GOLD-16 TEAMS CUSTOM'!J32&"" -> 10U_COED_GOLD | K21: =TEXT(DATE(2026, MONTH(A21), DAY(A21)) + TIME(HOUR(B21), MINUTE(B21), 0), "yyyymmddhhmm") -> 202602010845
A22: ='10U COED GOLD-16 TEAMS CUSTOM'!A33 -> 46054 | B22: ='10U COED GOLD-16 TEAMS CUSTOM'!B33 -> 0.39583333 | C22: ='10U COED GOLD-16 TEAMS CUSTOM'!C33&"" -> EL TORO HS 2 | D22: ='10U COED GOLD-16 TEAMS CUSTOM'!D33&"" -> 10Cau21 | E22: ='10U COED GOLD-16 TEAMS CUSTOM'!E33&"" -> 1stA-LA JOLLA UNITED | F22: ='10U COED GOLD-16 TEAMS CUSTOM'!F33&"" -> 6.3 | G22: ='10U COED GOLD-16 TEAMS CUSTOM'!G33&"" -> 1stD-YOLO YELLOW | H22: ='10U COED GOLD-16 TEAMS CUSTOM'!H33&"" -> 6 | I22: ='10U COED GOLD-16 TEAMS CUSTOM'!I33&"" -> 1-4 coed semi | J22: ='10U COED GOLD-16 TEAMS CUSTOM'!J33&"" -> 10U_COED_GOLD | K22: =TEXT(DATE(2026, MONTH(A22), DAY(A22)) + TIME(HOUR(B22), MINUTE(B22), 0), "yyyymmddhhmm") -> 202602010930
A23: ='10U COED GOLD-16 TEAMS CUSTOM'!A34 -> 46054 | B23: ='10U COED GOLD-16 TEAMS CUSTOM'!B34 -> 0.42708333 | C23: ='10U COED GOLD-16 TEAMS CUSTOM'!C34&"" -> EL TORO HS 2 | D23: ='10U COED GOLD-16 TEAMS CUSTOM'!D34&"" -> 10Cau22 | E23: ='10U COED GOLD-16 TEAMS CUSTOM'!E34&"" -> 1stB-DAVIS | F23: ='10U COED GOLD-16 TEAMS CUSTOM'!F34&"" -> 17 | G23: ='10U COED GOLD-16 TEAMS CUSTOM'!G34&"" -> 1stC-SOUTH BAY UNITED | H23: ='10U COED GOLD-16 TEAMS CUSTOM'!H34&"" -> 4 | I23: ='10U COED GOLD-16 TEAMS CUSTOM'!I34&"" -> 1-4 coed semi | J23: ='10U COED GOLD-16 TEAMS CUSTOM'!J34&"" -> 10U_COED_GOLD | K23: =TEXT(DATE(2026, MONTH(A23), DAY(A23)) + TIME(HOUR(B23), MINUTE(B23), 0), "yyyymmddhhmm") -> 202602011015
A24: ='10U COED GOLD-16 TEAMS CUSTOM'!A35 -> 46054 | B24: ='10U COED GOLD-16 TEAMS CUSTOM'!B35 -> 0.45833333 | C24: ='10U COED GOLD-16 TEAMS CUSTOM'!C35&"" -> BECKMAN HS 2 | D24: ='10U COED GOLD-16 TEAMS CUSTOM'!D35&"" -> 10Cau23 | E24: ='10U COED GOLD-16 TEAMS CUSTOM'!E35&"" -> G1-LAMORINDA BLUE (A) (girls) | F24: ='10U COED GOLD-16 TEAMS CUSTOM'!F35&"" -> 19 | G24: ='10U COED GOLD-16 TEAMS CUSTOM'!G35&"" -> 3rdB-DEL MAR WHITE | H24: ='10U COED GOLD-16 TEAMS CUSTOM'!H35&"" -> 0 | I24: ='10U COED GOLD-16 TEAMS CUSTOM'!I35&"" -> girls-coed interact | J24: ='10U COED GOLD-16 TEAMS CUSTOM'!J35&"" -> 10U_COED_GOLD | K24: =TEXT(DATE(2026, MONTH(A24), DAY(A24)) + TIME(HOUR(B24), MINUTE(B24), 0), "yyyymmddhhmm") -> 202602011100
A25: ='10U COED GOLD-16 TEAMS CUSTOM'!A36 -> 46054 | B25: ='10U COED GOLD-16 TEAMS CUSTOM'!B36 -> 0.45833333 | C25: ='10U COED GOLD-16 TEAMS CUSTOM'!C36&"" -> EL TORO HS 2 | D25: ='10U COED GOLD-16 TEAMS CUSTOM'!D36&"" -> 10Cau25 | E25: ='10U COED GOLD-16 TEAMS CUSTOM'!E36&"" -> G3-680 RED (girls) | F25: ='10U COED GOLD-16 TEAMS CUSTOM'!F36&"" -> 17 | G25: ='10U COED GOLD-16 TEAMS CUSTOM'!G36&"" -> 3rdC-SOUTH COAST RED | H25: ='10U COED GOLD-16 TEAMS CUSTOM'!H36&"" -> 16 | I25: ='10U COED GOLD-16 TEAMS CUSTOM'!I36&"" -> girls-coed interact | J25: ='10U COED GOLD-16 TEAMS CUSTOM'!J36&"" -> 10U_COED_GOLD | K25: =TEXT(DATE(2026, MONTH(A25), DAY(A25)) + TIME(HOUR(B25), MINUTE(B25), 0), "yyyymmddhhmm") -> 202602011100
A26: ='10U COED GOLD-16 TEAMS CUSTOM'!A37 -> 46054 | B26: ='10U COED GOLD-16 TEAMS CUSTOM'!B37 -> 0.48958333 | C26: ='10U COED GOLD-16 TEAMS CUSTOM'!C37&"" -> BECKMAN HS 2 | D26: ='10U COED GOLD-16 TEAMS CUSTOM'!D37&"" -> 10Cau24 | E26: ='10U COED GOLD-16 TEAMS CUSTOM'!E37&"" -> G2-DEL MAR BLUE (girls) | F26: ='10U COED GOLD-16 TEAMS CUSTOM'!F37&"" -> 15 | G26: ='10U COED GOLD-16 TEAMS CUSTOM'!G37&"" -> 3rdD-PATRIOT WHITE | H26: ='10U COED GOLD-16 TEAMS CUSTOM'!H37&"" -> 2 | I26: ='10U COED GOLD-16 TEAMS CUSTOM'!I37&"" -> girls-coed interact | J26: ='10U COED GOLD-16 TEAMS CUSTOM'!J37&"" -> 10U_COED_GOLD | K26: =TEXT(DATE(2026, MONTH(A26), DAY(A26)) + TIME(HOUR(B26), MINUTE(B26), 0), "yyyymmddhhmm") -> 202602011145
A27: ='10U COED GOLD-16 TEAMS CUSTOM'!A38 -> 46054 | B27: ='10U COED GOLD-16 TEAMS CUSTOM'!B38 -> 0.48958333 | C27: ='10U COED GOLD-16 TEAMS CUSTOM'!C38&"" -> EL TORO HS 2 | D27: ='10U COED GOLD-16 TEAMS CUSTOM'!D38&"" -> 10Cau26 | E27: ='10U COED GOLD-16 TEAMS CUSTOM'!E38&"" -> G4-SAN CLEMENTE RED (girls) | F27: ='10U COED GOLD-16 TEAMS CUSTOM'!F38&"" -> 12 | G27: ='10U COED GOLD-16 TEAMS CUSTOM'!G38&"" -> 3rdA-LAMORINDA C | H27: ='10U COED GOLD-16 TEAMS CUSTOM'!H38&"" -> 7 | I27: ='10U COED GOLD-16 TEAMS CUSTOM'!I38&"" -> girls-coed interact | J27: ='10U COED GOLD-16 TEAMS CUSTOM'!J38&"" -> 10U_COED_GOLD | K27: =TEXT(DATE(2026, MONTH(A27), DAY(A27)) + TIME(HOUR(B27), MINUTE(B27), 0), "yyyymmddhhmm") -> 202602011145
A28: ='10U COED GOLD-16 TEAMS CUSTOM'!A39 -> 46054 | B28: ='10U COED GOLD-16 TEAMS CUSTOM'!B39 -> 0.52083333 | C28: ='10U COED GOLD-16 TEAMS CUSTOM'!C39&"" -> EL TORO HS 2 | D28: ='10U COED GOLD-16 TEAMS CUSTOM'!D39&"" -> 10Cau27 | E28: ='10U COED GOLD-16 TEAMS CUSTOM'!E39&"" -> L#19-TROJAN | F28: ='10U COED GOLD-16 TEAMS CUSTOM'!F39&"" -> 18 | G28: ='10U COED GOLD-16 TEAMS CUSTOM'!G39&"" -> L#20-ORANGE COUNTY WPC RED | H28: ='10U COED GOLD-16 TEAMS CUSTOM'!H39&"" -> 12 | I28: ='10U COED GOLD-16 TEAMS CUSTOM'!I39&"" -> 7th Coed | J28: ='10U COED GOLD-16 TEAMS CUSTOM'!J39&"" -> 10U_COED_GOLD | K28: =TEXT(DATE(2026, MONTH(A28), DAY(A28)) + TIME(HOUR(B28), MINUTE(B28), 0), "yyyymmddhhmm") -> 202602011230
A29: ='10U COED GOLD-16 TEAMS CUSTOM'!A40 -> 46054 | B29: ='10U COED GOLD-16 TEAMS CUSTOM'!B40 -> 0.52083333 | C29: ='10U COED GOLD-16 TEAMS CUSTOM'!C40&"" -> WOOLLETT FAR LEFT | D29: ='10U COED GOLD-16 TEAMS CUSTOM'!D40&"" -> 10Cau29 | E29: ='10U COED GOLD-16 TEAMS CUSTOM'!E40&"" -> L#21-YOLO YELLOW | F29: ='10U COED GOLD-16 TEAMS CUSTOM'!F40&"" -> 11.2 | G29: ='10U COED GOLD-16 TEAMS CUSTOM'!G40&"" -> L#22-SOUTH BAY UNITED | H29: ='10U COED GOLD-16 TEAMS CUSTOM'!H40&"" -> 11.1 | I29: ='10U COED GOLD-16 TEAMS CUSTOM'!I40&"" -> 3rd Coed | J29: ='10U COED GOLD-16 TEAMS CUSTOM'!J40&"" -> 10U_COED_GOLD | K29: =TEXT(DATE(2026, MONTH(A29), DAY(A29)) + TIME(HOUR(B29), MINUTE(B29), 0), "yyyymmddhhmm") -> 202602011230
... A33: ='10U COED GOLD-16 TEAMS CUSTOM'!A44 -> 46054 | B33: ='10U COED GOLD-16 TEAMS CUSTOM'!B44 -> 0.61458333 | C33: ='10U COED GOLD-16 TEAMS CUSTOM'!C44&"" -> EL TORO HS 2 | D33: ='10U COED GOLD-16 TEAMS CUSTOM'!D44&"" -> 10Cau32 | E33: ='10U COED GOLD-16 TEAMS CUSTOM'!E44&"" -> 3rdB-DEL MAR WHITE | F33: ='10U COED GOLD-16 TEAMS CUSTOM'!F44&"" | G33: ='10U COED GOLD-16 TEAMS CUSTOM'!G44&"" -> 3rdC-SOUTH COAST RED | H33: ='10U COED GOLD-16 TEAMS CUSTOM'!H44&"" -> 12 | I33: ='10U COED GOLD-16 TEAMS CUSTOM'!I44&"" -> coed 9-12 | J33: ='10U COED GOLD-16 TEAMS CUSTOM'!J44&"" -> 10U_COED_GOLD | K33: =TEXT(DATE(2026, MONTH(A33), DAY(A33)) + TIME(HOUR(B33), MINUTE(B33), 0), "yyyymmddhhmm") -> 202602011445
A34: ='10U COED PLATINUM-8 TEAMS'!A10 -> 46053 | B34: ='10U COED PLATINUM-8 TEAMS'!B10 -> 0.33333333 | C34: ='10U COED PLATINUM-8 TEAMS'!C10&"" -> WOOLLETT FAR LEFT | D34: ='10U COED PLATINUM-8 TEAMS'!D10&"" -> 10Cpt01 | E34: ='10U COED PLATINUM-8 TEAMS'!E10&"" -> B1-ORANGE COUNTY WPC BLUE | F34: ='10U COED PLATINUM-8 TEAMS'!F10&"" -> 15 | G34: ='10U COED PLATINUM-8 TEAMS'!G10&"" -> B3-PATRIOT RED | H34: ='10U COED PLATINUM-8 TEAMS'!H10&"" -> 3 | I34: ='10U COED PLATINUM-8 TEAMS'!I10&"" -> bracket, B1/B3 | J34: ='10U COED PLATINUM-8 TEAMS'!J10&"" -> 10U_COED_PLATINUM | K34: =TEXT(DATE(2026, MONTH(A34), DAY(A34)) + TIME(HOUR(B34), MINUTE(B34), 0), "yyyymmddhhmm") -> 202601310800
A35: ='10U COED PLATINUM-8 TEAMS'!A11 -> 46053 | B35: ='10U COED PLATINUM-8 TEAMS'!B11 -> 0.36458333 | C35: ='10U COED PLATINUM-8 TEAMS'!C11&"" -> WOOLLETT FAR LEFT | D35: ='10U COED PLATINUM-8 TEAMS'!D11&"" -> 10Cpt02 | E35: ='10U COED PLATINUM-8 TEAMS'!E11&"" -> B2-CHULA VISTA PREMIER | F35: ='10U COED PLATINUM-8 TEAMS'!F11&"" -> 17 | G35: ='10U COED PLATINUM-8 TEAMS'!G11&"" -> B4-LAMORINDA GOLD (B) | H35: ='10U COED PLATINUM-8 TEAMS'!H11&"" -> 2 | I35: ='10U COED PLATINUM-8 TEAMS'!I11&"" -> bracket, B2/B4 | J35: ='10U COED PLATINUM-8 TEAMS'!J11&"" -> 10U_COED_PLATINUM | K35: =TEXT(DATE(2026, MONTH(A35), DAY(A35)) + TIME(HOUR(B35), MINUTE(B35), 0), "yyyymmddhhmm") -> 202601310845
A36: ='10U COED PLATINUM-8 TEAMS'!A12 -> 46053 | B36: ='10U COED PLATINUM-8 TEAMS'!B12 -> 0.39583333 | C36: ='10U COED PLATINUM-8 TEAMS'!C12&"" -> WOOLLETT FAR LEFT | D36: ='10U COED PLATINUM-8 TEAMS'!D12&"" -> 10Cpt03 | E36: ='10U COED PLATINUM-8 TEAMS'!E12&"" -> A1-CHANNEL ISLANDS UNITED | F36: ='10U COED PLATINUM-8 TEAMS'!F12&"" -> 10 | G36: ='10U COED PLATINUM-8 TEAMS'!G12&"" -> A3-YOLO BLACK | H36: ='10U COED PLATINUM-8 TEAMS'!H12&"" -> 9 | I36: ='10U COED PLATINUM-8 TEAMS'!I12&"" -> bracket, A1/A3 | J36: ='10U COED PLATINUM-8 TEAMS'!J12&"" -> 10U_COED_PLATINUM | K36: =TEXT(DATE(2026, MONTH(A36), DAY(A36)) + TIME(HOUR(B36), MINUTE(B36), 0), "yyyymmddhhmm") -> 202601310930
A37: ='10U COED PLATINUM-8 TEAMS'!A13 -> 46053 | B37: ='10U COED PLATINUM-8 TEAMS'!B13 -> 0.42708333 | C37: ='10U COED PLATINUM-8 TEAMS'!C13&"" -> WOOLLETT FAR LEFT | D37: ='10U COED PLATINUM-8 TEAMS'!D13&"" -> 10Cpt04 | E37: ='10U COED PLATINUM-8 TEAMS'!E13&"" -> A2-FOOTHILL RED | F37: ='10U COED PLATINUM-8 TEAMS'!F13&"" -> 2 | G37: ='10U COED PLATINUM-8 TEAMS'!G13&"" -> A4-NORTH IRVINE BLACK | H37: ='10U COED PLATINUM-8 TEAMS'!H13&"" -> 15 | I37: ='10U COED PLATINUM-8 TEAMS'!I13&"" -> bracket, A2/A4 | J37: ='10U COED PLATINUM-8 TEAMS'!J13&"" -> 10U_COED_PLATINUM | K37: =TEXT(DATE(2026, MONTH(A37), DAY(A37)) + TIME(HOUR(B37), MINUTE(B37), 0), "yyyymmddhhmm") -> 202601311015
A38: ='10U COED PLATINUM-8 TEAMS'!A15 -> 46053 | B38: ='10U COED PLATINUM-8 TEAMS'!B15 -> 0.52083333 | C38: ='10U COED PLATINUM-8 TEAMS'!C15&"" -> WOOLLETT FAR LEFT | D38: ='10U COED PLATINUM-8 TEAMS'!D15&"" -> 10Cpt05 | E38: ='10U COED PLATINUM-8 TEAMS'!E15&"" -> B1-ORANGE COUNTY WPC BLUE | F38: ='10U COED PLATINUM-8 TEAMS'!F15&"" -> 16 | G38: ='10U COED PLATINUM-8 TEAMS'!G15&"" -> B4-LAMORINDA GOLD (B) | H38: ='10U COED PLATINUM-8 TEAMS'!H15&"" -> 3 | I38: ='10U COED PLATINUM-8 TEAMS'!I15&"" -> bracket, B1/B4 | J38: ='10U COED PLATINUM-8 TEAMS'!J15&"" -> 10U_COED_PLATINUM | K38: =TEXT(DATE(2026, MONTH(A38), DAY(A38)) + TIME(HOUR(B38), MINUTE(B38), 0), "yyyymmddhhmm") -> 202601311230
A39: ='10U COED PLATINUM-8 TEAMS'!A16 -> 46053 | B39: ='10U COED PLATINUM-8 TEAMS'!B16 -> 0.55208333 | C39: ='10U COED PLATINUM-8 TEAMS'!C16&"" -> WOOLLETT FAR LEFT | D39: ='10U COED PLATINUM-8 TEAMS'!D16&"" -> 10Cpt06 | E39: ='10U COED PLATINUM-8 TEAMS'!E16&"" -> B2-CHULA VISTA PREMIER | F39: ='10U COED PLATINUM-8 TEAMS'!F16&"" -> 18 | G39: ='10U COED PLATINUM-8 TEAMS'!G16&"" -> B3-PATRIOT RED | H39: ='10U COED PLATINUM-8 TEAMS'!H16&"" -> 8 | I39: ='10U COED PLATINUM-8 TEAMS'!I16&"" -> bracket, B2/B3 | J39: ='10U COED PLATINUM-8 TEAMS'!J16&"" -> 10U_COED_PLATINUM | K39: =TEXT(DATE(2026, MONTH(A39), DAY(A39)) + TIME(HOUR(B39), MINUTE(B39), 0), "yyyymmddhhmm") -> 202601311315
A40: ='10U COED PLATINUM-8 TEAMS'!A17 -> 46053 | B40: ='10U COED PLATINUM-8 TEAMS'!B17 -> 0.58333333 | C40: ='10U COED PLATINUM-8 TEAMS'!C17&"" -> WOOLLETT FAR LEFT | D40: ='10U COED PLATINUM-8 TEAMS'!D17&"" -> 10Cpt07 | E40: ='10U COED PLATINUM-8 TEAMS'!E17&"" -> A1-CHANNEL ISLANDS UNITED | F40: ='10U COED PLATINUM-8 TEAMS'!F17&"" -> 11 | G40: ='10U COED PLATINUM-8 TEAMS'!G17&"" -> A4-NORTH IRVINE BLACK | H40: ='10U COED PLATINUM-8 TEAMS'!H17&"" -> 12 | I40: ='10U COED PLATINUM-8 TEAMS'!I17&"" -> bracket, A1/A4 | J40: ='10U COED PLATINUM-8 TEAMS'!J17&"" -> 10U_COED_PLATINUM | K40: =TEXT(DATE(2026, MONTH(A40), DAY(A40)) + TIME(HOUR(B40), MINUTE(B40), 0), "yyyymmddhhmm") -> 202601311400
A41: ='10U COED PLATINUM-8 TEAMS'!A18 -> 46053 | B41: ='10U COED PLATINUM-8 TEAMS'!B18 -> 0.61458333 | C41: ='10U COED PLATINUM-8 TEAMS'!C18&"" -> WOOLLETT FAR LEFT | D41: ='10U COED PLATINUM-8 TEAMS'!D18&"" -> 10Cpt08 | E41: ='10U COED PLATINUM-8 TEAMS'!E18&"" -> A2-FOOTHILL RED | F41: ='10U COED PLATINUM-8 TEAMS'!F18&"" -> 5 | G41: ='10U COED PLATINUM-8 TEAMS'!G18&"" -> A3-YOLO BLACK | H41: ='10U COED PLATINUM-8 TEAMS'!H18&"" -> 11 | I41: ='10U COED PLATINUM-8 TEAMS'!I18&"" -> bracket, A2/A3 | J41: ='10U COED PLATINUM-8 TEAMS'!J18&"" -> 10U_COED_PLATINUM | K41: =TEXT(DATE(2026, MONTH(A41), DAY(A41)) + TIME(HOUR(B41), MINUTE(B41), 0), "yyyymmddhhmm") -> 202601311445
A42: ='10U COED PLATINUM-8 TEAMS'!A22 -> 46054 | B42: ='10U COED PLATINUM-8 TEAMS'!B22 -> 0.39583333 | C42: ='10U COED PLATINUM-8 TEAMS'!C22&"" -> WOOLLETT FAR LEFT | D42: ='10U COED PLATINUM-8 TEAMS'!D22&"" -> 10Cpt09 | E42: ='10U COED PLATINUM-8 TEAMS'!E22&"" -> B3-PATRIOT RED | F42: ='10U COED PLATINUM-8 TEAMS'!F22&"" -> 21 | G42: ='10U COED PLATINUM-8 TEAMS'!G22&"" -> B4-LAMORINDA GOLD (B) | H42: ='10U COED PLATINUM-8 TEAMS'!H22&"" -> 6 | I42: ='10U COED PLATINUM-8 TEAMS'!I22&"" -> bracket, B3/B4 | J42: ='10U COED PLATINUM-8 TEAMS'!J22&"" -> 10U_COED_PLATINUM | K42: =TEXT(DATE(2026, MONTH(A42), DAY(A42)) + TIME(HOUR(B42), MINUTE(B42), 0), "yyyymmddhhmm") -> 202602010930
