Workbook

Sheet TEAM LISTING AND BRACKETS
A1: DIVISION | B1: TEAM
A2: 10U_BOYS_&_COED_PLATINUM | B2: 2 SET MEDALS | D2: A coed pt 1st-3rd | E2: B boys 1st-4th
A3: 10U_BOYS | B3: CDM BLUE | D3: A1-NORTH IRVINE BLACK | E3: B1-ORWP A
A4: 10U_BOYS | B4: NEWPORT BEACH WHITE | D4: A2-SAN DIEGO DONS BLACK | E4: B2-CDM BLUE
A5: 10U_BOYS | B5: ORWP A | D5: A3-VIKING | E5: B3-SAN CLEMENTE RED
A6: 10U_BOYS | B6: SAN CLEMENTE RED | E6: B4-NEWPORT BEACH WHITE
A7: 10U_COED_PLATINUM | B7: NORTH IRVINE BLACK
A8: 10U_COED_PLATINUM | B8: SAN DIEGO DONS BLACK
A9: 10U_COED_PLATINUM | B9: VIKING | C9: 7
A11: 10U_GIRLS_COED_GOLD_SILVER | B11: RR for 1st-4th then cross no re-play | D11: A gold 1st-4th
A12: 10U_COED_GOLD | B12: ORANGE COUNTY WPC B au | D12: A1-TROJAN SOUTH au
A13: 10U_COED_GOLD | B13: SAN CLEMENTE BLACK au | D13: A2-VANGUARD BLUE au
A14: 10U_COED_GOLD | B14: TROJAN SOUTH au | D14: A3-SAN CLEMENTE BLACK au
A15: 10U_COED_GOLD | B15: VANGUARD BLUE au | C15: 4 | D15: A4-ORANGE COUNTY WPC B au
B17: RR for 1st-4th then cross no re-play | D17: B silver 1st-4th
A18: 10U_COED_SILVER | B18: CDM BOYS WHITE ag | D18: B1-SAN CLEMENTE GIRLS RED ag
A19: 10U_COED_SILVER | B19: LAGUNA BEACH ag | D19: B2-CDM BOYS WHITE ag | M19: =#REF! -> #REF! | N19: =#REF! -> #REF!
A20: 10U_COED_SILVER | B20: SAN CLEMENTE GIRLS RED ag | D20: B3-LAGUNA BEACH ag | M20: =#REF! -> #REF! | N20: =#REF! -> #REF!
A21: 10U_COED_SILVER | B21: TROJAN NORTH ag | C21: 4 | D21: B4-TROJAN NORTH ag
B23: No Intra-club play, then cross | D23: C GIrls 1st-4th
A24: 10U_GIRLS | B24: DEL MAR GIRLS BLUE | D24: C1-DEL MAR GIRLS BLUE
A25: 10U_GIRLS | B25: DEL MAR GIRLS WHITE | D25: C2-NEWPORT BEACH GIRLS BLUE
A26: 10U_GIRLS | B26: NEWPORT BEACH GIRLS BLUE | D26: C3-DEL MAR GIRLS WHITE
A27: 10U_GIRLS | B27: NEWPORT BEACH GIRLS WHITE | D27: C4-NEWPORT BEACH GIRLS WHITE | M27: =#REF! -> #REF! | N27: =#REF! -> #REF!
C28: 4
M29: =#REF! -> #REF! | N29: =#REF! -> #REF!
A30: 12U_BOYS | B30: 3 SET MEDALS | M30: =#REF! -> #REF! | N30: =#REF! -> #REF!
A31: 12U_BOYS_SILVER | B31: CDM ag | M31: =#REF! -> #REF! | N31: =#REF! -> #REF!
A32: 12U_BOYS_SILVER | B32: ORANGE COUNTY WPC B ag | M32: =#REF! -> #REF! | N32: =#REF! -> #REF!
A33: 12U_BOYS_SILVER | B33: ORWP B ag | D33: A pt 1st-3rd | E33: B au | F33: C au | G33: D au | H33: E ag 1st-3rd
D34: A1-LA PREMIER | E34: B1-TROJAN | F34: C1-LAWPC | G34: D1-PEGASUS WPA BLUE | H34: E1-CDM
D35: A2-ORANGE COUNTY WPC A | E35: B2-ROUTE 66 | F35: C2-MISSION B | G35: D2-VANGUARD SILVER | H35: E2-ORWP B
A36: 12U_BOYS_GOLD | B36: LAGUNA BEACH au | D36: A3-CMAC | E36: B3-LAGUNA BEACH | F36: C3-NORTH IRVINE RED | G36: D3-SAN DIEGO DONS 10 RED | H36: E3-ORANGE COUNTY WPC B
A37: 12U_BOYS_GOLD | B37: LAWPC au | G37: D4-NEWPORT BEACH 10 BLUE
A38: 12U_BOYS_GOLD | B38: MISSION B au | H38: Day 2 crosses
A39: 12U_BOYS_GOLD | B39: NEWPORT BEACH 10 BLUE au
A40: 12U_BOYS_GOLD | B40: NORTH IRVINE RED au | H40: =D43 -> 2ndA- | I40: =G43 -> 3rdD-
A41: 12U_BOYS_GOLD | B41: PEGASUS WPA BLUE au | E41: F au 1st-3rd | F41: G au 4th-6th | G41: 3rdB- | H41: =D47 -> 2ndE- | I41: =G44 -> 4thD-
A42: 12U_BOYS_GOLD | B42: ROUTE 66 au | D42: 1stA- | E42: F1(1stB)- | F42: G1(2ndB)- | G42: 3rdC- | H42: =D42 -> 1stA- | I42: =G41 -> 3rdB-
A43: 12U_BOYS_GOLD | B43: SAN DIEGO DONS 10 RED au | D43: 2ndA- | E43: F2(1stC)- | F43: G2(2ndC)- | G43: 3rdD- | H43: =D43 -> 2ndA- | I43: =D46 -> 1stE-
...

Sheet CHICLETS MASTER
B1: 2026 TURBO OC CUP
B2: CHICLETS MASTER | C2: 10U | D2: 10U | G2: 12U | H2: 12U | I2: 12U | T2: start at 11AM
B3: SATURDAY, MARCH 7 | C3: WOOLLETT FAR LEFT | D3: EL TORO HS 2 | G3: WOOLLETT FAR RIGHT | H3: LAGUNA HILLS HS | I3: COSTA MESA HS 2 | L3: WOOLLETT NEAR LEFT | M3: ESTANCIA HS 1 | N3: COSTA MESA HS 1 | O3: WOOLLETT NEAR RIGHT | R3: EL TORO HS 1 | S3: SAN JUAN HILLS HS | T3: ALISO NIGUEL HS | U3: WESTMINSTER HS | V3: ESTANCIA HS 2 | Y3: =COUNTA(C3:X3) -> 14
F4: 0.29166667 | K4: 0.29166667 | L4: ='19U BOYS PLATINUM GOLD-11 TEAMS'!D12&"-"&'19U BOYS PLATINUM GOLD-11 TEAMS'!I12&"-"&TEXT('19U BOYS PLATINUM GOLD-11 TEAMS'!B12,"h:mm am/pm") -> 19Bptau01-W/L C1/C4-7:00 AM | O4: ='16U BOYS PLATINUM GOLD-10 TEAMS'!D10&"-"&'16U BOYS PLATINUM GOLD-10 TEAMS'!I10&"-"&TEXT('16U BOYS PLATINUM GOLD-10 TEAMS'!B10,"h:mm am/pm") -> 16Bptau01-A bracket A1,A2 platinum 1st-3rd-7:00 AM | Q4: 0.29166667 | R4: ='14U GIRLS-9 TEAMS'!D14&"-"&'14U GIRLS-9 TEAMS'!I22&"-"&TEXT('14U GIRLS-9 TEAMS'!B14,"h:mm am/pm") -> 14G01-C bracket silver 1st-3rd-7:00 AM
B5: 0.33333333 | C5: ='10U BOYS & COED PT-7 CUSTOM'!D10&"-"&'10U BOYS & COED PT-7 CUSTOM'!I10&"-"&TEXT('10U BOYS & COED PT-7 CUSTOM'!B10,"h:mm am/pm") -> 10BCpt01-A bracket A1,A3 Cpt 1st-3rd-8:00 AM | D5: ='10U GIRLS COED AU AG-12 TEAMS'!D10&"-"&'10U GIRLS COED AU AG-12 TEAMS'!I10&"-"&TEXT('10U GIRLS COED AU AG-12 TEAMS'!B10,"h:mm am/pm") -> 10GCauag01-B bracket, B1/B4 coed silver 1st-4th-8:00 AM | F5: 0.32638889 | I5: ='12U BOYS-16 TEAMS'!D21&"-"&'12U BOYS-16 TEAMS'!I21&"-"&TEXT('12U BOYS-16 TEAMS'!B21,"h:mm am/pm") -> 12B01-A bracket A1,A3 platinum 1st-3rd-7:50 AM | K5: 0.33333333 | L5: ='19U BOYS PLATINUM GOLD-11 TEAMS'!D13&"-"&'19U BOYS PLATINUM GOLD-11 TEAMS'!I13&"-"&TEXT('19U BOYS PLATINUM GOLD-11 TEAMS'!B13,"h:mm am/pm") -> 19Bptau02-W/L C2/C3-8:00 AM | M5: ='19U BOYS SILVER-5 TEAMS'!D11&"-"&'19U BOYS SILVER-5 TEAMS'!I11&"-"&TEXT('19U BOYS SILVER-5 TEAMS'!B11,"h:mm am/pm") -> 19Bag01-A bracket 2/5-8:00 AM | N5: ='16U BOYS SILVER-8 TEAMS'!D10&"-"&'16U BOYS SILVER-8 TEAMS'!I10&"-"&TEXT('16U BOYS SILVER-8 TEAMS'!B10,"h:mm am/pm") -> 16Bag01-bracket, B1/B4-8:00 AM | O5: ='16U BOYS PLATINUM GOLD-10 TEAMS'!D11&"-"&'16U BOYS PLATINUM GOLD-10 TEAMS'!I11&"-"&TEXT('16U BOYS PLATINUM GOLD-10 TEAMS'!B11,"h:mm am/pm") -> 16Bptau02-B bracket B1,B2-8:00 AM | Q5: 0.32638889 | R5: ='14U GIRLS-9 TEAMS'!D15&"-"&'14U GIRLS-9 TEAMS'!I15&"-"&TEXT('14U GIRLS-9 TEAMS'!B15,"h:mm am/pm") -> 14G02-B bracket gold 1st-3rd-7:50 AM | S5: ='14U BOYS GOLD-16 TEAMS'!D10&"-"&'14U BOYS GOLD-16 TEAMS'!I10&"-"&TEXT('14U BOYS GOLD-16 TEAMS'!B10,"h:mm am/pm") -> 14Bau01-W/L A2/A3-7:50 AM | U5: ='14U BOYS PLATINUM-10 TEAMS'!D10&"-"&'14U BOYS PLATINUM-10 TEAMS'!I10&"-"&TEXT('14U BOYS PLATINUM-10 TEAMS'!B10,"h:mm am/pm") -> 14Bpt01-C bracket C1,C4-7:50 AM | V5: ='14U BOYS SILVER-16 TEAMS'!D10&"-"&'14U BOYS SILVER-16 TEAMS'!I10&"-"&TEXT('14U BOYS SILVER-16 TEAMS'!B10,"h:mm am/pm") -> 14Bag01-W/L A2/A3-7:50 AM
B6: 0.36805556 | C6: ='10U BOYS & COED PT-7 CUSTOM'!D11&"-"&'10U BOYS & COED PT-7 CUSTOM'!I11&"-"&TEXT('10U BOYS & COED PT-7 CUSTOM'!B11,"h:mm am/pm") -> 10BCpt02-A bracket A2,A3 Cpt 1st-3rd-8:50 AM | D6: ='10U GIRLS COED AU AG-12 TEAMS'!D11&"-"&'10U GIRLS COED AU AG-12 TEAMS'!I11&"-"&TEXT('10U GIRLS COED AU AG-12 TEAMS'!B11,"h:mm am/pm") -> 10GCauag02-B bracket, B2/B3 coed silver 1st-4th-8:50 AM | F6: 0.36111111 | G6: ='12U BOYS-16 TEAMS'!D31&"-"&'12U BOYS-16 TEAMS'!I31&"-"&TEXT('12U BOYS-16 TEAMS'!B31,"h:mm am/pm") -> 12B10-C bracket C1,C3-8:40 AM | H6: ='12U COED GIRLS-9 TEAMS CUSTOM'!D14&"-"&'12U COED GIRLS-9 TEAMS CUSTOM'!I14&"-"&TEXT('12U COED GIRLS-9 TEAMS CUSTOM'!B14,"h:mm am/pm") -> 12GC01-A bracket A1,A3-8:40 AM | I6: ='12U BOYS-16 TEAMS'!D22&"-"&'12U BOYS-16 TEAMS'!I22&"-"&TEXT('12U BOYS-16 TEAMS'!B22,"h:mm am/pm") -> 12B02-B bracket B1,B3-8:40 AM | K6: 0.375 | L6: ='19U BOYS PLATINUM GOLD-11 TEAMS'!D14&"-"&'19U BOYS PLATINUM GOLD-11 TEAMS'!I14&"-"&TEXT('19U BOYS PLATINUM GOLD-11 TEAMS'!B14,"h:mm am/pm") -> 19Bptau03-A bracket A1,A3-9:00 AM | M6: ='19U BOYS SILVER-5 TEAMS'!D12&"-"&'19U BOYS SILVER-5 TEAMS'!I12&"-"&TEXT('19U BOYS SILVER-5 TEAMS'!B12,"h:mm am/pm") -> 19Bag02-A bracket 1/3-9:00 AM | N6: ='16U BOYS SILVER-8 TEAMS'!D11&"-"&'16U BOYS SILVER-8 TEAMS'!I11&"-"&TEXT('16U BOYS SILVER-8 TEAMS'!B11,"h:mm am/pm") -> 16Bag02-bracket, B2/B3-9:00 AM | O6: ='16U BOYS PLATINUM GOLD-10 TEAMS'!D12&"-"&'16U BOYS PLATINUM GOLD-10 TEAMS'!I12&"-"&TEXT('16U BOYS PLATINUM GOLD-10 TEAMS'!B12,"h:mm am/pm") -> 16Bptau03-C bracket C1,C4-9:00 AM | Q6: 0.36111111 | R6: ='14U GIRLS-9 TEAMS'!D16&"-"&'14U GIRLS-9 TEAMS'!I16&"-"&TEXT('14U GIRLS-9 TEAMS'!B16,"h:mm am/pm") -> 14G03-A bracket platinum 1st-3rd-8:40 AM | S6: ='14U BOYS GOLD-16 TEAMS'!D11&"-"&'14U BOYS GOLD-16 TEAMS'!I11&"-"&TEXT('14U BOYS GOLD-16 TEAMS'!B11,"h:mm am/pm") -> 14Bau02-W/L A1/A4-8:40 AM | U6: ='14U BOYS PLATINUM-10 TEAMS'!D11&"-"&'14U BOYS PLATINUM-10 TEAMS'!I11&"-"&TEXT('14U BOYS PLATINUM-10 TEAMS'!B11,"h:mm am/pm") -> 14Bpt02-A bracket A1,A3-8:40 AM | V6: ='14U BOYS SILVER-16 TEAMS'!D11&"-"&'14U BOYS SILVER-16 TEAMS'!I11&"-"&TEXT('14U BOYS SILVER-16 TEAMS'!B11,"h:mm am/pm") -> 14Bag02-W/L A1/A4-8:40 AM
A7: 2R | B7: 0.40277778 | C7: ='10U GIRLS COED AU AG-12 TEAMS'!D13&"-"&'10U GIRLS COED AU AG-12 TEAMS'!I13&"-"&TEXT('10U GIRLS COED AU AG-12 TEAMS'!B13,"h:mm am/pm") -> 10GCauag05-C bracket C1,C4 Girls 1st-4th-9:40 AM | D7: ='10U GIRLS COED AU AG-12 TEAMS'!D12&"-"&'10U GIRLS COED AU AG-12 TEAMS'!I12&"-"&TEXT('10U GIRLS COED AU AG-12 TEAMS'!B12,"h:mm am/pm") -> 10GCauag03-A bracket, A1/A4 coed gold 1st-4th-9:40 AM | F7: 0.39583333 | G7: ='12U BOYS-16 TEAMS'!D32&"-"&'12U BOYS-16 TEAMS'!I32&"-"&TEXT('12U BOYS-16 TEAMS'!B32,"h:mm am/pm") -> 12B11-W/L D1/D4-9:30 AM | H7: ='12U COED GIRLS-9 TEAMS CUSTOM'!D15&"-"&'12U COED GIRLS-9 TEAMS CUSTOM'!I15&"-"&TEXT('12U COED GIRLS-9 TEAMS CUSTOM'!B15,"h:mm am/pm") -> 12GC02-B bracket B1,B3-9:30 AM | I7: ='12U BOYS-16 TEAMS'!D23&"-"&'12U BOYS-16 TEAMS'!I23&"-"&TEXT('12U BOYS-16 TEAMS'!B23,"h:mm am/pm") -> 12B03-E bracket E1,E3 silver 1st-3rd-9:30 AM | K7: 0.41666667 | L7: ='19U BOYS PLATINUM GOLD-11 TEAMS'!D15&"-"&'19U BOYS PLATINUM GOLD-11 TEAMS'!I15&"-"&TEXT('19U BOYS PLATINUM GOLD-11 TEAMS'!B15,"h:mm am/pm") -> 19Bptau04-W/L B1/B4-10:00 AM | M7: ='19U BOYS PLATINUM GOLD-11 TEAMS'!D16&"-"&'19U BOYS PLATINUM GOLD-11 TEAMS'!I16&"-"&TEXT('19U BOYS PLATINUM GOLD-11 TEAMS'!B16,"h:mm am/pm") -> 19Bptau05-W/L B2/B3-10:00 AM | N7: ='16U BOYS SILVER-8 TEAMS'!D12&"-"&'16U BOYS SILVER-8 TEAMS'!I12&"-"&TEXT('16U BOYS SILVER-8 TEAMS'!B12,"h:mm am/pm") -> 16Bag03-bracket, A2/A3-10:00 AM | O7: ='16U BOYS PLATINUM GOLD-10 TEAMS'!D13&"-"&'16U BOYS PLATINUM GOLD-10 TEAMS'!I13&"-"&TEXT('16U BOYS PLATINUM GOLD-10 TEAMS'!B13,"h:mm am/pm") -> 16Bptau04-C bracket C2,C3-10:00 AM | Q7: 0.39583333 | R7: ='14U BOYS SILVER-16 TEAMS'!D13&"-"&'14U BOYS SILVER-16 TEAMS'!I13&"-"&TEXT('14U BOYS SILVER-16 TEAMS'!B13,"h:mm am/pm") -> 14Bag09-W/L D1/D4-9:30 AM | S7: ='14U BOYS GOLD-16 TEAMS'!D12&"-"&'14U BOYS GOLD-16 TEAMS'!I12&"-"&TEXT('14U BOYS GOLD-16 TEAMS'!B12,"h:mm am/pm") -> 14Bau03-W/L C2/C3-9:30 AM | U7: ='14U BOYS PLATINUM-10 TEAMS'!D12&"-"&'14U BOYS PLATINUM-10 TEAMS'!I12&"-"&TEXT('14U BOYS PLATINUM-10 TEAMS'!B12,"h:mm am/pm") -> 14Bpt03-B bracket B1,B3-9:30 AM | V7: ='14U BOYS SILVER-16 TEAMS'!D12&"-"&'14U BOYS SILVER-16 TEAMS'!I12&"-"&TEXT('14U BOYS SILVER-16 TEAMS'!B12,"h:mm am/pm") -> 14Bag03-W/L C2/C3-9:30 AM
A8: 2R | B8: 0.4375 | C8: ='10U GIRLS COED AU AG-12 TEAMS'!D15&"-"&'10U GIRLS COED AU AG-12 TEAMS'!I15&"-"&TEXT('10U GIRLS COED AU AG-12 TEAMS'!B15,"h:mm am/pm") -> 10GCauag06-C bracket C2,C3 Girls 1st-4th-10:30 AM | D8: ='10U GIRLS COED AU AG-12 TEAMS'!D14&"-"&'10U GIRLS COED AU AG-12 TEAMS'!I14&"-"&TEXT('10U GIRLS COED AU AG-12 TEAMS'!B14,"h:mm am/pm") -> 10GCauag04-A bracket, A2/A3 coed gold 1st-4th-10:30 AM | F8: 0.43055556 | G8: ='12U BOYS-16 TEAMS'!D33&"-"&'12U BOYS-16 TEAMS'!I33&"-"&TEXT('12U BOYS-16 TEAMS'!B33,"h:mm am/pm") -> 12B12-W/L D2/D3-10:20 AM | H8: ='12U COED GIRLS-9 TEAMS CUSTOM'!D16&"-"&'12U COED GIRLS-9 TEAMS CUSTOM'!I16&"-"&TEXT('12U COED GIRLS-9 TEAMS CUSTOM'!B16,"h:mm am/pm") -> 12GC03-C bracket C1,C3-10:20 AM | I8: ='12U BOYS-16 TEAMS'!D24&"-"&'12U BOYS-16 TEAMS'!I24&"-"&TEXT('12U BOYS-16 TEAMS'!B24,"h:mm am/pm") -> 12B04-A bracket A2,A3 platinum 1st-3rd-10:20 AM | K8: 0.45833333 | L8: ='19U BOYS PLATINUM GOLD-11 TEAMS'!D17&"-"&'19U BOYS PLATINUM GOLD-11 TEAMS'!I17&"-"&TEXT('19U BOYS PLATINUM GOLD-11 TEAMS'!B17,"h:mm am/pm") -> 19Bptau06-A bracket A2,A3-11:00 AM | M8: ='19U BOYS SILVER-5 TEAMS'!D14&"-"&'19U BOYS SILVER-5 TEAMS'!I14&"-"&TEXT('19U BOYS SILVER-5 TEAMS'!B14,"h:mm am/pm") -> 19Bag03-A bracket 2/4-11:00 AM | N8: ='16U BOYS SILVER-8 TEAMS'!D13&"-"&'16U BOYS SILVER-8 TEAMS'!I13&"-"&TEXT('16U BOYS SILVER-8 TEAMS'!B13,"h:mm am/pm") -> 16Bag04-bracket, A1/A4-11:00 AM | O8: ='16U BOYS PLATINUM GOLD-10 TEAMS'!D14&"-"&'16U BOYS PLATINUM GOLD-10 TEAMS'!I14&"-"&TEXT('16U BOYS PLATINUM GOLD-10 TEAMS'!B14,"h:mm am/pm") -> 16Bptau05-A bracket A2,A3 platinum 1st-3rd-11:00 AM | Q8: 0.43055556 | R8: ='14U BOYS SILVER-16 TEAMS'!D14&"-"&'14U BOYS SILVER-16 TEAMS'!I14&"-"&TEXT('14U BOYS SILVER-16 TEAMS'!B14,"h:mm am/pm") -> 14Bag10-W/L D2/D3-10:20 AM | S8: ='14U BOYS GOLD-16 TEAMS'!D13&"-"&'14U BOYS GOLD-16 TEAMS'!I13&"-"&TEXT('14U BOYS GOLD-16 TEAMS'!B13,"h:mm am/pm") -> 14Bau04-W/L C1/C4-10:20 AM | U8: ='14U BOYS PLATINUM-10 TEAMS'!D13&"-"&'14U BOYS PLATINUM-10 TEAMS'!I13&"-"&TEXT('14U BOYS PLATINUM-10 TEAMS'!B13,"h:mm am/pm") -> 14Bpt04-C bracket C1,C2-10:20 AM | V8: ='14U BOYS SILVER-16 TEAMS'!D15&"-"&'14U BOYS SILVER-16 TEAMS'!I15&"-"&TEXT('14U BOYS SILVER-16 TEAMS'!B15,"h:mm am/pm") -> 14Bag04-W/L C1/C4-10:20 AM
B9: 0.47222222 | C9: ='10U BOYS & COED PT-7 CUSTOM'!D13&"-"&'10U BOYS & COED PT-7 CUSTOM'!I13&"-"&TEXT('10U BOYS & COED PT-7 CUSTOM'!B13,"h:mm am/pm") -> 10BCpt03-B bracket B1,B4 Boys 1st-4th-11:20 AM | D9: ='10U GIRLS COED AU AG-12 TEAMS'!D16&"-"&'10U GIRLS COED AU AG-12 TEAMS'!I16&"-"&TEXT('10U GIRLS COED AU AG-12 TEAMS'!B16,"h:mm am/pm") -> 10GCauag07-B bracket, B2/B4 coed silver 1st-4th-11:20 AM | F9: 0.46527778 | G9: ='12U BOYS-16 TEAMS'!D34&"-"&'12U BOYS-16 TEAMS'!I34&"-"&TEXT('12U BOYS-16 TEAMS'!B34,"h:mm am/pm") -> 12B13-C bracket C2,C3-11:10 AM | H9: ='12U COED GIRLS-9 TEAMS CUSTOM'!D17&"-"&'12U COED GIRLS-9 TEAMS CUSTOM'!I17&"-"&TEXT('12U COED GIRLS-9 TEAMS CUSTOM'!B17,"h:mm am/pm") -> 12GC04-A bracket A2,A3-11:10 AM | I9: ='12U BOYS-16 TEAMS'!D25&"-"&'12U BOYS-16 TEAMS'!I25&"-"&TEXT('12U BOYS-16 TEAMS'!B25,"h:mm am/pm") -> 12B05-B bracket B2,B3-11:10 AM | K9: 0.5 | L9: ='19U BOYS PLATINUM GOLD-11 TEAMS'!D18&"-"&'19U BOYS PLATINUM GOLD-11 TEAMS'!I18&"-"&TEXT('19U BOYS PLATINUM GOLD-11 TEAMS'!B18,"h:mm am/pm") -> 19Bptau07-3rd/4thC-12:00 PM | M9: ='19U BOYS SILVER-5 TEAMS'!D15&"-"&'19U BOYS SILVER-5 TEAMS'!I15&"-"&TEXT('19U BOYS SILVER-5 TEAMS'!B15,"h:mm am/pm") -> 19Bag04-A bracket 3/5-12:00 PM | N9: ='16U BOYS SILVER-8 TEAMS'!D14&"-"&'16U BOYS SILVER-8 TEAMS'!I14&"-"&TEXT('16U BOYS SILVER-8 TEAMS'!B14,"h:mm am/pm") -> 16Bag05-bracket, B1/B3-12:00 PM | O9: ='16U BOYS PLATINUM GOLD-10 TEAMS'!D15&"-"&'16U BOYS PLATINUM GOLD-10 TEAMS'!I15&"-"&TEXT('16U BOYS PLATINUM GOLD-10 TEAMS'!B15,"h:mm am/pm") -> 16Bptau06-B bracket B2,B3-12:00 PM | Q9: 0.46527778 | R9: ='14U GIRLS-9 TEAMS'!D18&"-"&'14U GIRLS-9 TEAMS'!I18&"-"&TEXT('14U GIRLS-9 TEAMS'!B18,"h:mm am/pm") -> 14G04-C bracket silver 1st-3rd-11:10 AM | S9: ='14U BOYS GOLD-16 TEAMS'!D14&"-"&'14U BOYS GOLD-16 TEAMS'!I14&"-"&TEXT('14U BOYS GOLD-16 TEAMS'!B14,"h:mm am/pm") -> 14Bau05-W/L D1/D4-11:10 AM | T9: ='14U BOYS GOLD-16 TEAMS'!D15&"-"&'14U BOYS GOLD-16 TEAMS'!I15&"-"&TEXT('14U BOYS GOLD-16 TEAMS'!B15,"h:mm am/pm") -> 14Bau07-W/L B2/B3-11:10 AM | U9: ='14U BOYS PLATINUM-10 TEAMS'!D14&"-"&'14U BOYS PLATINUM-10 TEAMS'!I14&"-"&TEXT('14U BOYS PLATINUM-10 TEAMS'!B14,"h:mm am/pm") -> 14Bpt05-A bracket A2,A3-11:10 AM | V9: ='14U BOYS SILVER-16 TEAMS'!D16&"-"&'14U BOYS SILVER-16 TEAMS'!I16&"-"&TEXT('14U BOYS SILVER-16 TEAMS'!B16,"h:mm am/pm") -> 14Bag05-3rd/4thA-11:10 AM
B10: 0.50694444 | C10: ='10U BOYS & COED PT-7 CUSTOM'!D14&"-"&'10U BOYS & COED PT-7 CUSTOM'!I14&"-"&TEXT('10U BOYS & COED PT-7 CUSTOM'!B14,"h:mm am/pm") -> 10BCpt04-B bracket B2,B3 Boys 1st-4th-12:10 PM | D10: ='10U GIRLS COED AU AG-12 TEAMS'!D17&"-"&'10U GIRLS COED AU AG-12 TEAMS'!I17&"-"&TEXT('10U GIRLS COED AU AG-12 TEAMS'!B17,"h:mm am/pm") -> 10GCauag08-B bracket, B1/B3 coed silver 1st-4th-12:10 PM | F10: 0.5 | G10: ='12U BOYS-16 TEAMS'!D35&"-"&'12U BOYS-16 TEAMS'!I35&"-"&TEXT('12U BOYS-16 TEAMS'!B35,"h:mm am/pm") -> 12B14-3rd/4thD-12:00 PM | H10: ='12U COED GIRLS-9 TEAMS CUSTOM'!D18&"-"&'12U COED GIRLS-9 TEAMS CUSTOM'!I18&"-"&TEXT('12U COED GIRLS-9 TEAMS CUSTOM'!B18,"h:mm am/pm") -> 12GC05-B bracket B2,B3-12:00 PM | I10: ='12U BOYS-16 TEAMS'!D26&"-"&'12U BOYS-16 TEAMS'!I26&"-"&TEXT('12U BOYS-16 TEAMS'!B26,"h:mm am/pm") -> 12B06-E bracket E2,E3 silver 1st-3rd-12:00 PM | K10: 0.54166667 | L10: ='19U BOYS PLATINUM GOLD-11 TEAMS'!D19&"-"&'19U BOYS PLATINUM GOLD-11 TEAMS'!I19&"-"&TEXT('19U BOYS PLATINUM GOLD-11 TEAMS'!B19,"h:mm am/pm") -> 19Bptau08-1st/2ndC-1:00 PM | M10: ='19U BOYS PLATINUM GOLD-11 TEAMS'!D20&"-"&'19U BOYS PLATINUM GOLD-11 TEAMS'!I20&"-"&TEXT('19U BOYS PLATINUM GOLD-11 TEAMS'!B20,"h:mm am/pm") -> 19Bptau10-3rd/4thB-1:00 PM | N10: ='16U BOYS SILVER-8 TEAMS'!D15&"-"&'16U BOYS SILVER-8 TEAMS'!I15&"-"&TEXT('16U BOYS SILVER-8 TEAMS'!B15,"h:mm am/pm") -> 16Bag06-bracket, B2/B4-1:00 PM | O10: ='16U BOYS PLATINUM GOLD-10 TEAMS'!D16&"-"&'16U BOYS PLATINUM GOLD-10 TEAMS'!I16&"-"&TEXT('16U BOYS PLATINUM GOLD-10 TEAMS'!B16,"h:mm am/pm") -> 16Bptau07-C bracket C1,C2-1:00 PM | Q10: 0.5 | R10: ='14U GIRLS-9 TEAMS'!D19&"-"&'14U GIRLS-9 TEAMS'!I19&"-"&TEXT('14U GIRLS-9 TEAMS'!B19,"h:mm am/pm") -> 14G05-B bracket gold 1st-3rd-12:00 PM | S10: ='14U BOYS GOLD-16 TEAMS'!D16&"-"&'14U BOYS GOLD-16 TEAMS'!I16&"-"&TEXT('14U BOYS GOLD-16 TEAMS'!B16,"h:mm am/pm") -> 14Bau06-W/L D2/D3-12:00 PM | T10: ='14U BOYS GOLD-16 TEAMS'!D17&"-"&'14U BOYS GOLD-16 TEAMS'!I17&"-"&TEXT('14U BOYS GOLD-16 TEAMS'!B17,"h:mm am/pm") -> 14Bau08-W/L B1/B4-12:00 PM | U10: ='14U BOYS PLATINUM-10 TEAMS'!D15&"-"&'14U BOYS PLATINUM-10 TEAMS'!I15&"-"&TEXT('14U BOYS PLATINUM-10 TEAMS'!B15,"h:mm am/pm") -> 14Bpt06-B bracket B2,B3-12:00 PM | V10: ='14U BOYS SILVER-16 TEAMS'!D17&"-"&'14U BOYS SILVER-16 TEAMS'!I17&"-"&TEXT('14U BOYS SILVER-16 TEAMS'!B17,"h:mm am/pm") -> 14Bag06-1st/2ndA-12:00 PM
A11: 2R | B11: 0.54166667 | C11: ='10U GIRLS COED AU AG-12 TEAMS'!D19&"-"&'10U GIRLS COED AU AG-12 TEAMS'!I19&"-"&TEXT('10U GIRLS COED AU AG-12 TEAMS'!B19,"h:mm am/pm") -> 10GCauag11-C bracket C1,C2 Girls 1st-4th-1:00 PM | D11: ='10U GIRLS COED AU AG-12 TEAMS'!D18&"-"&'10U GIRLS COED AU AG-12 TEAMS'!I18&"-"&TEXT('10U GIRLS COED AU AG-12 TEAMS'!B18,"h:mm am/pm") -> 10GCauag09-A bracket, A1/A3 coed gold 1st-4th-1:00 PM | F11: 0.53472222 | G11: ='12U BOYS-16 TEAMS'!D36&"-"&'12U BOYS-16 TEAMS'!I36&"-"&TEXT('12U BOYS-16 TEAMS'!B36,"h:mm am/pm") -> 12B15-1st/2ndD-12:50 PM | H11: ='12U COED GIRLS-9 TEAMS CUSTOM'!D19&"-"&'12U COED GIRLS-9 TEAMS CUSTOM'!I19&"-"&TEXT('12U COED GIRLS-9 TEAMS CUSTOM'!B19,"h:mm am/pm") -> 12GC06-C bracket B2,B4 12U GIRLS 1st/2nd-12:50 PM | I11: ='12U BOYS-16 TEAMS'!D27&"-"&'12U BOYS-16 TEAMS'!I27&"-"&TEXT('12U BOYS-16 TEAMS'!B27,"h:mm am/pm") -> 12B07-A bracket A1,A2 platinum 1st-3rd-12:50 PM | K11: 0.58333333 | L11: ='19U BOYS PLATINUM GOLD-11 TEAMS'!D21&"-"&'19U BOYS PLATINUM GOLD-11 TEAMS'!I21&"-"&TEXT('19U BOYS PLATINUM GOLD-11 TEAMS'!B21,"h:mm am/pm") -> 19Bptau09-A bracket A1,A2-2:00 PM | M11: ='19U BOYS SILVER-5 TEAMS'!D17&"-"&'19U BOYS SILVER-5 TEAMS'!I17&"-"&TEXT('19U BOYS SILVER-5 TEAMS'!B17,"h:mm am/pm") -> 19Bag05-A bracket 1/4-2:00 PM | N11: ='16U BOYS SILVER-8 TEAMS'!D16&"-"&'16U BOYS SILVER-8 TEAMS'!I16&"-"&TEXT('16U BOYS SILVER-8 TEAMS'!B16,"h:mm am/pm") -> 16Bag07-bracket, A2/A4-2:00 PM | O11: ='16U BOYS PLATINUM GOLD-10 TEAMS'!D17&"-"&'16U BOYS PLATINUM GOLD-10 TEAMS'!I17&"-"&TEXT('16U BOYS PLATINUM GOLD-10 TEAMS'!B17,"h:mm am/pm") -> 16Bptau08-C bracket C3,C4-2:00 PM | Q11: 0.53472222 | R11: ='14U GIRLS-9 TEAMS'!D20&"-"&'14U GIRLS-9 TEAMS'!I20&"-"&TEXT('14U GIRLS-9 TEAMS'!B20,"h:mm am/pm") -> 14G06-A bracket platinum 1st-3rd-12:50 PM | S11: ='14U BOYS GOLD-16 TEAMS'!D19&"-"&'14U BOYS GOLD-16 TEAMS'!I19&"-"&TEXT('14U BOYS GOLD-16 TEAMS'!B19,"h:mm am/pm") -> 14Bau11-3rd/4thC-12:50 PM | T11: ='14U BOYS GOLD-16 TEAMS'!D18&"-"&'14U BOYS GOLD-16 TEAMS'!I18&"-"&TEXT('14U BOYS GOLD-16 TEAMS'!B18,"h:mm am/pm") -> 14Bau09-3rd/4thA (7-1 LAWP)-12:50 PM | U11: ='14U BOYS PLATINUM-10 TEAMS'!D16&"-"&'14U BOYS PLATINUM-10 TEAMS'!I16&"-"&TEXT('14U BOYS PLATINUM-10 TEAMS'!B16,"h:mm am/pm") -> 14Bpt07-C bracket C3,C4-12:50 PM | V11: ='14U BOYS SILVER-16 TEAMS'!D18&"-"&'14U BOYS SILVER-16 TEAMS'!I18&"-"&TEXT('14U BOYS SILVER-16 TEAMS'!B18,"h:mm am/pm") -> 14Bag11-W/L B2/B3-12:50 PM
A12: 2R | B12: 0.57638889 | C12: ='10U GIRLS COED AU AG-12 TEAMS'!D21&"-"&'10U GIRLS COED AU AG-12 TEAMS'!I21&"-"&TEXT('10U GIRLS COED AU AG-12 TEAMS'!B21,"h:mm am/pm") -> 10GCauag12-C bracket C3,C4 Girls 1st-4th-1:50 PM | D12: ='10U GIRLS COED AU AG-12 TEAMS'!D20&"-"&'10U GIRLS COED AU AG-12 TEAMS'!I20&"-"&TEXT('10U GIRLS COED AU AG-12 TEAMS'!B20,"h:mm am/pm") -> 10GCauag10-A bracket, A2/A4 coed gold 1st-4th-1:50 PM | F12: 0.56944444 | G12: ='12U BOYS-16 TEAMS'!D37&"-"&'12U BOYS-16 TEAMS'!I37&"-"&TEXT('12U BOYS-16 TEAMS'!B37,"h:mm am/pm") -> 12B16-C bracket C1,C2-1:40 PM | H12: ='12U COED GIRLS-9 TEAMS CUSTOM'!D20&"-"&'12U COED GIRLS-9 TEAMS CUSTOM'!I20&"-"&TEXT('12U COED GIRLS-9 TEAMS CUSTOM'!B20,"h:mm am/pm") -> 12GC07-A bracket A1,A2-1:40 PM | I12: ='12U BOYS-16 TEAMS'!D28&"-"&'12U BOYS-16 TEAMS'!I28&"-"&TEXT('12U BOYS-16 TEAMS'!B28,"h:mm am/pm") -> 12B08-B bracket B1,B2-1:40 PM | K12: 0.625 | L12: ='19U BOYS PLATINUM GOLD-11 TEAMS'!D22&"-"&'19U BOYS PLATINUM GOLD-11 TEAMS'!I22&"-"&TEXT('19U BOYS PLATINUM GOLD-11 TEAMS'!B22,"h:mm am/pm") -> 19Bptau11-1st/2ndB-3:00 PM | M12: ='16U BOYS SILVER-8 TEAMS'!D17&"-"&'16U BOYS SILVER-8 TEAMS'!I17&"-"&TEXT('16U BOYS SILVER-8 TEAMS'!B17,"h:mm am/pm") -> 16Bag08-bracket, A1/A3-3:00 PM | N12: ='14U BOYS SILVER-16 TEAMS'!D23&"-"&'14U BOYS SILVER-16 TEAMS'!I23&"-"&TEXT('14U BOYS SILVER-16 TEAMS'!B23,"h:mm am/pm") -> 14Bag08-1st/2ndC-3:00 PM | O12: ='16U BOYS PLATINUM GOLD-10 TEAMS'!D18&"-"&'16U BOYS PLATINUM GOLD-10 TEAMS'!I18&"-"&TEXT('16U BOYS PLATINUM GOLD-10 TEAMS'!B18,"h:mm am/pm") -> 16Bptau09-A bracket A1,A3 platinum 1st-3rd-3:00 PM | Q12: 0.56944444 | R12: ='14U BOYS SILVER-16 TEAMS'!D20&"-"&'14U BOYS SILVER-16 TEAMS'!I20&"-"&TEXT('14U BOYS SILVER-16 TEAMS'!B20,"h:mm am/pm") -> 14Bag13-3rd/4thD-1:40 PM | S12: ='14U BOYS GOLD-16 TEAMS'!D21&"-"&'14U BOYS GOLD-16 TEAMS'!I21&"-"&TEXT('14U BOYS GOLD-16 TEAMS'!B21,"h:mm am/pm") -> 14Bau12-1st/2ndC-1:40 PM | T12: ='14U BOYS GOLD-16 TEAMS'!D20&"-"&'14U BOYS GOLD-16 TEAMS'!I20&"-"&TEXT('14U BOYS GOLD-16 TEAMS'!B20,"h:mm am/pm") -> 14Bau10-1st/2ndA-1:40 PM | U12: ='14U BOYS PLATINUM-10 TEAMS'!D17&"-"&'14U BOYS PLATINUM-10 TEAMS'!I17&"-"&TEXT('14U BOYS PLATINUM-10 TEAMS'!B17,"h:mm am/pm") -> 14Bpt08-A bracket A1,A2-1:40 PM | V12: ='14U BOYS SILVER-16 TEAMS'!D19&"-"&'14U BOYS SILVER-16 TEAMS'!I19&"-"&TEXT('14U BOYS SILVER-16 TEAMS'!B19,"h:mm am/pm") -> 14Bag12-W/L B1/B4-1:40 PM
B13: 0.61111111 | C13: ='10U BOYS & COED PT-7 CUSTOM'!D16&"-"&'10U BOYS & COED PT-7 CUSTOM'!I16&"-"&TEXT('10U BOYS & COED PT-7 CUSTOM'!B16,"h:mm am/pm") -> 10BCpt05-A bracket A1,A2 Cpt 1st-3rd-2:40 PM | D13: ='10U BOYS & COED PT-7 CUSTOM'!D17&"-"&'10U BOYS & COED PT-7 CUSTOM'!I17&"-"&TEXT('10U BOYS & COED PT-7 CUSTOM'!B17,"h:mm am/pm") -> 10BCpt06-B bracket B1,B3 Boys 1st-4th-2:40 PM | F13: 0.60416667 | I13: ='12U BOYS-16 TEAMS'!D29&"-"&'12U BOYS-16 TEAMS'!I29&"-"&TEXT('12U BOYS-16 TEAMS'!B29,"h:mm am/pm") -> 12B09-E bracket E1,E2 silver 1st-3rd-2:30 PM | K13: 0.66666667 | N13: ='14U BOYS SILVER-16 TEAMS'!D25&"-"&'14U BOYS SILVER-16 TEAMS'!I25&"-"&TEXT('14U BOYS SILVER-16 TEAMS'!B25,"h:mm am/pm") -> 14Bag16-1st/2ndB-3:50 PM | O13: ='16U BOYS PLATINUM GOLD-10 TEAMS'!D19&"-"&'16U BOYS PLATINUM GOLD-10 TEAMS'!I19&"-"&TEXT('16U BOYS PLATINUM GOLD-10 TEAMS'!B19,"h:mm am/pm") -> 16Bptau10-B bracket B1,B3-4:00 PM | Q13: 0.60416667 | R13: ='14U BOYS SILVER-16 TEAMS'!D22&"-"&'14U BOYS SILVER-16 TEAMS'!I22&"-"&TEXT('14U BOYS SILVER-16 TEAMS'!B22,"h:mm am/pm") -> 14Bag14-1st/2ndD-2:30 PM | S13: ='14U BOYS GOLD-16 TEAMS'!D22&"-"&'14U BOYS GOLD-16 TEAMS'!I22&"-"&TEXT('14U BOYS GOLD-16 TEAMS'!B22,"h:mm am/pm") -> 14Bau13-3rd/4thD-2:30 PM | T13: ='14U BOYS GOLD-16 TEAMS'!D23&"-"&'14U BOYS GOLD-16 TEAMS'!I23&"-"&TEXT('14U BOYS GOLD-16 TEAMS'!B23,"h:mm am/pm") -> 14Bau15-3rd/4thB-2:30 PM | U13: ='14U BOYS PLATINUM-10 TEAMS'!D18&"-"&'14U BOYS PLATINUM-10 TEAMS'!I18&"-"&TEXT('14U BOYS PLATINUM-10 TEAMS'!B18,"h:mm am/pm") -> 14Bpt09-B bracket B1,B2-2:30 PM | V13: ='14U BOYS SILVER-16 TEAMS'!D21&"-"&'14U BOYS SILVER-16 TEAMS'!I21&"-"&TEXT('14U BOYS SILVER-16 TEAMS'!B21,"h:mm am/pm") -> 14Bag07-3rd/4thC-2:30 PM
A14: 2R | B14: 0.64583333 | D14: ='10U BOYS & COED PT-7 CUSTOM'!D18&"-"&'10U BOYS & COED PT-7 CUSTOM'!I18&"-"&TEXT('10U BOYS & COED PT-7 CUSTOM'!B18,"h:mm am/pm") -> 10BCpt07-B bracket B2,B4 Boys 1st-4th-3:30 PM | F14: 0.64583333 | G14: ='12U COED GIRLS-9 TEAMS CUSTOM'!D22&"-"&'12U COED GIRLS-9 TEAMS CUSTOM'!I22&"-"&TEXT('12U COED GIRLS-9 TEAMS CUSTOM'!B22,"h:mm am/pm") -> 12GC08-B bracket B1,B2-3:30 PM | K14: 0.70833333 | Q14: 0.63888889 | R14: ='14U GIRLS-9 TEAMS'!D22&"-"&'14U GIRLS-9 TEAMS'!I14&"-"&TEXT('14U GIRLS-9 TEAMS'!B22,"h:mm am/pm") -> 14G07-C bracket silver 1st-3rd-3:20 PM | S14: ='14U BOYS GOLD-16 TEAMS'!D24&"-"&'14U BOYS GOLD-16 TEAMS'!I24&"-"&TEXT('14U BOYS GOLD-16 TEAMS'!B24,"h:mm am/pm") -> 14Bau14-1st/2ndD-3:20 PM | T14: ='14U BOYS GOLD-16 TEAMS'!D25&"-"&'14U BOYS GOLD-16 TEAMS'!I25&"-"&TEXT('14U BOYS GOLD-16 TEAMS'!B25,"h:mm am/pm") -> 14Bau16-1st/2ndB-3:20 PM | U14: ='14U BOYS PLATINUM-10 TEAMS'!D19&"-"&'14U BOYS PLATINUM-10 TEAMS'!I19&"-"&TEXT('14U BOYS PLATINUM-10 TEAMS'!B19,"h:mm am/pm") -> 14Bpt10-C bracket C2,C3-3:20 PM | V14: ='14U BOYS SILVER-16 TEAMS'!D24&"-"&'14U BOYS SILVER-16 TEAMS'!I24&"-"&TEXT('14U BOYS SILVER-16 TEAMS'!B24,"h:mm am/pm") -> 14Bag15-3rd/4thB-3:20 PM
A15: 2R | B15: 0.68055556 | F15: 0.68055556 | G15: ='12U COED GIRLS-9 TEAMS CUSTOM'!D23&"-"&'12U COED GIRLS-9 TEAMS CUSTOM'!I23&"-"&TEXT('12U COED GIRLS-9 TEAMS CUSTOM'!B23,"h:mm am/pm") -> 12GC09-C bracket C1,C2-4:20 PM | Q15: 0.67361111 | R15: ='14U GIRLS-9 TEAMS'!D24&"-"&'14U GIRLS-9 TEAMS'!I24&"-"&TEXT('14U GIRLS-9 TEAMS'!B24,"h:mm am/pm") -> 14G09-A bracket platinum 1st-3rd-4:10 PM | S15: ='14U GIRLS-9 TEAMS'!D23&"-"&'14U GIRLS-9 TEAMS'!I23&"-"&TEXT('14U GIRLS-9 TEAMS'!B23,"h:mm am/pm") -> 14G08-B bracket gold 1st-3rd-4:10 PM
F16: moved from Far Left | Q16: 0.70833333
C21: =COUNTA(C5:C20) -> 9 | D21: =COUNTA(D4:D20) -> 10 | G21: =COUNTA(G4:G20) -> 9 | H21: =COUNTA(H4:H20) -> 7 | I21: =COUNTA(I4:I20) -> 9 | L21: =COUNTA(L4:L20) -> 9 | M21: =COUNTA(M4:M20) -> 8 | N21: =COUNTA(N4:N20) -> 9 | O21: =COUNTA(O4:O20) -> 10 | R21: =COUNTA(R4:R20) -> 12 | S21: =COUNTA(S4:S20) -> 11 | T21: =COUNTA(T4:T20) -> 6 | U21: =COUNTA(U4:U20) -> 10 | V21: =COUNTA(V5:V20) -> 10 | Y21: =SUM(C21:X21) -> 129
N22: last game 3:50pm
B27: DAYLIGHT SAVINGS!!!
B28: SUNDAY MARCH 8 | C28: 10U | D28: 10U | G28: 12U | H28: 12U | I28: 12U
C29: WOOLLETT FAR LEFT | D29: EL TORO HS 2 | G29: WOOLLETT FAR RIGHT | H29: LAGUNA HILLS HS | I29: COSTA MESA HS 2 | L29: WOOLLETT NEAR LEFT | M29: ESTANCIA HS 1 | N29: COSTA MESA HS 1 | O29: WOOLLETT NEAR RIGHT | R29: EL TORO HS 1 | S29: SAN JUAN HILLS HS | T29: ALISO NIGUEL HS | U29: WESTMINSTER HS | V29: ESTANCIA HS 2
F30: 0.29166667 | K30: 0.29166667 | Q30: 0.29166667
B31: 0.33333333 | C31: ='10U BOYS & COED PT-7 CUSTOM'!D22&"-"&'10U BOYS & COED PT-7 CUSTOM'!I22&"-"&TEXT('10U BOYS & COED PT-7 CUSTOM'!B22,"h:mm am/pm") -> 10BCpt08-B bracket B3,B4 Boys 1st-4th-8:00 AM | D31: ='10U GIRLS COED AU AG-12 TEAMS'!D25&"-"&'10U GIRLS COED AU AG-12 TEAMS'!I25&"-"&TEXT('10U GIRLS COED AU AG-12 TEAMS'!B25,"h:mm am/pm") -> 10GCauag13-bracket, A1/A2 coed gold 1st-4th-8:00 AM | E31: x | F31: 0.32638889 | H31: ='12U COED GIRLS-9 TEAMS CUSTOM'!D27&"-"&'12U COED GIRLS-9 TEAMS CUSTOM'!I27&"-"&TEXT('12U COED GIRLS-9 TEAMS CUSTOM'!B27,"h:mm am/pm") -> 12GC10-D bracket D1,D3 Coed 1st-3rd-7:50 AM | I31: ='12U BOYS-16 TEAMS'!D49&"-"&'12U BOYS-16 TEAMS'!I49&"-"&TEXT('12U BOYS-16 TEAMS'!B49,"h:mm am/pm") -> 12B19-cross-7:50 AM | K31: 0.33333333 | L31: ='19U BOYS PLATINUM GOLD-11 TEAMS'!D26&"-"&'19U BOYS PLATINUM GOLD-11 TEAMS'!I26&"-"&TEXT('19U BOYS PLATINUM GOLD-11 TEAMS'!B26,"h:mm am/pm") -> 19Bptau12-F1,F2 7th-11th-8:00 AM | M31: ='19U BOYS PLATINUM GOLD-11 TEAMS'!D27&"-"&'19U BOYS PLATINUM GOLD-11 TEAMS'!I27&"-"&TEXT('19U BOYS PLATINUM GOLD-11 TEAMS'!B27,"h:mm am/pm") -> 19Bptau15-E1,E3 4th-6th-8:00 AM | N31: ='16U BOYS SILVER-8 TEAMS'!D21&"-"&'16U BOYS SILVER-8 TEAMS'!I21&"-"&TEXT('16U BOYS SILVER-8 TEAMS'!B21,"h:mm am/pm") -> 16Bag09-bracket, B3/B4-8:00 AM | O31: ='16U BOYS PLATINUM GOLD-10 TEAMS'!D23&"-"&'16U BOYS PLATINUM GOLD-10 TEAMS'!I23&"-"&TEXT('16U BOYS PLATINUM GOLD-10 TEAMS'!B23,"h:mm am/pm") -> 16Bptau11-C bracket C2,C4-8:00 AM | Q31: 0.32638889 | R31: ='14U GIRLS-9 TEAMS'!D28&"-"&'14U GIRLS-9 TEAMS'!I28&"-"&TEXT('14U GIRLS-9 TEAMS'!B28,"h:mm am/pm") -> 14G10-plat-gold-silver D1,D3-7:50 AM | S31: ='14U BOYS GOLD-16 TEAMS'!D29&"-"&'14U BOYS GOLD-16 TEAMS'!I29&"-"&TEXT('14U BOYS GOLD-16 TEAMS'!B29,"h:mm am/pm") -> 14Bau27-9-12 semi 3A/3D-7:50 AM | T31: ='14U BOYS GOLD-16 TEAMS'!D28&"-"&'14U BOYS GOLD-16 TEAMS'!I28&"-"&TEXT('14U BOYS GOLD-16 TEAMS'!B28,"h:mm am/pm") -> 14Bau29-13-16 semi-7:50 AM | U31: ='14U BOYS PLATINUM-10 TEAMS'!D23&"-"&'14U BOYS PLATINUM-10 TEAMS'!I23&"-"&TEXT('14U BOYS PLATINUM-10 TEAMS'!B23,"h:mm am/pm") -> 14Bpt11-C bracket C2,C4-7:50 AM | V31: ='14U BOYS SILVER-16 TEAMS'!D29&"-"&'14U BOYS SILVER-16 TEAMS'!I29&"-"&TEXT('14U BOYS SILVER-16 TEAMS'!B29,"h:mm am/pm") -> 14Bag27-9-12 semi 3A/3D-7:50 AM
B32: 0.36805556 | C32: ='10U BOYS & COED PT-7 CUSTOM'!D23&"-"&'10U BOYS & COED PT-7 CUSTOM'!I23&"-"&TEXT('10U BOYS & COED PT-7 CUSTOM'!B23,"h:mm am/pm") -> 10BCpt09-B bracket B1,B2 Boys 1st-4th-8:50 AM | D32: ='10U GIRLS COED AU AG-12 TEAMS'!D26&"-"&'10U GIRLS COED AU AG-12 TEAMS'!I26&"-"&TEXT('10U GIRLS COED AU AG-12 TEAMS'!B26,"h:mm am/pm") -> 10GCauag14-bracket, A3/A4 coed gold 1st-4th-8:50 AM | F32: 0.36111111 | G32: ='12U BOYS-16 TEAMS'!D40&"-"&'12U BOYS-16 TEAMS'!I40&"-"&TEXT('12U BOYS-16 TEAMS'!B40,"h:mm am/pm") -> 12B17-G bracket G1,G3 gold 4th-6th-8:40 AM | H32: ='12U COED GIRLS-9 TEAMS CUSTOM'!D28&"-"&'12U COED GIRLS-9 TEAMS CUSTOM'!I28&"-"&TEXT('12U COED GIRLS-9 TEAMS CUSTOM'!B28,"h:mm am/pm") -> 12GC11-E bracket E1,E3 cross-8:40 AM | I32: ='12U BOYS-16 TEAMS'!D50&"-"&'12U BOYS-16 TEAMS'!I50&"-"&TEXT('12U BOYS-16 TEAMS'!B50,"h:mm am/pm") -> 12B20-cross-8:40 AM | K32: 0.375 | L32: ='19U BOYS PLATINUM GOLD-11 TEAMS'!D28&"-"&'19U BOYS PLATINUM GOLD-11 TEAMS'!I28&"-"&TEXT('19U BOYS PLATINUM GOLD-11 TEAMS'!B28,"h:mm am/pm") -> 19Bptau13-F3,F5 7th-11th-9:00 AM | M32: ='19U BOYS SILVER-5 TEAMS'!D21&"-"&'19U BOYS SILVER-5 TEAMS'!I21&"-"&TEXT('19U BOYS SILVER-5 TEAMS'!B21,"h:mm am/pm") -> 19Bag06-A bracket 2/3-9:00 AM | N32: ='16U BOYS SILVER-8 TEAMS'!D22&"-"&'16U BOYS SILVER-8 TEAMS'!I22&"-"&TEXT('16U BOYS SILVER-8 TEAMS'!B22,"h:mm am/pm") -> 16Bag10-bracket, A3/A4-9:00 AM | O32: ='16U BOYS PLATINUM GOLD-10 TEAMS'!D24&"-"&'16U BOYS PLATINUM GOLD-10 TEAMS'!I24&"-"&TEXT('16U BOYS PLATINUM GOLD-10 TEAMS'!B24,"h:mm am/pm") -> 16Bptau12-C bracket C1,C3-9:00 AM | Q32: 0.36111111 | R32: ='14U GIRLS-9 TEAMS'!D29&"-"&'14U GIRLS-9 TEAMS'!I29&"-"&TEXT('14U GIRLS-9 TEAMS'!B29,"h:mm am/pm") -> 14G11-plat-gold-silver E1,E3-8:40 AM | S32: ='14U BOYS GOLD-16 TEAMS'!D31&"-"&'14U BOYS GOLD-16 TEAMS'!I31&"-"&TEXT('14U BOYS GOLD-16 TEAMS'!B31,"h:mm am/pm") -> 14Bau28-9-12 semi 3B/3C-8:40 AM | T32: ='14U BOYS GOLD-16 TEAMS'!D30&"-"&'14U BOYS GOLD-16 TEAMS'!I30&"-"&TEXT('14U BOYS GOLD-16 TEAMS'!B30,"h:mm am/pm") -> 14Bau30-13-16 semi-8:40 AM | U32: ='14U BOYS PLATINUM-10 TEAMS'!D24&"-"&'14U BOYS PLATINUM-10 TEAMS'!I24&"-"&TEXT('14U BOYS PLATINUM-10 TEAMS'!B24,"h:mm am/pm") -> 14Bpt12-C bracket C1,C3-8:40 AM | V32: ='14U BOYS SILVER-16 TEAMS'!D30&"-"&'14U BOYS SILVER-16 TEAMS'!I30&"-"&TEXT('14U BOYS SILVER-16 TEAMS'!B30,"h:mm am/pm") -> 14Bag28-9-12 semi 3B/3C-8:40 AM
A33: 2R | B33: 0.40277778 | C33: ='10U GIRLS COED AU AG-12 TEAMS'!D27&"-"&'10U GIRLS COED AU AG-12 TEAMS'!I27&"-"&TEXT('10U GIRLS COED AU AG-12 TEAMS'!B27,"h:mm am/pm") -> 10GCauag15-bracket, B1/B2 coed silver 1st-4th-9:40 AM | D33: ='10U GIRLS COED AU AG-12 TEAMS'!D28&"-"&'10U GIRLS COED AU AG-12 TEAMS'!I28&"-"&TEXT('10U GIRLS COED AU AG-12 TEAMS'!B28,"h:mm am/pm") -> 10GCauag16-bracket, B3/B4 coed silver 1st-4th-9:40 AM | F33: 0.39583333 | G33: ='12U BOYS-16 TEAMS'!D41&"-"&'12U BOYS-16 TEAMS'!I41&"-"&TEXT('12U BOYS-16 TEAMS'!B41,"h:mm am/pm") -> 12B18-F bracket F1,F3 gold 1st-3rd-9:30 AM | H33: ='12U COED GIRLS-9 TEAMS CUSTOM'!D29&"-"&'12U COED GIRLS-9 TEAMS CUSTOM'!I29&"-"&TEXT('12U COED GIRLS-9 TEAMS CUSTOM'!B29,"h:mm am/pm") -> 12GC12-F bracket F1,F3 cross-9:30 AM | I33: ='12U BOYS-16 TEAMS'!D51&"-"&'12U BOYS-16 TEAMS'!I51&"-"&TEXT('12U BOYS-16 TEAMS'!B51,"h:mm am/pm") -> 12B23-cross-9:30 AM | K33: 0.41666667 | L33: ='19U BOYS PLATINUM GOLD-11 TEAMS'!D29&"-"&'19U BOYS PLATINUM GOLD-11 TEAMS'!I29&"-"&TEXT('19U BOYS PLATINUM GOLD-11 TEAMS'!B29,"h:mm am/pm") -> 19Bptau14-D1,D3 1st-3rd-10:00 AM | M33: ='19U BOYS SILVER-5 TEAMS'!D22&"-"&'19U BOYS SILVER-5 TEAMS'!I22&"-"&TEXT('19U BOYS SILVER-5 TEAMS'!B22,"h:mm am/pm") -> 19Bag07-A bracket 4/5-10:00 AM | N33: ='16U BOYS SILVER-8 TEAMS'!D23&"-"&'16U BOYS SILVER-8 TEAMS'!I23&"-"&TEXT('16U BOYS SILVER-8 TEAMS'!B23,"h:mm am/pm") -> 16Bag11-bracket, B1/B2-10:00 AM | O33: ='16U BOYS PLATINUM GOLD-10 TEAMS'!D25&"-"&'16U BOYS PLATINUM GOLD-10 TEAMS'!I25&"-"&TEXT('16U BOYS PLATINUM GOLD-10 TEAMS'!B25,"h:mm am/pm") -> 16Bptau13-cross-10:00 AM | Q33: 0.39583333 | R33: ='14U GIRLS-9 TEAMS'!D30&"-"&'14U GIRLS-9 TEAMS'!I30&"-"&TEXT('14U GIRLS-9 TEAMS'!B30,"h:mm am/pm") -> 14G12-plat-gold-silver F1,F3-9:30 AM | S33: ='14U BOYS GOLD-16 TEAMS'!D32&"-"&'14U BOYS GOLD-16 TEAMS'!I32&"-"&TEXT('14U BOYS GOLD-16 TEAMS'!B32,"h:mm am/pm") -> 14Bau21-5-8 semi 2D/2A-9:30 AM | T33: ='14U BOYS SILVER-16 TEAMS'!D32&"-"&'14U BOYS SILVER-16 TEAMS'!I32&"-"&TEXT('14U BOYS SILVER-16 TEAMS'!B32,"h:mm am/pm") -> 14Bag29-13-16 semi-9:30 AM | U33: ='14U BOYS PLATINUM-10 TEAMS'!D25&"-"&'14U BOYS PLATINUM-10 TEAMS'!I25&"-"&TEXT('14U BOYS PLATINUM-10 TEAMS'!B25,"h:mm am/pm") -> 14Bpt13-5th-10th 2A/3B-9:30 AM | V33: ='14U BOYS SILVER-16 TEAMS'!D31&"-"&'14U BOYS SILVER-16 TEAMS'!I31&"-"&TEXT('14U BOYS SILVER-16 TEAMS'!B31,"h:mm am/pm") -> 14Bag21-5-8 semi 2D/2A-9:30 AM
A34: 2R | B34: 0.4375 | C34: ='10U BOYS & COED PT-7 CUSTOM'!D25&"-"&'10U BOYS & COED PT-7 CUSTOM'!I25&"-"&TEXT('10U BOYS & COED PT-7 CUSTOM'!B25,"h:mm am/pm") -> 10BCpt10-cross-10:30 AM | D34: ='10U GIRLS COED AU AG-12 TEAMS'!D29&"-"&'10U GIRLS COED AU AG-12 TEAMS'!I29&"-"&TEXT('10U GIRLS COED AU AG-12 TEAMS'!B29,"h:mm am/pm") -> 10GCauag17-cross-10:30 AM | F34: 0.43055556 | H34: ='12U COED GIRLS-9 TEAMS CUSTOM'!D30&"-"&'12U COED GIRLS-9 TEAMS CUSTOM'!I30&"-"&TEXT('12U COED GIRLS-9 TEAMS CUSTOM'!B30,"h:mm am/pm") -> 12GC13-D bracket D2,D3 Coed 1st-3rd-10:20 AM | I34: ='12U BOYS-16 TEAMS'!D52&"-"&'12U BOYS-16 TEAMS'!I52&"-"&TEXT('12U BOYS-16 TEAMS'!B52,"h:mm am/pm") -> 12B24-cross-10:20 AM | K34: 0.45833333 | L34: ='19U BOYS PLATINUM GOLD-11 TEAMS'!D30&"-"&'19U BOYS PLATINUM GOLD-11 TEAMS'!I30&"-"&TEXT('19U BOYS PLATINUM GOLD-11 TEAMS'!B30,"h:mm am/pm") -> 19Bptau16-F2,F4 7th-11th-11:00 AM | M34: ='19U BOYS PLATINUM GOLD-11 TEAMS'!D31&"-"&'19U BOYS PLATINUM GOLD-11 TEAMS'!I31&"-"&TEXT('19U BOYS PLATINUM GOLD-11 TEAMS'!B31,"h:mm am/pm") -> 19Bptau19-E2,E3 4th-6th-11:00 AM | N34: ='16U BOYS SILVER-8 TEAMS'!D24&"-"&'16U BOYS SILVER-8 TEAMS'!I24&"-"&TEXT('16U BOYS SILVER-8 TEAMS'!B24,"h:mm am/pm") -> 16Bag12-bracket, A1/A2-11:00 AM | O34: ='16U BOYS PLATINUM GOLD-10 TEAMS'!D26&"-"&'16U BOYS PLATINUM GOLD-10 TEAMS'!I26&"-"&TEXT('16U BOYS PLATINUM GOLD-10 TEAMS'!B26,"h:mm am/pm") -> 16Bptau14-cross-11:00 AM | Q34: 0.43055556 | R34: ='14U GIRLS-9 TEAMS'!D31&"-"&'14U GIRLS-9 TEAMS'!I31&"-"&TEXT('14U GIRLS-9 TEAMS'!B31,"h:mm am/pm") -> 14G13-plat-gold-silver D2,D3-10:20 AM | S34: ='14U BOYS GOLD-16 TEAMS'!D33&"-"&'14U BOYS GOLD-16 TEAMS'!I33&"-"&TEXT('14U BOYS GOLD-16 TEAMS'!B33,"h:mm am/pm") -> 14Bau22-5-8 semi 2C/2B-10:20 AM | T34: ='14U BOYS SILVER-16 TEAMS'!D33&"-"&'14U BOYS SILVER-16 TEAMS'!I33&"-"&TEXT('14U BOYS SILVER-16 TEAMS'!B33,"h:mm am/pm") -> 14Bag30-13-16 semi-10:20 AM | U34: ='14U BOYS PLATINUM-10 TEAMS'!D26&"-"&'14U BOYS PLATINUM-10 TEAMS'!I26&"-"&TEXT('14U BOYS PLATINUM-10 TEAMS'!B26,"h:mm am/pm") -> 14Bpt14-5th-10th 3A/2B-10:20 AM | V34: ='14U BOYS SILVER-16 TEAMS'!D34&"-"&'14U BOYS SILVER-16 TEAMS'!I34&"-"&TEXT('14U BOYS SILVER-16 TEAMS'!B34,"h:mm am/pm") -> 14Bag22-5-8 semi 2C/2B-10:20 AM
A35: 2R | B35: 0.47222222 | C35: ='10U BOYS & COED PT-7 CUSTOM'!D26&"-"&'10U BOYS & COED PT-7 CUSTOM'!I26&"-"&TEXT('10U BOYS & COED PT-7 CUSTOM'!B26,"h:mm am/pm") -> 10BCpt11-cross-11:20 AM | D35: ='10U GIRLS COED AU AG-12 TEAMS'!D30&"-"&'10U GIRLS COED AU AG-12 TEAMS'!I30&"-"&TEXT('10U GIRLS COED AU AG-12 TEAMS'!B30,"h:mm am/pm") -> 10GCauag18-cross-11:20 AM | F35: 0.46527778 | G35: ='12U BOYS-16 TEAMS'!D43&"-"&'12U BOYS-16 TEAMS'!I43&"-"&TEXT('12U BOYS-16 TEAMS'!B43,"h:mm am/pm") -> 12B21-G bracket G2,G3 gold 4th-6th-11:10 AM | H35: ='12U COED GIRLS-9 TEAMS CUSTOM'!D31&"-"&'12U COED GIRLS-9 TEAMS CUSTOM'!I31&"-"&TEXT('12U COED GIRLS-9 TEAMS CUSTOM'!B31,"h:mm am/pm") -> 12GC14-E bracket E2,E3 cross-11:10 AM | I35: ='12U BOYS-16 TEAMS'!D53&"-"&'12U BOYS-16 TEAMS'!I53&"-"&TEXT('12U BOYS-16 TEAMS'!B53,"h:mm am/pm") -> 12B27-cross-11:10 AM | K35: 0.5 | L35: ='19U BOYS PLATINUM GOLD-11 TEAMS'!D32&"-"&'19U BOYS PLATINUM GOLD-11 TEAMS'!I32&"-"&TEXT('19U BOYS PLATINUM GOLD-11 TEAMS'!B32,"h:mm am/pm") -> 19Bptau17-F1,F3 7th-11th-12:00 PM | M35: ='19U BOYS SILVER-5 TEAMS'!D24&"-"&'19U BOYS SILVER-5 TEAMS'!I24&"-"&TEXT('19U BOYS SILVER-5 TEAMS'!B24,"h:mm am/pm") -> 19Bag08-A bracket 1/2-12:00 PM | N35: ='16U BOYS SILVER-8 TEAMS'!D25&"-"&'16U BOYS SILVER-8 TEAMS'!I25&"-"&TEXT('16U BOYS SILVER-8 TEAMS'!B25,"h:mm am/pm") -> 16Bag13-7th-12:00 PM | O35: ='16U BOYS PLATINUM GOLD-10 TEAMS'!D27&"-"&'16U BOYS PLATINUM GOLD-10 TEAMS'!I27&"-"&TEXT('16U BOYS PLATINUM GOLD-10 TEAMS'!B27,"h:mm am/pm") -> 16Bptau15-Gold 3rd-12:00 PM | Q35: 0.46527778 | R35: ='14U GIRLS-9 TEAMS'!D32&"-"&'14U GIRLS-9 TEAMS'!I32&"-"&TEXT('14U GIRLS-9 TEAMS'!B32,"h:mm am/pm") -> 14G14-plat-gold-silver E2,E3-11:10 AM | S35: ='14U BOYS GOLD-16 TEAMS'!D34&"-"&'14U BOYS GOLD-16 TEAMS'!I34&"-"&TEXT('14U BOYS GOLD-16 TEAMS'!B34,"h:mm am/pm") -> 14Bau19-1-4 semi 1A/1D-11:10 AM | T35: ='14U BOYS GOLD-16 TEAMS'!D35&"-"&'14U BOYS GOLD-16 TEAMS'!I35&"-"&TEXT('14U BOYS GOLD-16 TEAMS'!B35,"h:mm am/pm") -> 14Bau34-13th-11:10 AM | U35: ='14U BOYS PLATINUM-10 TEAMS'!D27&"-"&'14U BOYS PLATINUM-10 TEAMS'!I27&"-"&TEXT('14U BOYS PLATINUM-10 TEAMS'!B27,"h:mm am/pm") -> 14Bpt15-1-4 semi 1A/2C-11:10 AM | V35: ='14U BOYS SILVER-16 TEAMS'!D35&"-"&'14U BOYS SILVER-16 TEAMS'!I35&"-"&TEXT('14U BOYS SILVER-16 TEAMS'!B35,"h:mm am/pm") -> 14Bag19-1-4 semi 1A/1D-11:10 AM
B36: 0.50694444 | C36: ='10U BOYS & COED PT-7 CUSTOM'!D27&"-"&'10U BOYS & COED PT-7 CUSTOM'!I27&"-"&TEXT('10U BOYS & COED PT-7 CUSTOM'!B27,"h:mm am/pm") -> 10BCpt12-cross-12:10 PM | D36: ='10U GIRLS COED AU AG-12 TEAMS'!D31&"-"&'10U GIRLS COED AU AG-12 TEAMS'!I31&"-"&TEXT('10U GIRLS COED AU AG-12 TEAMS'!B31,"h:mm am/pm") -> 10GCauag19-cross-12:10 PM | F36: 0.5 | G36: ='12U BOYS-16 TEAMS'!D44&"-"&'12U BOYS-16 TEAMS'!I44&"-"&TEXT('12U BOYS-16 TEAMS'!B44,"h:mm am/pm") -> 12B22-F bracket F2,F3 gold 1st-3rd-12:00 PM | H36: ='12U COED GIRLS-9 TEAMS CUSTOM'!D32&"-"&'12U COED GIRLS-9 TEAMS CUSTOM'!I32&"-"&TEXT('12U COED GIRLS-9 TEAMS CUSTOM'!B32,"h:mm am/pm") -> 12GC15-F bracket F2,F3 cross-12:00 PM | I36: ='12U BOYS-16 TEAMS'!D54&"-"&'12U BOYS-16 TEAMS'!I54&"-"&TEXT('12U BOYS-16 TEAMS'!B54,"h:mm am/pm") -> 12B28-cross-12:00 PM | K36: 0.54166667 | L36: ='19U BOYS PLATINUM GOLD-11 TEAMS'!D33&"-"&'19U BOYS PLATINUM GOLD-11 TEAMS'!I33&"-"&TEXT('19U BOYS PLATINUM GOLD-11 TEAMS'!B33,"h:mm am/pm") -> 19Bptau18-D2,D3 1st-3rd-1:00 PM | M36: ='19U BOYS SILVER-5 TEAMS'!D25&"-"&'19U BOYS SILVER-5 TEAMS'!I25&"-"&TEXT('19U BOYS SILVER-5 TEAMS'!B25,"h:mm am/pm") -> 19Bag09-A bracket 3/4-1:00 PM | N36: ='16U BOYS SILVER-8 TEAMS'!D26&"-"&'16U BOYS SILVER-8 TEAMS'!I26&"-"&TEXT('16U BOYS SILVER-8 TEAMS'!B26,"h:mm am/pm") -> 16Bag14-5th-1:00 PM | O36: ='16U BOYS PLATINUM GOLD-10 TEAMS'!D28&"-"&'16U BOYS PLATINUM GOLD-10 TEAMS'!I28&"-"&TEXT('16U BOYS PLATINUM GOLD-10 TEAMS'!B28,"h:mm am/pm") -> 16Bptau16-Gold 1st-1:00 PM | Q36: 0.5 | R36: ='14U GIRLS-9 TEAMS'!D33&"-"&'14U GIRLS-9 TEAMS'!I33&"-"&TEXT('14U GIRLS-9 TEAMS'!B33,"h:mm am/pm") -> 14G15-plat-gold-silver F2,F3-12:00 PM | S36: ='14U BOYS GOLD-16 TEAMS'!D37&"-"&'14U BOYS GOLD-16 TEAMS'!I37&"-"&TEXT('14U BOYS GOLD-16 TEAMS'!B37,"h:mm am/pm") -> 14Bau20-1-4 semi 1B/1C-12:00 PM | T36: ='14U BOYS GOLD-16 TEAMS'!D36&"-"&'14U BOYS GOLD-16 TEAMS'!I36&"-"&TEXT('14U BOYS GOLD-16 TEAMS'!B36,"h:mm am/pm") -> 14Bau33-15th-12:00 PM | U36: ='14U BOYS PLATINUM-10 TEAMS'!D28&"-"&'14U BOYS PLATINUM-10 TEAMS'!I28&"-"&TEXT('14U BOYS PLATINUM-10 TEAMS'!B28,"h:mm am/pm") -> 14Bpt16-1-4 semi 1B/1C-12:00 PM | V36: ='14U BOYS SILVER-16 TEAMS'!D36&"-"&'14U BOYS SILVER-16 TEAMS'!I36&"-"&TEXT('14U BOYS SILVER-16 TEAMS'!B36,"h:mm am/pm") -> 14Bag20-1-4 semi 1B/1C-12:00 PM
B37: 0.54166667 | C37: ='10U BOYS & COED PT-7 CUSTOM'!D28&"-"&'10U BOYS & COED PT-7 CUSTOM'!I28&"-"&TEXT('10U BOYS & COED PT-7 CUSTOM'!B28,"h:mm am/pm") -> 10BCpt13-cross-1:00 PM | D37: ='10U GIRLS COED AU AG-12 TEAMS'!D32&"-"&'10U GIRLS COED AU AG-12 TEAMS'!I32&"-"&TEXT('10U GIRLS COED AU AG-12 TEAMS'!B32,"h:mm am/pm") -> 10GCauag20-cross-1:00 PM | F37: 0.53472222 | H37: ='12U COED GIRLS-9 TEAMS CUSTOM'!D33&"-"&'12U COED GIRLS-9 TEAMS CUSTOM'!I33&"-"&TEXT('12U COED GIRLS-9 TEAMS CUSTOM'!B33,"h:mm am/pm") -> 12GC16-D bracket D1,D2 Coed 1st-3rd-12:50 PM | I37: ='12U BOYS-16 TEAMS'!D55&"-"&'12U BOYS-16 TEAMS'!I55&"-"&TEXT('12U BOYS-16 TEAMS'!B55,"h:mm am/pm") -> 12B29-cross-12:50 PM | K37: 0.58333333 | L37: ='19U BOYS PLATINUM GOLD-11 TEAMS'!D34&"-"&'19U BOYS PLATINUM GOLD-11 TEAMS'!I34&"-"&TEXT('19U BOYS PLATINUM GOLD-11 TEAMS'!B34,"h:mm am/pm") -> 19Bptau20-F4,F5 7th-11th-2:00 PM | M37: ='19U BOYS PLATINUM GOLD-11 TEAMS'!D35&"-"&'19U BOYS PLATINUM GOLD-11 TEAMS'!I35&"-"&TEXT('19U BOYS PLATINUM GOLD-11 TEAMS'!B35,"h:mm am/pm") -> 19Bptau22-E1,E2 4th-6th-2:00 PM | N37: ='16U BOYS SILVER-8 TEAMS'!D27&"-"&'16U BOYS SILVER-8 TEAMS'!I27&"-"&TEXT('16U BOYS SILVER-8 TEAMS'!B27,"h:mm am/pm") -> 16Bag15-3rd-2:00 PM | O37: ='16U BOYS PLATINUM GOLD-10 TEAMS'!D29&"-"&'16U BOYS PLATINUM GOLD-10 TEAMS'!I29&"-"&TEXT('16U BOYS PLATINUM GOLD-10 TEAMS'!B29,"h:mm am/pm") -> 16Bptau17-cross-2:00 PM | Q37: 0.53472222 | R37: ='14U BOYS GOLD-16 TEAMS'!D39&"-"&'14U BOYS GOLD-16 TEAMS'!I39&"-"&TEXT('14U BOYS GOLD-16 TEAMS'!B39,"h:mm am/pm") -> 14Bau31-9th-12:50 PM | S37: ='14U BOYS GOLD-16 TEAMS'!D38&"-"&'14U BOYS GOLD-16 TEAMS'!I38&"-"&TEXT('14U BOYS GOLD-16 TEAMS'!B38,"h:mm am/pm") -> 14Bau25-5th-12:50 PM | T37: ='14U BOYS SILVER-16 TEAMS'!D38&"-"&'14U BOYS SILVER-16 TEAMS'!I38&"-"&TEXT('14U BOYS SILVER-16 TEAMS'!B38,"h:mm am/pm") -> 14Bag31-9th-12:50 PM | U37: ='14U BOYS PLATINUM-10 TEAMS'!D29&"-"&'14U BOYS PLATINUM-10 TEAMS'!I29&"-"&TEXT('14U BOYS PLATINUM-10 TEAMS'!B29,"h:mm am/pm") -> 14Bpt18-7th-10th-12:50 PM | V37: ='14U BOYS SILVER-16 TEAMS'!D37&"-"&'14U BOYS SILVER-16 TEAMS'!I37&"-"&TEXT('14U BOYS SILVER-16 TEAMS'!B37,"h:mm am/pm") -> 14Bag25-5th-12:50 PM
A38: 2R | B38: 0.57638889 | C38: ='10U BOYS & COED PT-7 CUSTOM'!D29&"-"&'10U BOYS & COED PT-7 CUSTOM'!I29&"-"&TEXT('10U BOYS & COED PT-7 CUSTOM'!B29,"h:mm am/pm") -> 10BCpt14-cross-1:50 PM | D38: ='10U GIRLS COED AU AG-12 TEAMS'!D33&"-"&'10U GIRLS COED AU AG-12 TEAMS'!I33&"-"&TEXT('10U GIRLS COED AU AG-12 TEAMS'!B33,"h:mm am/pm") -> 10GCauag21-cross-1:50 PM | E38: x | F38: 0.56944444 | G38: ='12U BOYS-16 TEAMS'!D46&"-"&'12U BOYS-16 TEAMS'!I46&"-"&TEXT('12U BOYS-16 TEAMS'!B46,"h:mm am/pm") -> 12B25-G bracket G1,G2 gold 4th-6th-1:40 PM | H38: ='12U COED GIRLS-9 TEAMS CUSTOM'!D34&"-"&'12U COED GIRLS-9 TEAMS CUSTOM'!I34&"-"&TEXT('12U COED GIRLS-9 TEAMS CUSTOM'!B34,"h:mm am/pm") -> 12GC17-E bracket E1,E2 Coed 4th-1:40 PM | I38: ='12U BOYS-16 TEAMS'!D56&"-"&'12U BOYS-16 TEAMS'!I56&"-"&TEXT('12U BOYS-16 TEAMS'!B56,"h:mm am/pm") -> 12B30-cross-1:40 PM | K38: 0.625 | L38: ='19U BOYS PLATINUM GOLD-11 TEAMS'!D36&"-"&'19U BOYS PLATINUM GOLD-11 TEAMS'!I36&"-"&TEXT('19U BOYS PLATINUM GOLD-11 TEAMS'!B36,"h:mm am/pm") -> 19Bptau21-D1,D2 1st-3rd-3:00 PM | M38: ='19U BOYS SILVER-5 TEAMS'!D27&"-"&'19U BOYS SILVER-5 TEAMS'!I27&"-"&TEXT('19U BOYS SILVER-5 TEAMS'!B27,"h:mm am/pm") -> 19Bag10-A bracket 1/5-3:00 PM | N38: ='16U BOYS SILVER-8 TEAMS'!D28&"-"&'16U BOYS SILVER-8 TEAMS'!I28&"-"&TEXT('16U BOYS SILVER-8 TEAMS'!B28,"h:mm am/pm") -> 16Bag16-1st-3:00 PM | O38: ='16U BOYS PLATINUM GOLD-10 TEAMS'!D30&"-"&'16U BOYS PLATINUM GOLD-10 TEAMS'!I30&"-"&TEXT('16U BOYS PLATINUM GOLD-10 TEAMS'!B30,"h:mm am/pm") -> 16Bptau18-cross-3:00 PM | Q38: 0.56944444 | R38: ='14U BOYS GOLD-16 TEAMS'!D41&"-"&'14U BOYS GOLD-16 TEAMS'!I41&"-"&TEXT('14U BOYS GOLD-16 TEAMS'!B41,"h:mm am/pm") -> 14Bau32-11th-1:40 PM | S38: ='14U BOYS GOLD-16 TEAMS'!D40&"-"&'14U BOYS GOLD-16 TEAMS'!I40&"-"&TEXT('14U BOYS GOLD-16 TEAMS'!B40,"h:mm am/pm") -> 14Bau26-7th-1:40 PM | T38: ='14U BOYS SILVER-16 TEAMS'!D40&"-"&'14U BOYS SILVER-16 TEAMS'!I40&"-"&TEXT('14U BOYS SILVER-16 TEAMS'!B40,"h:mm am/pm") -> 14Bag32-11th-1:40 PM | U38: ='14U BOYS PLATINUM-10 TEAMS'!D30&"-"&'14U BOYS PLATINUM-10 TEAMS'!I30&"-"&TEXT('14U BOYS PLATINUM-10 TEAMS'!B30,"h:mm am/pm") -> 14Bpt20-3rd-1:40 PM | V38: ='14U BOYS SILVER-16 TEAMS'!D39&"-"&'14U BOYS SILVER-16 TEAMS'!I39&"-"&TEXT('14U BOYS SILVER-16 TEAMS'!B39,"h:mm am/pm") -> 14Bag26-7th-1:40 PM
A39: 2R | B39: 0.61111111 | C39: ='10U BOYS & COED PT-7 CUSTOM'!D30&"-"&'10U BOYS & COED PT-7 CUSTOM'!I30&"-"&TEXT('10U BOYS & COED PT-7 CUSTOM'!B30,"h:mm am/pm") -> 10BCpt15-cross-2:40 PM | D39: ='10U GIRLS COED AU AG-12 TEAMS'!D34&"-"&'10U GIRLS COED AU AG-12 TEAMS'!I34&"-"&TEXT('10U GIRLS COED AU AG-12 TEAMS'!B34,"h:mm am/pm") -> 10GCauag22-cross-2:40 PM | F39: 0.60416667 | G39: ='12U BOYS-16 TEAMS'!D47&"-"&'12U BOYS-16 TEAMS'!I47&"-"&TEXT('12U BOYS-16 TEAMS'!B47,"h:mm am/pm") -> 12B26-F bracket F1,F2 gold 1st-3rd-2:30 PM | I39: ='12U BOYS-16 TEAMS'!D57&"-"&'12U BOYS-16 TEAMS'!I57&"-"&TEXT('12U BOYS-16 TEAMS'!B57,"h:mm am/pm") -> 12B31-cross-2:30 PM | K39: 0.66666667 | L39: ='16U BOYS PLATINUM GOLD-10 TEAMS'!D32&"-"&'16U BOYS PLATINUM GOLD-10 TEAMS'!I32&"-"&TEXT('16U BOYS PLATINUM GOLD-10 TEAMS'!B32,"h:mm am/pm") -> 16Bptau20-cross-4:00 PM | O39: ='16U BOYS PLATINUM GOLD-10 TEAMS'!D31&"-"&'16U BOYS PLATINUM GOLD-10 TEAMS'!I31&"-"&TEXT('16U BOYS PLATINUM GOLD-10 TEAMS'!B31,"h:mm am/pm") -> 16Bptau19-cross-4:00 PM | Q39: 0.60416667 | R39: ='14U GIRLS-9 TEAMS'!D35&"-"&'14U GIRLS-9 TEAMS'!I35&"-"&TEXT('14U GIRLS-9 TEAMS'!B35,"h:mm am/pm") -> 14G16-plat-gold-silver D1,D2-2:30 PM | S39: ='14U BOYS GOLD-16 TEAMS'!D42&"-"&'14U BOYS GOLD-16 TEAMS'!I42&"-"&TEXT('14U BOYS GOLD-16 TEAMS'!B42,"h:mm am/pm") -> 14Bau23-3rd-2:30 PM | T39: ='14U BOYS SILVER-16 TEAMS'!D41&"-"&'14U BOYS SILVER-16 TEAMS'!I41&"-"&TEXT('14U BOYS SILVER-16 TEAMS'!B41,"h:mm am/pm") -> 14Bag34-13th-2:30 PM | U39: ='14U BOYS PLATINUM-10 TEAMS'!D31&"-"&'14U BOYS PLATINUM-10 TEAMS'!I31&"-"&TEXT('14U BOYS PLATINUM-10 TEAMS'!B31,"h:mm am/pm") -> 14Bpt21-1st-2:30 PM | V39: ='14U BOYS SILVER-16 TEAMS'!D42&"-"&'14U BOYS SILVER-16 TEAMS'!I42&"-"&TEXT('14U BOYS SILVER-16 TEAMS'!B42,"h:mm am/pm") -> 14Bag23-3rd-2:30 PM
A40: 2R | B40: 0.64583333 | D40: ='10U GIRLS COED AU AG-12 TEAMS'!D35&"-"&'10U GIRLS COED AU AG-12 TEAMS'!I35&"-"&TEXT('10U GIRLS COED AU AG-12 TEAMS'!B35,"h:mm am/pm") -> 10GCauag23-cross-3:30 PM | F40: 0.64583333 | G40: ='12U COED GIRLS-9 TEAMS CUSTOM'!D36&"-"&'12U COED GIRLS-9 TEAMS CUSTOM'!I36&"-"&TEXT('12U COED GIRLS-9 TEAMS CUSTOM'!B36,"h:mm am/pm") -> 12GC18-F bracket F1,F2 Coed 6th-3:30 PM | I40: ='12U BOYS-16 TEAMS'!D58&"-"&'12U BOYS-16 TEAMS'!I58&"-"&TEXT('12U BOYS-16 TEAMS'!B58,"h:mm am/pm") -> 12B32-cross-3:20 PM | K40: 0.70833333 | Q40: 0.63888889 | R40: ='14U GIRLS-9 TEAMS'!D36&"-"&'14U GIRLS-9 TEAMS'!I36&"-"&TEXT('14U GIRLS-9 TEAMS'!B36,"h:mm am/pm") -> 14G17-plat-gold-silver E1,E2-3:20 PM | S40: ='14U BOYS GOLD-16 TEAMS'!D43&"-"&'14U BOYS GOLD-16 TEAMS'!I43&"-"&TEXT('14U BOYS GOLD-16 TEAMS'!B43,"h:mm am/pm") -> 14Bau24-1st-3:20 PM | T40: ='14U BOYS SILVER-16 TEAMS'!D43&"-"&'14U BOYS SILVER-16 TEAMS'!I43&"-"&TEXT('14U BOYS SILVER-16 TEAMS'!B43,"h:mm am/pm") -> 14Bag33-15th-3:20 PM | U40: ='14U BOYS PLATINUM-10 TEAMS'!D32&"-"&'14U BOYS PLATINUM-10 TEAMS'!I32&"-"&TEXT('14U BOYS PLATINUM-10 TEAMS'!B32,"h:mm am/pm") -> 14Bpt17-5th-3:20 PM | V40: ='14U BOYS SILVER-16 TEAMS'!D44&"-"&'14U BOYS SILVER-16 TEAMS'!I44&"-"&TEXT('14U BOYS SILVER-16 TEAMS'!B44,"h:mm am/pm") -> 14Bag24-1st-3:20 PM
B41: 0.68055556 | D41: ='10U GIRLS COED AU AG-12 TEAMS'!D36&"-"&'10U GIRLS COED AU AG-12 TEAMS'!I36&"-"&TEXT('10U GIRLS COED AU AG-12 TEAMS'!B36,"h:mm am/pm") -> 10GCauag24-cross-4:20 PM | F41: moved from Far Left same time | Q41: 0.67361111 | R41: ='14U GIRLS-9 TEAMS'!D37&"-"&'14U GIRLS-9 TEAMS'!I37&"-"&TEXT('14U GIRLS-9 TEAMS'!B37,"h:mm am/pm") -> 14G18-plat-gold-silver F1,F2-4:10 PM | U41: ='14U BOYS PLATINUM-10 TEAMS'!D33&"-"&'14U BOYS PLATINUM-10 TEAMS'!I33&"-"&TEXT('14U BOYS PLATINUM-10 TEAMS'!B33,"h:mm am/pm") -> 14Bpt19-7th-10th-4:10 PM
C49: =COUNTA(C30:C48) -> 9 | D49: =COUNTA(D30:D48) -> 11 | G49: =COUNTA(G30:G48) -> 7 | H49: =COUNTA(H30:H48) -> 8 | I49: =COUNTA(I30:I48) -> 10 | L49: =COUNTA(L31:L48) -> 9 | M49: =COUNTA(M30:M48) -> 8 | N49: =COUNTA(N30:N48) -> 8 | O49: =COUNTA(O30:O48) -> 9 | R49: =COUNTA(R30:R48) -> 11 | S49: =COUNTA(S30:S48) -> 10 | T49: =COUNTA(T30:T48) -> 10 | U49: =COUNTA(U30:U48) -> 11 | V49: =COUNTA(V30:V48) -> 10 | Y49: =SUM(C49:X49) -> 131
B53: 130 | C53: =B53/14 -> 9.2857143

Sheet MASTER BY DIVISION
A1: DATE | B1: TIME | C1: LOCATION | D1: GAME ID | E1: WHITE TEAM | F1: S | G1: DARK TEAM | H1: S | I1: COMMENTS | J1: DIVISION | K1: SORTKEY
A2: ='10U GIRLS COED AU AG-12 TEAMS'!A10 -> 46088 | B2: ='10U GIRLS COED AU AG-12 TEAMS'!B10 -> 0.33333333 | C2: ='10U GIRLS COED AU AG-12 TEAMS'!C10&"" -> EL TORO HS 2 | D2: ='10U GIRLS COED AU AG-12 TEAMS'!D10&"" -> 10GCauag01 | E2: ='10U GIRLS COED AU AG-12 TEAMS'!E10&"" -> B1-SAN CLEMENTE GIRLS RED ag | F2: ='10U GIRLS COED AU AG-12 TEAMS'!F10&"" -> 6 | G2: ='10U GIRLS COED AU AG-12 TEAMS'!G10&"" -> B4-TROJAN NORTH ag | H2: ='10U GIRLS COED AU AG-12 TEAMS'!H10&"" -> 14 | I2: ='10U GIRLS COED AU AG-12 TEAMS'!I10&"" -> B bracket, B1/B4 coed silver 1st-4th | J2: ='10U GIRLS COED AU AG-12 TEAMS'!J10&"" -> 10U_GIRLS_COED_GOLD_SILVER | K2: =TEXT(DATE(2026, MONTH(A2), DAY(A2)) + TIME(HOUR(B2), MINUTE(B2), 0), "yyyymmddhhmm") -> 202603070800
A3: ='10U GIRLS COED AU AG-12 TEAMS'!A11 -> 46088 | B3: ='10U GIRLS COED AU AG-12 TEAMS'!B11 -> 0.36805556 | C3: ='10U GIRLS COED AU AG-12 TEAMS'!C11&"" -> EL TORO HS 2 | D3: ='10U GIRLS COED AU AG-12 TEAMS'!D11&"" -> 10GCauag02 | E3: ='10U GIRLS COED AU AG-12 TEAMS'!E11&"" -> B2-CDM BOYS WHITE ag | F3: ='10U GIRLS COED AU AG-12 TEAMS'!F11&"" -> 8 | G3: ='10U GIRLS COED AU AG-12 TEAMS'!G11&"" -> B3-LAGUNA BEACH ag | H3: ='10U GIRLS COED AU AG-12 TEAMS'!H11&"" -> 10 | I3: ='10U GIRLS COED AU AG-12 TEAMS'!I11&"" -> B bracket, B2/B3 coed silver 1st-4th | J3: ='10U GIRLS COED AU AG-12 TEAMS'!J11&"" -> 10U_GIRLS_COED_GOLD_SILVER | K3: =TEXT(DATE(2026, MONTH(A3), DAY(A3)) + TIME(HOUR(B3), MINUTE(B3), 0), "yyyymmddhhmm") -> 202603070850
A4: ='10U GIRLS COED AU AG-12 TEAMS'!A12 -> 46088 | B4: ='10U GIRLS COED AU AG-12 TEAMS'!B12 -> 0.40277778 | C4: ='10U GIRLS COED AU AG-12 TEAMS'!C12&"" -> EL TORO HS 2 | D4: ='10U GIRLS COED AU AG-12 TEAMS'!D12&"" -> 10GCauag03 | E4: ='10U GIRLS COED AU AG-12 TEAMS'!E12&"" -> A1-TROJAN SOUTH au | F4: ='10U GIRLS COED AU AG-12 TEAMS'!F12&"" -> 3 | G4: ='10U GIRLS COED AU AG-12 TEAMS'!G12&"" -> A4-ORANGE COUNTY WPC B au | H4: ='10U GIRLS COED AU AG-12 TEAMS'!H12&"" -> 14 | I4: ='10U GIRLS COED AU AG-12 TEAMS'!I12&"" -> A bracket, A1/A4 coed gold 1st-4th | J4: ='10U GIRLS COED AU AG-12 TEAMS'!J12&"" -> 10U_GIRLS_COED_GOLD_SILVER | K4: =TEXT(DATE(2026, MONTH(A4), DAY(A4)) + TIME(HOUR(B4), MINUTE(B4), 0), "yyyymmddhhmm") -> 202603070940
A5: ='10U GIRLS COED AU AG-12 TEAMS'!A13 -> 46088 | B5: ='10U GIRLS COED AU AG-12 TEAMS'!B13 -> 0.40277778 | C5: ='10U GIRLS COED AU AG-12 TEAMS'!C13&"" -> WOOLLETT FAR LEFT | D5: ='10U GIRLS COED AU AG-12 TEAMS'!D13&"" -> 10GCauag05 | E5: ='10U GIRLS COED AU AG-12 TEAMS'!E13&"" -> C1-DEL MAR GIRLS BLUE | F5: ='10U GIRLS COED AU AG-12 TEAMS'!F13&"" -> 20 | G5: ='10U GIRLS COED AU AG-12 TEAMS'!G13&"" -> C4-NEWPORT BEACH GIRLS WHITE | H5: ='10U GIRLS COED AU AG-12 TEAMS'!H13&"" -> 0 | I5: ='10U GIRLS COED AU AG-12 TEAMS'!I13&"" -> C bracket C1,C4 Girls 1st-4th | J5: ='10U GIRLS COED AU AG-12 TEAMS'!J13&"" -> 10U_GIRLS_COED_GOLD_SILVER | K5: =TEXT(DATE(2026, MONTH(A5), DAY(A5)) + TIME(HOUR(B5), MINUTE(B5), 0), "yyyymmddhhmm") -> 202603070940
A6: ='10U GIRLS COED AU AG-12 TEAMS'!A14 -> 46088 | B6: ='10U GIRLS COED AU AG-12 TEAMS'!B14 -> 0.4375 | C6: ='10U GIRLS COED AU AG-12 TEAMS'!C14&"" -> EL TORO HS 2 | D6: ='10U GIRLS COED AU AG-12 TEAMS'!D14&"" -> 10GCauag04 | E6: ='10U GIRLS COED AU AG-12 TEAMS'!E14&"" -> A2-VANGUARD BLUE au | F6: ='10U GIRLS COED AU AG-12 TEAMS'!F14&"" -> 17 | G6: ='10U GIRLS COED AU AG-12 TEAMS'!G14&"" -> A3-SAN CLEMENTE BLACK au | H6: ='10U GIRLS COED AU AG-12 TEAMS'!H14&"" -> 3 | I6: ='10U GIRLS COED AU AG-12 TEAMS'!I14&"" -> A bracket, A2/A3 coed gold 1st-4th | J6: ='10U GIRLS COED AU AG-12 TEAMS'!J14&"" -> 10U_GIRLS_COED_GOLD_SILVER | K6: =TEXT(DATE(2026, MONTH(A6), DAY(A6)) + TIME(HOUR(B6), MINUTE(B6), 0), "yyyymmddhhmm") -> 202603071030
A7: ='10U GIRLS COED AU AG-12 TEAMS'!A15 -> 46088 | B7: ='10U GIRLS COED AU AG-12 TEAMS'!B15 -> 0.4375 | C7: ='10U GIRLS COED AU AG-12 TEAMS'!C15&"" -> WOOLLETT FAR LEFT | D7: ='10U GIRLS COED AU AG-12 TEAMS'!D15&"" -> 10GCauag06 | E7: ='10U GIRLS COED AU AG-12 TEAMS'!E15&"" -> C2-NEWPORT BEACH GIRLS BLUE | F7: ='10U GIRLS COED AU AG-12 TEAMS'!F15&"" -> 17 | G7: ='10U GIRLS COED AU AG-12 TEAMS'!G15&"" -> C3-DEL MAR GIRLS WHITE | H7: ='10U GIRLS COED AU AG-12 TEAMS'!H15&"" -> 1 | I7: ='10U GIRLS COED AU AG-12 TEAMS'!I15&"" -> C bracket C2,C3 Girls 1st-4th | J7: ='10U GIRLS COED AU AG-12 TEAMS'!J15&"" -> 10U_GIRLS_COED_GOLD_SILVER | K7: =TEXT(DATE(2026, MONTH(A7), DAY(A7)) + TIME(HOUR(B7), MINUTE(B7), 0), "yyyymmddhhmm") -> 202603071030
A8: ='10U GIRLS COED AU AG-12 TEAMS'!A16 -> 46088 | B8: ='10U GIRLS COED AU AG-12 TEAMS'!B16 -> 0.47222222 | C8: ='10U GIRLS COED AU AG-12 TEAMS'!C16&"" -> EL TORO HS 2 | D8: ='10U GIRLS COED AU AG-12 TEAMS'!D16&"" -> 10GCauag07 | E8: ='10U GIRLS COED AU AG-12 TEAMS'!E16&"" -> B2-CDM BOYS WHITE ag | F8: ='10U GIRLS COED AU AG-12 TEAMS'!F16&"" -> 4 | G8: ='10U GIRLS COED AU AG-12 TEAMS'!G16&"" -> B4-TROJAN NORTH ag | H8: ='10U GIRLS COED AU AG-12 TEAMS'!H16&"" -> 14 | I8: ='10U GIRLS COED AU AG-12 TEAMS'!I16&"" -> B bracket, B2/B4 coed silver 1st-4th | J8: ='10U GIRLS COED AU AG-12 TEAMS'!J16&"" -> 10U_GIRLS_COED_GOLD_SILVER | K8: =TEXT(DATE(2026, MONTH(A8), DAY(A8)) + TIME(HOUR(B8), MINUTE(B8), 0), "yyyymmddhhmm") -> 202603071120
A9: ='10U GIRLS COED AU AG-12 TEAMS'!A17 -> 46088 | B9: ='10U GIRLS COED AU AG-12 TEAMS'!B17 -> 0.50694444 | C9: ='10U GIRLS COED AU AG-12 TEAMS'!C17&"" -> EL TORO HS 2 | D9: ='10U GIRLS COED AU AG-12 TEAMS'!D17&"" -> 10GCauag08 | E9: ='10U GIRLS COED AU AG-12 TEAMS'!E17&"" -> B1-SAN CLEMENTE GIRLS RED ag | F9: ='10U GIRLS COED AU AG-12 TEAMS'!F17&"" -> 9 | G9: ='10U GIRLS COED AU AG-12 TEAMS'!G17&"" -> B3-LAGUNA BEACH ag | H9: ='10U GIRLS COED AU AG-12 TEAMS'!H17&"" -> 10 | I9: ='10U GIRLS COED AU AG-12 TEAMS'!I17&"" -> B bracket, B1/B3 coed silver 1st-4th | J9: ='10U GIRLS COED AU AG-12 TEAMS'!J17&"" -> 10U_GIRLS_COED_GOLD_SILVER | K9: =TEXT(DATE(2026, MONTH(A9), DAY(A9)) + TIME(HOUR(B9), MINUTE(B9), 0), "yyyymmddhhmm") -> 202603071210
A10: ='10U GIRLS COED AU AG-12 TEAMS'!A18 -> 46088 | B10: ='10U GIRLS COED AU AG-12 TEAMS'!B18 -> 0.54166667 | C10: ='10U GIRLS COED AU AG-12 TEAMS'!C18&"" -> EL TORO HS 2 | D10: ='10U GIRLS COED AU AG-12 TEAMS'!D18&"" -> 10GCauag09 | E10: ='10U GIRLS COED AU AG-12 TEAMS'!E18&"" -> A1-TROJAN SOUTH au | F10: ='10U GIRLS COED AU AG-12 TEAMS'!F18&"" -> 15 | G10: ='10U GIRLS COED AU AG-12 TEAMS'!G18&"" -> A3-SAN CLEMENTE BLACK au | H10: ='10U GIRLS COED AU AG-12 TEAMS'!H18&"" -> 6 | I10: ='10U GIRLS COED AU AG-12 TEAMS'!I18&"" -> A bracket, A1/A3 coed gold 1st-4th | J10: ='10U GIRLS COED AU AG-12 TEAMS'!J18&"" -> 10U_GIRLS_COED_GOLD_SILVER | K10: =TEXT(DATE(2026, MONTH(A10), DAY(A10)) + TIME(HOUR(B10), MINUTE(B10), 0), "yyyymmddhhmm") -> 202603071300
A11: ='10U GIRLS COED AU AG-12 TEAMS'!A19 -> 46088 | B11: ='10U GIRLS COED AU AG-12 TEAMS'!B19 -> 0.54166667 | C11: ='10U GIRLS COED AU AG-12 TEAMS'!C19&"" -> WOOLLETT FAR LEFT | D11: ='10U GIRLS COED AU AG-12 TEAMS'!D19&"" -> 10GCauag11 | E11: ='10U GIRLS COED AU AG-12 TEAMS'!E19&"" -> C1-DEL MAR GIRLS BLUE | F11: ='10U GIRLS COED AU AG-12 TEAMS'!F19&"" -> 7 | G11: ='10U GIRLS COED AU AG-12 TEAMS'!G19&"" -> C2-NEWPORT BEACH GIRLS BLUE | H11: ='10U GIRLS COED AU AG-12 TEAMS'!H19&"" -> 3 | I11: ='10U GIRLS COED AU AG-12 TEAMS'!I19&"" -> C bracket C1,C2 Girls 1st-4th | J11: ='10U GIRLS COED AU AG-12 TEAMS'!J19&"" -> 10U_GIRLS_COED_GOLD_SILVER | K11: =TEXT(DATE(2026, MONTH(A11), DAY(A11)) + TIME(HOUR(B11), MINUTE(B11), 0), "yyyymmddhhmm") -> 202603071300
A12: ='10U GIRLS COED AU AG-12 TEAMS'!A20 -> 46088 | B12: ='10U GIRLS COED AU AG-12 TEAMS'!B20 -> 0.57638889 | C12: ='10U GIRLS COED AU AG-12 TEAMS'!C20&"" -> EL TORO HS 2 | D12: ='10U GIRLS COED AU AG-12 TEAMS'!D20&"" -> 10GCauag10 | E12: ='10U GIRLS COED AU AG-12 TEAMS'!E20&"" -> A2-VANGUARD BLUE au | F12: ='10U GIRLS COED AU AG-12 TEAMS'!F20&"" -> 5 | G12: ='10U GIRLS COED AU AG-12 TEAMS'!G20&"" -> A4-ORANGE COUNTY WPC B au | H12: ='10U GIRLS COED AU AG-12 TEAMS'!H20&"" -> 11 | I12: ='10U GIRLS COED AU AG-12 TEAMS'!I20&"" -> A bracket, A2/A4 coed gold 1st-4th | J12: ='10U GIRLS COED AU AG-12 TEAMS'!J20&"" -> 10U_GIRLS_COED_GOLD_SILVER | K12: =TEXT(DATE(2026, MONTH(A12), DAY(A12)) + TIME(HOUR(B12), MINUTE(B12), 0), "yyyymmddhhmm") -> 202603071350
A13: ='10U GIRLS COED AU AG-12 TEAMS'!A21 -> 46088 | B13: ='10U GIRLS COED AU AG-12 TEAMS'!B21 -> 0.57638889 | C13: ='10U GIRLS COED AU AG-12 TEAMS'!C21&"" -> WOOLLETT FAR LEFT | D13: ='10U GIRLS COED AU AG-12 TEAMS'!D21&"" -> 10GCauag12 | E13: ='10U GIRLS COED AU AG-12 TEAMS'!E21&"" -> C3-DEL MAR GIRLS WHITE | F13: ='10U GIRLS COED AU AG-12 TEAMS'!F21&"" -> 16 | G13: ='10U GIRLS COED AU AG-12 TEAMS'!G21&"" -> C4-NEWPORT BEACH GIRLS WHITE | H13: ='10U GIRLS COED AU AG-12 TEAMS'!H21&"" -> 0 | I13: ='10U GIRLS COED AU AG-12 TEAMS'!I21&"" -> C bracket C3,C4 Girls 1st-4th | J13: ='10U GIRLS COED AU AG-12 TEAMS'!J21&"" -> 10U_GIRLS_COED_GOLD_SILVER | K13: =TEXT(DATE(2026, MONTH(A13), DAY(A13)) + TIME(HOUR(B13), MINUTE(B13), 0), "yyyymmddhhmm") -> 202603071350
A14: ='10U GIRLS COED AU AG-12 TEAMS'!A25 -> 46089 | B14: ='10U GIRLS COED AU AG-12 TEAMS'!B25 -> 0.33333333 | C14: ='10U GIRLS COED AU AG-12 TEAMS'!C25&"" -> EL TORO HS 2 | D14: ='10U GIRLS COED AU AG-12 TEAMS'!D25&"" -> 10GCauag13 | E14: ='10U GIRLS COED AU AG-12 TEAMS'!E25&"" -> A1-TROJAN SOUTH au | F14: ='10U GIRLS COED AU AG-12 TEAMS'!F25&"" -> 9 | G14: ='10U GIRLS COED AU AG-12 TEAMS'!G25&"" -> A2-VANGUARD BLUE au | H14: ='10U GIRLS COED AU AG-12 TEAMS'!H25&"" -> 15 | I14: ='10U GIRLS COED AU AG-12 TEAMS'!I25&"" -> bracket, A1/A2 coed gold 1st-4th | J14: ='10U GIRLS COED AU AG-12 TEAMS'!J25&"" -> 10U_GIRLS_COED_GOLD_SILVER | K14: =TEXT(DATE(2026, MONTH(A14), DAY(A14)) + TIME(HOUR(B14), MINUTE(B14), 0), "yyyymmddhhmm") -> 202603080800
